[2024-01-26T20:54:26.314+0000] {processor.py:153} INFO - Started process (PID=37463) to work on /opt/airflow/dags/etl_scripts/elt_fato_atendimento.py
[2024-01-26T20:54:26.316+0000] {processor.py:743} INFO - Processing file /opt/airflow/dags/etl_scripts/elt_fato_atendimento.py for tasks to queue
[2024-01-26T20:54:26.317+0000] {logging_mixin.py:137} INFO - [2024-01-26T20:54:26.317+0000] {dagbag.py:538} INFO - Filling up the DagBag from /opt/airflow/dags/etl_scripts/elt_fato_atendimento.py
[2024-01-26T20:54:26.470+0000] {logging_mixin.py:137} INFO - [2024-01-26T20:54:26.354+0000] {dagbag.py:343} ERROR - Failed to import: /opt/airflow/dags/etl_scripts/elt_fato_atendimento.py
Traceback (most recent call last):
  File "/home/airflow/.local/lib/python3.7/site-packages/airflow/models/dagbag.py", line 339, in parse
    loader.exec_module(new_module)
  File "<frozen importlib._bootstrap_external>", line 724, in exec_module
  File "<frozen importlib._bootstrap_external>", line 860, in get_code
  File "<frozen importlib._bootstrap_external>", line 791, in source_to_code
  File "<frozen importlib._bootstrap>", line 219, in _call_with_frames_removed
  File "/opt/airflow/dags/etl_scripts/elt_fato_atendimento.py", line 7
    config.read('C:\Users\User\Documents\GitHub\processoseletivo-teste\airflow-docker\dags\etl_scripts\config.ini')
               ^
SyntaxError: (unicode error) 'unicodeescape' codec can't decode bytes in position 2-3: truncated \UXXXXXXXX escape
[2024-01-26T20:54:26.471+0000] {processor.py:755} WARNING - No viable dags retrieved from /opt/airflow/dags/etl_scripts/elt_fato_atendimento.py
[2024-01-26T20:54:26.524+0000] {processor.py:175} INFO - Processing /opt/airflow/dags/etl_scripts/elt_fato_atendimento.py took 0.212 seconds
[2024-01-26T20:54:56.716+0000] {processor.py:153} INFO - Started process (PID=37498) to work on /opt/airflow/dags/etl_scripts/elt_fato_atendimento.py
[2024-01-26T20:54:56.718+0000] {processor.py:743} INFO - Processing file /opt/airflow/dags/etl_scripts/elt_fato_atendimento.py for tasks to queue
[2024-01-26T20:54:56.719+0000] {logging_mixin.py:137} INFO - [2024-01-26T20:54:56.719+0000] {dagbag.py:538} INFO - Filling up the DagBag from /opt/airflow/dags/etl_scripts/elt_fato_atendimento.py
[2024-01-26T20:54:56.744+0000] {logging_mixin.py:137} INFO - [2024-01-26T20:54:56.743+0000] {dagbag.py:343} ERROR - Failed to import: /opt/airflow/dags/etl_scripts/elt_fato_atendimento.py
Traceback (most recent call last):
  File "/home/airflow/.local/lib/python3.7/site-packages/airflow/models/dagbag.py", line 339, in parse
    loader.exec_module(new_module)
  File "<frozen importlib._bootstrap_external>", line 724, in exec_module
  File "<frozen importlib._bootstrap_external>", line 860, in get_code
  File "<frozen importlib._bootstrap_external>", line 791, in source_to_code
  File "<frozen importlib._bootstrap>", line 219, in _call_with_frames_removed
  File "/opt/airflow/dags/etl_scripts/elt_fato_atendimento.py", line 7
    config.read('C:\Users\User\Documents\GitHub\processoseletivo-teste\airflow-docker\dags\etl_scripts\config.ini')
               ^
SyntaxError: (unicode error) 'unicodeescape' codec can't decode bytes in position 2-3: truncated \UXXXXXXXX escape
[2024-01-26T20:54:56.745+0000] {processor.py:755} WARNING - No viable dags retrieved from /opt/airflow/dags/etl_scripts/elt_fato_atendimento.py
[2024-01-26T20:54:56.793+0000] {processor.py:175} INFO - Processing /opt/airflow/dags/etl_scripts/elt_fato_atendimento.py took 0.081 seconds
[2024-01-26T20:55:27.193+0000] {processor.py:153} INFO - Started process (PID=37542) to work on /opt/airflow/dags/etl_scripts/elt_fato_atendimento.py
[2024-01-26T20:55:27.198+0000] {processor.py:743} INFO - Processing file /opt/airflow/dags/etl_scripts/elt_fato_atendimento.py for tasks to queue
[2024-01-26T20:55:27.201+0000] {logging_mixin.py:137} INFO - [2024-01-26T20:55:27.200+0000] {dagbag.py:538} INFO - Filling up the DagBag from /opt/airflow/dags/etl_scripts/elt_fato_atendimento.py
[2024-01-26T20:55:27.241+0000] {logging_mixin.py:137} INFO - [2024-01-26T20:55:27.240+0000] {dagbag.py:343} ERROR - Failed to import: /opt/airflow/dags/etl_scripts/elt_fato_atendimento.py
Traceback (most recent call last):
  File "/home/airflow/.local/lib/python3.7/site-packages/airflow/models/dagbag.py", line 339, in parse
    loader.exec_module(new_module)
  File "<frozen importlib._bootstrap_external>", line 724, in exec_module
  File "<frozen importlib._bootstrap_external>", line 860, in get_code
  File "<frozen importlib._bootstrap_external>", line 791, in source_to_code
  File "<frozen importlib._bootstrap>", line 219, in _call_with_frames_removed
  File "/opt/airflow/dags/etl_scripts/elt_fato_atendimento.py", line 7
    config.read('C:\Users\User\Documents\GitHub\processoseletivo-teste\airflow-docker\dags\etl_scripts\config.ini')
               ^
SyntaxError: (unicode error) 'unicodeescape' codec can't decode bytes in position 2-3: truncated \UXXXXXXXX escape
[2024-01-26T20:55:27.242+0000] {processor.py:755} WARNING - No viable dags retrieved from /opt/airflow/dags/etl_scripts/elt_fato_atendimento.py
[2024-01-26T20:55:27.277+0000] {processor.py:175} INFO - Processing /opt/airflow/dags/etl_scripts/elt_fato_atendimento.py took 0.089 seconds
[2024-01-26T20:55:57.813+0000] {processor.py:153} INFO - Started process (PID=37584) to work on /opt/airflow/dags/etl_scripts/elt_fato_atendimento.py
[2024-01-26T20:55:57.815+0000] {processor.py:743} INFO - Processing file /opt/airflow/dags/etl_scripts/elt_fato_atendimento.py for tasks to queue
[2024-01-26T20:55:57.818+0000] {logging_mixin.py:137} INFO - [2024-01-26T20:55:57.818+0000] {dagbag.py:538} INFO - Filling up the DagBag from /opt/airflow/dags/etl_scripts/elt_fato_atendimento.py
[2024-01-26T20:55:57.882+0000] {logging_mixin.py:137} INFO - [2024-01-26T20:55:57.880+0000] {dagbag.py:343} ERROR - Failed to import: /opt/airflow/dags/etl_scripts/elt_fato_atendimento.py
Traceback (most recent call last):
  File "/home/airflow/.local/lib/python3.7/site-packages/airflow/models/dagbag.py", line 339, in parse
    loader.exec_module(new_module)
  File "<frozen importlib._bootstrap_external>", line 724, in exec_module
  File "<frozen importlib._bootstrap_external>", line 860, in get_code
  File "<frozen importlib._bootstrap_external>", line 791, in source_to_code
  File "<frozen importlib._bootstrap>", line 219, in _call_with_frames_removed
  File "/opt/airflow/dags/etl_scripts/elt_fato_atendimento.py", line 7
    config.read('C:\Users\User\Documents\GitHub\processoseletivo-teste\airflow-docker\dags\etl_scripts\config.ini')
               ^
SyntaxError: (unicode error) 'unicodeescape' codec can't decode bytes in position 2-3: truncated \UXXXXXXXX escape
[2024-01-26T20:55:57.883+0000] {processor.py:755} WARNING - No viable dags retrieved from /opt/airflow/dags/etl_scripts/elt_fato_atendimento.py
[2024-01-26T20:55:57.936+0000] {processor.py:175} INFO - Processing /opt/airflow/dags/etl_scripts/elt_fato_atendimento.py took 0.129 seconds
[2024-01-26T20:56:28.379+0000] {processor.py:153} INFO - Started process (PID=37619) to work on /opt/airflow/dags/etl_scripts/elt_fato_atendimento.py
[2024-01-26T20:56:28.380+0000] {processor.py:743} INFO - Processing file /opt/airflow/dags/etl_scripts/elt_fato_atendimento.py for tasks to queue
[2024-01-26T20:56:28.381+0000] {logging_mixin.py:137} INFO - [2024-01-26T20:56:28.381+0000] {dagbag.py:538} INFO - Filling up the DagBag from /opt/airflow/dags/etl_scripts/elt_fato_atendimento.py
[2024-01-26T20:56:28.400+0000] {logging_mixin.py:137} INFO - [2024-01-26T20:56:28.399+0000] {dagbag.py:343} ERROR - Failed to import: /opt/airflow/dags/etl_scripts/elt_fato_atendimento.py
Traceback (most recent call last):
  File "/home/airflow/.local/lib/python3.7/site-packages/airflow/models/dagbag.py", line 339, in parse
    loader.exec_module(new_module)
  File "<frozen importlib._bootstrap_external>", line 724, in exec_module
  File "<frozen importlib._bootstrap_external>", line 860, in get_code
  File "<frozen importlib._bootstrap_external>", line 791, in source_to_code
  File "<frozen importlib._bootstrap>", line 219, in _call_with_frames_removed
  File "/opt/airflow/dags/etl_scripts/elt_fato_atendimento.py", line 7
    config.read('C:\Users\User\Documents\GitHub\processoseletivo-teste\airflow-docker\dags\etl_scripts\config.ini')
               ^
SyntaxError: (unicode error) 'unicodeescape' codec can't decode bytes in position 2-3: truncated \UXXXXXXXX escape
[2024-01-26T20:56:28.401+0000] {processor.py:755} WARNING - No viable dags retrieved from /opt/airflow/dags/etl_scripts/elt_fato_atendimento.py
[2024-01-26T20:56:28.423+0000] {processor.py:175} INFO - Processing /opt/airflow/dags/etl_scripts/elt_fato_atendimento.py took 0.047 seconds
[2024-01-26T20:56:58.819+0000] {processor.py:153} INFO - Started process (PID=37654) to work on /opt/airflow/dags/etl_scripts/elt_fato_atendimento.py
[2024-01-26T20:56:58.821+0000] {processor.py:743} INFO - Processing file /opt/airflow/dags/etl_scripts/elt_fato_atendimento.py for tasks to queue
[2024-01-26T20:56:58.823+0000] {logging_mixin.py:137} INFO - [2024-01-26T20:56:58.823+0000] {dagbag.py:538} INFO - Filling up the DagBag from /opt/airflow/dags/etl_scripts/elt_fato_atendimento.py
[2024-01-26T20:56:58.853+0000] {logging_mixin.py:137} INFO - [2024-01-26T20:56:58.852+0000] {dagbag.py:343} ERROR - Failed to import: /opt/airflow/dags/etl_scripts/elt_fato_atendimento.py
Traceback (most recent call last):
  File "/home/airflow/.local/lib/python3.7/site-packages/airflow/models/dagbag.py", line 339, in parse
    loader.exec_module(new_module)
  File "<frozen importlib._bootstrap_external>", line 724, in exec_module
  File "<frozen importlib._bootstrap_external>", line 860, in get_code
  File "<frozen importlib._bootstrap_external>", line 791, in source_to_code
  File "<frozen importlib._bootstrap>", line 219, in _call_with_frames_removed
  File "/opt/airflow/dags/etl_scripts/elt_fato_atendimento.py", line 7
    config.read('C:\Users\User\Documents\GitHub\processoseletivo-teste\airflow-docker\dags\etl_scripts\config.ini')
               ^
SyntaxError: (unicode error) 'unicodeescape' codec can't decode bytes in position 2-3: truncated \UXXXXXXXX escape
[2024-01-26T20:56:58.854+0000] {processor.py:755} WARNING - No viable dags retrieved from /opt/airflow/dags/etl_scripts/elt_fato_atendimento.py
[2024-01-26T20:56:58.880+0000] {processor.py:175} INFO - Processing /opt/airflow/dags/etl_scripts/elt_fato_atendimento.py took 0.065 seconds
[2024-01-26T20:57:29.253+0000] {processor.py:153} INFO - Started process (PID=37705) to work on /opt/airflow/dags/etl_scripts/elt_fato_atendimento.py
[2024-01-26T20:57:29.254+0000] {processor.py:743} INFO - Processing file /opt/airflow/dags/etl_scripts/elt_fato_atendimento.py for tasks to queue
[2024-01-26T20:57:29.256+0000] {logging_mixin.py:137} INFO - [2024-01-26T20:57:29.256+0000] {dagbag.py:538} INFO - Filling up the DagBag from /opt/airflow/dags/etl_scripts/elt_fato_atendimento.py
[2024-01-26T20:57:29.277+0000] {logging_mixin.py:137} INFO - [2024-01-26T20:57:29.276+0000] {dagbag.py:343} ERROR - Failed to import: /opt/airflow/dags/etl_scripts/elt_fato_atendimento.py
Traceback (most recent call last):
  File "/home/airflow/.local/lib/python3.7/site-packages/airflow/models/dagbag.py", line 339, in parse
    loader.exec_module(new_module)
  File "<frozen importlib._bootstrap_external>", line 724, in exec_module
  File "<frozen importlib._bootstrap_external>", line 860, in get_code
  File "<frozen importlib._bootstrap_external>", line 791, in source_to_code
  File "<frozen importlib._bootstrap>", line 219, in _call_with_frames_removed
  File "/opt/airflow/dags/etl_scripts/elt_fato_atendimento.py", line 7
    config.read('C:\Users\User\Documents\GitHub\processoseletivo-teste\airflow-docker\dags\etl_scripts\config.ini')
               ^
SyntaxError: (unicode error) 'unicodeescape' codec can't decode bytes in position 2-3: truncated \UXXXXXXXX escape
[2024-01-26T20:57:29.278+0000] {processor.py:755} WARNING - No viable dags retrieved from /opt/airflow/dags/etl_scripts/elt_fato_atendimento.py
[2024-01-26T20:57:29.309+0000] {processor.py:175} INFO - Processing /opt/airflow/dags/etl_scripts/elt_fato_atendimento.py took 0.060 seconds
[2024-01-26T20:57:59.740+0000] {processor.py:153} INFO - Started process (PID=37740) to work on /opt/airflow/dags/etl_scripts/elt_fato_atendimento.py
[2024-01-26T20:57:59.742+0000] {processor.py:743} INFO - Processing file /opt/airflow/dags/etl_scripts/elt_fato_atendimento.py for tasks to queue
[2024-01-26T20:57:59.744+0000] {logging_mixin.py:137} INFO - [2024-01-26T20:57:59.743+0000] {dagbag.py:538} INFO - Filling up the DagBag from /opt/airflow/dags/etl_scripts/elt_fato_atendimento.py
[2024-01-26T20:57:59.768+0000] {logging_mixin.py:137} INFO - [2024-01-26T20:57:59.767+0000] {dagbag.py:343} ERROR - Failed to import: /opt/airflow/dags/etl_scripts/elt_fato_atendimento.py
Traceback (most recent call last):
  File "/home/airflow/.local/lib/python3.7/site-packages/airflow/models/dagbag.py", line 339, in parse
    loader.exec_module(new_module)
  File "<frozen importlib._bootstrap_external>", line 724, in exec_module
  File "<frozen importlib._bootstrap_external>", line 860, in get_code
  File "<frozen importlib._bootstrap_external>", line 791, in source_to_code
  File "<frozen importlib._bootstrap>", line 219, in _call_with_frames_removed
  File "/opt/airflow/dags/etl_scripts/elt_fato_atendimento.py", line 7
    config.read('C:\Users\User\Documents\GitHub\processoseletivo-teste\airflow-docker\dags\etl_scripts\config.ini')
               ^
SyntaxError: (unicode error) 'unicodeescape' codec can't decode bytes in position 2-3: truncated \UXXXXXXXX escape
[2024-01-26T20:57:59.769+0000] {processor.py:755} WARNING - No viable dags retrieved from /opt/airflow/dags/etl_scripts/elt_fato_atendimento.py
[2024-01-26T20:57:59.798+0000] {processor.py:175} INFO - Processing /opt/airflow/dags/etl_scripts/elt_fato_atendimento.py took 0.062 seconds
[2024-01-26T20:58:30.175+0000] {processor.py:153} INFO - Started process (PID=37775) to work on /opt/airflow/dags/etl_scripts/elt_fato_atendimento.py
[2024-01-26T20:58:30.176+0000] {processor.py:743} INFO - Processing file /opt/airflow/dags/etl_scripts/elt_fato_atendimento.py for tasks to queue
[2024-01-26T20:58:30.178+0000] {logging_mixin.py:137} INFO - [2024-01-26T20:58:30.177+0000] {dagbag.py:538} INFO - Filling up the DagBag from /opt/airflow/dags/etl_scripts/elt_fato_atendimento.py
[2024-01-26T20:58:30.206+0000] {logging_mixin.py:137} INFO - [2024-01-26T20:58:30.205+0000] {dagbag.py:343} ERROR - Failed to import: /opt/airflow/dags/etl_scripts/elt_fato_atendimento.py
Traceback (most recent call last):
  File "/home/airflow/.local/lib/python3.7/site-packages/airflow/models/dagbag.py", line 339, in parse
    loader.exec_module(new_module)
  File "<frozen importlib._bootstrap_external>", line 724, in exec_module
  File "<frozen importlib._bootstrap_external>", line 860, in get_code
  File "<frozen importlib._bootstrap_external>", line 791, in source_to_code
  File "<frozen importlib._bootstrap>", line 219, in _call_with_frames_removed
  File "/opt/airflow/dags/etl_scripts/elt_fato_atendimento.py", line 7
    config.read('C:\Users\User\Documents\GitHub\processoseletivo-teste\airflow-docker\dags\etl_scripts\config.ini')
               ^
SyntaxError: (unicode error) 'unicodeescape' codec can't decode bytes in position 2-3: truncated \UXXXXXXXX escape
[2024-01-26T20:58:30.207+0000] {processor.py:755} WARNING - No viable dags retrieved from /opt/airflow/dags/etl_scripts/elt_fato_atendimento.py
[2024-01-26T20:58:30.231+0000] {processor.py:175} INFO - Processing /opt/airflow/dags/etl_scripts/elt_fato_atendimento.py took 0.060 seconds
[2024-01-26T20:59:00.647+0000] {processor.py:153} INFO - Started process (PID=37817) to work on /opt/airflow/dags/etl_scripts/elt_fato_atendimento.py
[2024-01-26T20:59:00.649+0000] {processor.py:743} INFO - Processing file /opt/airflow/dags/etl_scripts/elt_fato_atendimento.py for tasks to queue
[2024-01-26T20:59:00.650+0000] {logging_mixin.py:137} INFO - [2024-01-26T20:59:00.650+0000] {dagbag.py:538} INFO - Filling up the DagBag from /opt/airflow/dags/etl_scripts/elt_fato_atendimento.py
[2024-01-26T20:59:00.676+0000] {logging_mixin.py:137} INFO - [2024-01-26T20:59:00.674+0000] {dagbag.py:343} ERROR - Failed to import: /opt/airflow/dags/etl_scripts/elt_fato_atendimento.py
Traceback (most recent call last):
  File "/home/airflow/.local/lib/python3.7/site-packages/airflow/models/dagbag.py", line 339, in parse
    loader.exec_module(new_module)
  File "<frozen importlib._bootstrap_external>", line 724, in exec_module
  File "<frozen importlib._bootstrap_external>", line 860, in get_code
  File "<frozen importlib._bootstrap_external>", line 791, in source_to_code
  File "<frozen importlib._bootstrap>", line 219, in _call_with_frames_removed
  File "/opt/airflow/dags/etl_scripts/elt_fato_atendimento.py", line 7
    config.read('C:\Users\User\Documents\GitHub\processoseletivo-teste\airflow-docker\dags\etl_scripts\config.ini')
               ^
SyntaxError: (unicode error) 'unicodeescape' codec can't decode bytes in position 2-3: truncated \UXXXXXXXX escape
[2024-01-26T20:59:00.677+0000] {processor.py:755} WARNING - No viable dags retrieved from /opt/airflow/dags/etl_scripts/elt_fato_atendimento.py
[2024-01-26T20:59:00.703+0000] {processor.py:175} INFO - Processing /opt/airflow/dags/etl_scripts/elt_fato_atendimento.py took 0.061 seconds
[2024-01-26T20:59:31.639+0000] {processor.py:153} INFO - Started process (PID=37863) to work on /opt/airflow/dags/etl_scripts/elt_fato_atendimento.py
[2024-01-26T20:59:31.640+0000] {processor.py:743} INFO - Processing file /opt/airflow/dags/etl_scripts/elt_fato_atendimento.py for tasks to queue
[2024-01-26T20:59:31.642+0000] {logging_mixin.py:137} INFO - [2024-01-26T20:59:31.642+0000] {dagbag.py:538} INFO - Filling up the DagBag from /opt/airflow/dags/etl_scripts/elt_fato_atendimento.py
[2024-01-26T20:59:31.673+0000] {logging_mixin.py:137} INFO - [2024-01-26T20:59:31.671+0000] {dagbag.py:343} ERROR - Failed to import: /opt/airflow/dags/etl_scripts/elt_fato_atendimento.py
Traceback (most recent call last):
  File "/home/airflow/.local/lib/python3.7/site-packages/airflow/models/dagbag.py", line 339, in parse
    loader.exec_module(new_module)
  File "<frozen importlib._bootstrap_external>", line 724, in exec_module
  File "<frozen importlib._bootstrap_external>", line 860, in get_code
  File "<frozen importlib._bootstrap_external>", line 791, in source_to_code
  File "<frozen importlib._bootstrap>", line 219, in _call_with_frames_removed
  File "/opt/airflow/dags/etl_scripts/elt_fato_atendimento.py", line 7
    config.read('C:\Users\User\Documents\GitHub\processoseletivo-teste\airflow-docker\dags\etl_scripts\config.ini')
               ^
SyntaxError: (unicode error) 'unicodeescape' codec can't decode bytes in position 2-3: truncated \UXXXXXXXX escape
[2024-01-26T20:59:31.675+0000] {processor.py:755} WARNING - No viable dags retrieved from /opt/airflow/dags/etl_scripts/elt_fato_atendimento.py
[2024-01-26T20:59:31.705+0000] {processor.py:175} INFO - Processing /opt/airflow/dags/etl_scripts/elt_fato_atendimento.py took 0.069 seconds
[2024-01-26T21:00:02.036+0000] {processor.py:153} INFO - Started process (PID=37900) to work on /opt/airflow/dags/etl_scripts/elt_fato_atendimento.py
[2024-01-26T21:00:02.037+0000] {processor.py:743} INFO - Processing file /opt/airflow/dags/etl_scripts/elt_fato_atendimento.py for tasks to queue
[2024-01-26T21:00:02.038+0000] {logging_mixin.py:137} INFO - [2024-01-26T21:00:02.038+0000] {dagbag.py:538} INFO - Filling up the DagBag from /opt/airflow/dags/etl_scripts/elt_fato_atendimento.py
[2024-01-26T21:00:02.056+0000] {logging_mixin.py:137} INFO - [2024-01-26T21:00:02.055+0000] {dagbag.py:343} ERROR - Failed to import: /opt/airflow/dags/etl_scripts/elt_fato_atendimento.py
Traceback (most recent call last):
  File "/home/airflow/.local/lib/python3.7/site-packages/airflow/models/dagbag.py", line 339, in parse
    loader.exec_module(new_module)
  File "<frozen importlib._bootstrap_external>", line 724, in exec_module
  File "<frozen importlib._bootstrap_external>", line 860, in get_code
  File "<frozen importlib._bootstrap_external>", line 791, in source_to_code
  File "<frozen importlib._bootstrap>", line 219, in _call_with_frames_removed
  File "/opt/airflow/dags/etl_scripts/elt_fato_atendimento.py", line 7
    config.read('C:\Users\User\Documents\GitHub\processoseletivo-teste\airflow-docker\dags\etl_scripts\config.ini')
               ^
SyntaxError: (unicode error) 'unicodeescape' codec can't decode bytes in position 2-3: truncated \UXXXXXXXX escape
[2024-01-26T21:00:02.057+0000] {processor.py:755} WARNING - No viable dags retrieved from /opt/airflow/dags/etl_scripts/elt_fato_atendimento.py
[2024-01-26T21:00:02.078+0000] {processor.py:175} INFO - Processing /opt/airflow/dags/etl_scripts/elt_fato_atendimento.py took 0.046 seconds
[2024-01-26T21:00:32.536+0000] {processor.py:153} INFO - Started process (PID=37938) to work on /opt/airflow/dags/etl_scripts/elt_fato_atendimento.py
[2024-01-26T21:00:32.538+0000] {processor.py:743} INFO - Processing file /opt/airflow/dags/etl_scripts/elt_fato_atendimento.py for tasks to queue
[2024-01-26T21:00:32.539+0000] {logging_mixin.py:137} INFO - [2024-01-26T21:00:32.539+0000] {dagbag.py:538} INFO - Filling up the DagBag from /opt/airflow/dags/etl_scripts/elt_fato_atendimento.py
[2024-01-26T21:00:32.565+0000] {logging_mixin.py:137} INFO - [2024-01-26T21:00:32.564+0000] {dagbag.py:343} ERROR - Failed to import: /opt/airflow/dags/etl_scripts/elt_fato_atendimento.py
Traceback (most recent call last):
  File "/home/airflow/.local/lib/python3.7/site-packages/airflow/models/dagbag.py", line 339, in parse
    loader.exec_module(new_module)
  File "<frozen importlib._bootstrap_external>", line 724, in exec_module
  File "<frozen importlib._bootstrap_external>", line 860, in get_code
  File "<frozen importlib._bootstrap_external>", line 791, in source_to_code
  File "<frozen importlib._bootstrap>", line 219, in _call_with_frames_removed
  File "/opt/airflow/dags/etl_scripts/elt_fato_atendimento.py", line 7
    config.read('C:\Users\User\Documents\GitHub\processoseletivo-teste\airflow-docker\dags\etl_scripts\config.ini')
               ^
SyntaxError: (unicode error) 'unicodeescape' codec can't decode bytes in position 2-3: truncated \UXXXXXXXX escape
[2024-01-26T21:00:32.566+0000] {processor.py:755} WARNING - No viable dags retrieved from /opt/airflow/dags/etl_scripts/elt_fato_atendimento.py
[2024-01-26T21:00:32.589+0000] {processor.py:175} INFO - Processing /opt/airflow/dags/etl_scripts/elt_fato_atendimento.py took 0.056 seconds
[2024-01-26T21:01:02.948+0000] {processor.py:153} INFO - Started process (PID=37992) to work on /opt/airflow/dags/etl_scripts/elt_fato_atendimento.py
[2024-01-26T21:01:02.950+0000] {processor.py:743} INFO - Processing file /opt/airflow/dags/etl_scripts/elt_fato_atendimento.py for tasks to queue
[2024-01-26T21:01:02.952+0000] {logging_mixin.py:137} INFO - [2024-01-26T21:01:02.951+0000] {dagbag.py:538} INFO - Filling up the DagBag from /opt/airflow/dags/etl_scripts/elt_fato_atendimento.py
[2024-01-26T21:01:02.987+0000] {logging_mixin.py:137} INFO - [2024-01-26T21:01:02.985+0000] {dagbag.py:343} ERROR - Failed to import: /opt/airflow/dags/etl_scripts/elt_fato_atendimento.py
Traceback (most recent call last):
  File "/home/airflow/.local/lib/python3.7/site-packages/airflow/models/dagbag.py", line 339, in parse
    loader.exec_module(new_module)
  File "<frozen importlib._bootstrap_external>", line 724, in exec_module
  File "<frozen importlib._bootstrap_external>", line 860, in get_code
  File "<frozen importlib._bootstrap_external>", line 791, in source_to_code
  File "<frozen importlib._bootstrap>", line 219, in _call_with_frames_removed
  File "/opt/airflow/dags/etl_scripts/elt_fato_atendimento.py", line 7
    config.read('C:\Users\User\Documents\GitHub\processoseletivo-teste\airflow-docker\dags\etl_scripts\config.ini')
               ^
SyntaxError: (unicode error) 'unicodeescape' codec can't decode bytes in position 2-3: truncated \UXXXXXXXX escape
[2024-01-26T21:01:02.988+0000] {processor.py:755} WARNING - No viable dags retrieved from /opt/airflow/dags/etl_scripts/elt_fato_atendimento.py
[2024-01-26T21:01:03.024+0000] {processor.py:175} INFO - Processing /opt/airflow/dags/etl_scripts/elt_fato_atendimento.py took 0.084 seconds
[2024-01-26T21:01:33.605+0000] {processor.py:153} INFO - Started process (PID=38028) to work on /opt/airflow/dags/etl_scripts/elt_fato_atendimento.py
[2024-01-26T21:01:33.606+0000] {processor.py:743} INFO - Processing file /opt/airflow/dags/etl_scripts/elt_fato_atendimento.py for tasks to queue
[2024-01-26T21:01:33.608+0000] {logging_mixin.py:137} INFO - [2024-01-26T21:01:33.607+0000] {dagbag.py:538} INFO - Filling up the DagBag from /opt/airflow/dags/etl_scripts/elt_fato_atendimento.py
[2024-01-26T21:01:33.633+0000] {logging_mixin.py:137} INFO - [2024-01-26T21:01:33.632+0000] {dagbag.py:343} ERROR - Failed to import: /opt/airflow/dags/etl_scripts/elt_fato_atendimento.py
Traceback (most recent call last):
  File "/home/airflow/.local/lib/python3.7/site-packages/airflow/models/dagbag.py", line 339, in parse
    loader.exec_module(new_module)
  File "<frozen importlib._bootstrap_external>", line 724, in exec_module
  File "<frozen importlib._bootstrap_external>", line 860, in get_code
  File "<frozen importlib._bootstrap_external>", line 791, in source_to_code
  File "<frozen importlib._bootstrap>", line 219, in _call_with_frames_removed
  File "/opt/airflow/dags/etl_scripts/elt_fato_atendimento.py", line 7
    config.read('C:\Users\User\Documents\GitHub\processoseletivo-teste\airflow-docker\dags\etl_scripts\config.ini')
               ^
SyntaxError: (unicode error) 'unicodeescape' codec can't decode bytes in position 2-3: truncated \UXXXXXXXX escape
[2024-01-26T21:01:33.634+0000] {processor.py:755} WARNING - No viable dags retrieved from /opt/airflow/dags/etl_scripts/elt_fato_atendimento.py
[2024-01-26T21:01:33.661+0000] {processor.py:175} INFO - Processing /opt/airflow/dags/etl_scripts/elt_fato_atendimento.py took 0.062 seconds
[2024-01-26T21:02:03.935+0000] {processor.py:153} INFO - Started process (PID=38064) to work on /opt/airflow/dags/etl_scripts/elt_fato_atendimento.py
[2024-01-26T21:02:03.937+0000] {processor.py:743} INFO - Processing file /opt/airflow/dags/etl_scripts/elt_fato_atendimento.py for tasks to queue
[2024-01-26T21:02:03.938+0000] {logging_mixin.py:137} INFO - [2024-01-26T21:02:03.938+0000] {dagbag.py:538} INFO - Filling up the DagBag from /opt/airflow/dags/etl_scripts/elt_fato_atendimento.py
[2024-01-26T21:02:03.969+0000] {logging_mixin.py:137} INFO - [2024-01-26T21:02:03.967+0000] {dagbag.py:343} ERROR - Failed to import: /opt/airflow/dags/etl_scripts/elt_fato_atendimento.py
Traceback (most recent call last):
  File "/home/airflow/.local/lib/python3.7/site-packages/airflow/models/dagbag.py", line 339, in parse
    loader.exec_module(new_module)
  File "<frozen importlib._bootstrap_external>", line 724, in exec_module
  File "<frozen importlib._bootstrap_external>", line 860, in get_code
  File "<frozen importlib._bootstrap_external>", line 791, in source_to_code
  File "<frozen importlib._bootstrap>", line 219, in _call_with_frames_removed
  File "/opt/airflow/dags/etl_scripts/elt_fato_atendimento.py", line 7
    config.read('C:\Users\User\Documents\GitHub\processoseletivo-teste\airflow-docker\dags\etl_scripts\config.ini')
               ^
SyntaxError: (unicode error) 'unicodeescape' codec can't decode bytes in position 2-3: truncated \UXXXXXXXX escape
[2024-01-26T21:02:03.970+0000] {processor.py:755} WARNING - No viable dags retrieved from /opt/airflow/dags/etl_scripts/elt_fato_atendimento.py
[2024-01-26T21:02:04.016+0000] {processor.py:175} INFO - Processing /opt/airflow/dags/etl_scripts/elt_fato_atendimento.py took 0.084 seconds
[2024-01-26T21:02:34.676+0000] {processor.py:153} INFO - Started process (PID=38109) to work on /opt/airflow/dags/etl_scripts/elt_fato_atendimento.py
[2024-01-26T21:02:34.677+0000] {processor.py:743} INFO - Processing file /opt/airflow/dags/etl_scripts/elt_fato_atendimento.py for tasks to queue
[2024-01-26T21:02:34.679+0000] {logging_mixin.py:137} INFO - [2024-01-26T21:02:34.678+0000] {dagbag.py:538} INFO - Filling up the DagBag from /opt/airflow/dags/etl_scripts/elt_fato_atendimento.py
[2024-01-26T21:02:34.700+0000] {logging_mixin.py:137} INFO - [2024-01-26T21:02:34.699+0000] {dagbag.py:343} ERROR - Failed to import: /opt/airflow/dags/etl_scripts/elt_fato_atendimento.py
Traceback (most recent call last):
  File "/home/airflow/.local/lib/python3.7/site-packages/airflow/models/dagbag.py", line 339, in parse
    loader.exec_module(new_module)
  File "<frozen importlib._bootstrap_external>", line 724, in exec_module
  File "<frozen importlib._bootstrap_external>", line 860, in get_code
  File "<frozen importlib._bootstrap_external>", line 791, in source_to_code
  File "<frozen importlib._bootstrap>", line 219, in _call_with_frames_removed
  File "/opt/airflow/dags/etl_scripts/elt_fato_atendimento.py", line 7
    config.read('C:\Users\User\Documents\GitHub\processoseletivo-teste\airflow-docker\dags\etl_scripts\config.ini')
               ^
SyntaxError: (unicode error) 'unicodeescape' codec can't decode bytes in position 2-3: truncated \UXXXXXXXX escape
[2024-01-26T21:02:34.701+0000] {processor.py:755} WARNING - No viable dags retrieved from /opt/airflow/dags/etl_scripts/elt_fato_atendimento.py
[2024-01-26T21:02:34.723+0000] {processor.py:175} INFO - Processing /opt/airflow/dags/etl_scripts/elt_fato_atendimento.py took 0.050 seconds
[2024-01-26T21:03:05.212+0000] {processor.py:153} INFO - Started process (PID=38152) to work on /opt/airflow/dags/etl_scripts/elt_fato_atendimento.py
[2024-01-26T21:03:05.214+0000] {processor.py:743} INFO - Processing file /opt/airflow/dags/etl_scripts/elt_fato_atendimento.py for tasks to queue
[2024-01-26T21:03:05.216+0000] {logging_mixin.py:137} INFO - [2024-01-26T21:03:05.215+0000] {dagbag.py:538} INFO - Filling up the DagBag from /opt/airflow/dags/etl_scripts/elt_fato_atendimento.py
[2024-01-26T21:03:05.319+0000] {logging_mixin.py:137} INFO - [2024-01-26T21:03:05.317+0000] {dagbag.py:343} ERROR - Failed to import: /opt/airflow/dags/etl_scripts/elt_fato_atendimento.py
Traceback (most recent call last):
  File "/home/airflow/.local/lib/python3.7/site-packages/airflow/models/dagbag.py", line 339, in parse
    loader.exec_module(new_module)
  File "<frozen importlib._bootstrap_external>", line 724, in exec_module
  File "<frozen importlib._bootstrap_external>", line 860, in get_code
  File "<frozen importlib._bootstrap_external>", line 791, in source_to_code
  File "<frozen importlib._bootstrap>", line 219, in _call_with_frames_removed
  File "/opt/airflow/dags/etl_scripts/elt_fato_atendimento.py", line 7
    config.read('C:\Users\User\Documents\GitHub\processoseletivo-teste\airflow-docker\dags\etl_scripts\config.ini')
               ^
SyntaxError: (unicode error) 'unicodeescape' codec can't decode bytes in position 2-3: truncated \UXXXXXXXX escape
[2024-01-26T21:03:05.323+0000] {processor.py:755} WARNING - No viable dags retrieved from /opt/airflow/dags/etl_scripts/elt_fato_atendimento.py
[2024-01-26T21:03:05.388+0000] {processor.py:175} INFO - Processing /opt/airflow/dags/etl_scripts/elt_fato_atendimento.py took 0.182 seconds
[2024-01-26T21:03:35.979+0000] {processor.py:153} INFO - Started process (PID=38188) to work on /opt/airflow/dags/etl_scripts/elt_fato_atendimento.py
[2024-01-26T21:03:35.980+0000] {processor.py:743} INFO - Processing file /opt/airflow/dags/etl_scripts/elt_fato_atendimento.py for tasks to queue
[2024-01-26T21:03:35.981+0000] {logging_mixin.py:137} INFO - [2024-01-26T21:03:35.981+0000] {dagbag.py:538} INFO - Filling up the DagBag from /opt/airflow/dags/etl_scripts/elt_fato_atendimento.py
[2024-01-26T21:03:36.004+0000] {logging_mixin.py:137} INFO - [2024-01-26T21:03:36.003+0000] {dagbag.py:343} ERROR - Failed to import: /opt/airflow/dags/etl_scripts/elt_fato_atendimento.py
Traceback (most recent call last):
  File "/home/airflow/.local/lib/python3.7/site-packages/airflow/models/dagbag.py", line 339, in parse
    loader.exec_module(new_module)
  File "<frozen importlib._bootstrap_external>", line 724, in exec_module
  File "<frozen importlib._bootstrap_external>", line 860, in get_code
  File "<frozen importlib._bootstrap_external>", line 791, in source_to_code
  File "<frozen importlib._bootstrap>", line 219, in _call_with_frames_removed
  File "/opt/airflow/dags/etl_scripts/elt_fato_atendimento.py", line 7
    config.read('C:\Users\User\Documents\GitHub\processoseletivo-teste\airflow-docker\dags\etl_scripts\config.ini')
               ^
SyntaxError: (unicode error) 'unicodeescape' codec can't decode bytes in position 2-3: truncated \UXXXXXXXX escape
[2024-01-26T21:03:36.006+0000] {processor.py:755} WARNING - No viable dags retrieved from /opt/airflow/dags/etl_scripts/elt_fato_atendimento.py
[2024-01-26T21:03:36.047+0000] {processor.py:175} INFO - Processing /opt/airflow/dags/etl_scripts/elt_fato_atendimento.py took 0.073 seconds
[2024-01-26T21:04:09.072+0000] {processor.py:153} INFO - Started process (PID=38225) to work on /opt/airflow/dags/etl_scripts/elt_fato_atendimento.py
[2024-01-26T21:04:09.073+0000] {processor.py:743} INFO - Processing file /opt/airflow/dags/etl_scripts/elt_fato_atendimento.py for tasks to queue
[2024-01-26T21:04:09.074+0000] {logging_mixin.py:137} INFO - [2024-01-26T21:04:09.074+0000] {dagbag.py:538} INFO - Filling up the DagBag from /opt/airflow/dags/etl_scripts/elt_fato_atendimento.py
[2024-01-26T21:04:09.093+0000] {logging_mixin.py:137} INFO - [2024-01-26T21:04:09.093+0000] {dagbag.py:343} ERROR - Failed to import: /opt/airflow/dags/etl_scripts/elt_fato_atendimento.py
Traceback (most recent call last):
  File "/home/airflow/.local/lib/python3.7/site-packages/airflow/models/dagbag.py", line 339, in parse
    loader.exec_module(new_module)
  File "<frozen importlib._bootstrap_external>", line 724, in exec_module
  File "<frozen importlib._bootstrap_external>", line 860, in get_code
  File "<frozen importlib._bootstrap_external>", line 791, in source_to_code
  File "<frozen importlib._bootstrap>", line 219, in _call_with_frames_removed
  File "/opt/airflow/dags/etl_scripts/elt_fato_atendimento.py", line 7
    config.read('C:\Users\User\Documents\GitHub\processoseletivo-teste\airflow-docker\dags\etl_scripts\config.ini')
               ^
SyntaxError: (unicode error) 'unicodeescape' codec can't decode bytes in position 2-3: truncated \UXXXXXXXX escape
[2024-01-26T21:04:09.094+0000] {processor.py:755} WARNING - No viable dags retrieved from /opt/airflow/dags/etl_scripts/elt_fato_atendimento.py
[2024-01-26T21:04:10.260+0000] {processor.py:175} INFO - Processing /opt/airflow/dags/etl_scripts/elt_fato_atendimento.py took 1.192 seconds
[2024-01-26T21:04:40.647+0000] {processor.py:153} INFO - Started process (PID=38244) to work on /opt/airflow/dags/etl_scripts/elt_fato_atendimento.py
[2024-01-26T21:04:40.648+0000] {processor.py:743} INFO - Processing file /opt/airflow/dags/etl_scripts/elt_fato_atendimento.py for tasks to queue
[2024-01-26T21:04:40.649+0000] {logging_mixin.py:137} INFO - [2024-01-26T21:04:40.649+0000] {dagbag.py:538} INFO - Filling up the DagBag from /opt/airflow/dags/etl_scripts/elt_fato_atendimento.py
[2024-01-26T21:04:40.674+0000] {logging_mixin.py:137} INFO - [2024-01-26T21:04:40.671+0000] {dagbag.py:343} ERROR - Failed to import: /opt/airflow/dags/etl_scripts/elt_fato_atendimento.py
Traceback (most recent call last):
  File "/home/airflow/.local/lib/python3.7/site-packages/airflow/models/dagbag.py", line 339, in parse
    loader.exec_module(new_module)
  File "<frozen importlib._bootstrap_external>", line 724, in exec_module
  File "<frozen importlib._bootstrap_external>", line 860, in get_code
  File "<frozen importlib._bootstrap_external>", line 791, in source_to_code
  File "<frozen importlib._bootstrap>", line 219, in _call_with_frames_removed
  File "/opt/airflow/dags/etl_scripts/elt_fato_atendimento.py", line 7
    config.read('C:\Users\User\Documents\GitHub\processoseletivo-teste\airflow-docker\dags\etl_scripts\config.ini')
               ^
SyntaxError: (unicode error) 'unicodeescape' codec can't decode bytes in position 2-3: truncated \UXXXXXXXX escape
[2024-01-26T21:04:40.675+0000] {processor.py:755} WARNING - No viable dags retrieved from /opt/airflow/dags/etl_scripts/elt_fato_atendimento.py
[2024-01-26T21:04:40.700+0000] {processor.py:175} INFO - Processing /opt/airflow/dags/etl_scripts/elt_fato_atendimento.py took 0.057 seconds
[2024-01-26T21:05:11.196+0000] {processor.py:153} INFO - Started process (PID=38279) to work on /opt/airflow/dags/etl_scripts/elt_fato_atendimento.py
[2024-01-26T21:05:11.197+0000] {processor.py:743} INFO - Processing file /opt/airflow/dags/etl_scripts/elt_fato_atendimento.py for tasks to queue
[2024-01-26T21:05:11.198+0000] {logging_mixin.py:137} INFO - [2024-01-26T21:05:11.198+0000] {dagbag.py:538} INFO - Filling up the DagBag from /opt/airflow/dags/etl_scripts/elt_fato_atendimento.py
[2024-01-26T21:05:11.225+0000] {logging_mixin.py:137} INFO - [2024-01-26T21:05:11.224+0000] {dagbag.py:343} ERROR - Failed to import: /opt/airflow/dags/etl_scripts/elt_fato_atendimento.py
Traceback (most recent call last):
  File "/home/airflow/.local/lib/python3.7/site-packages/airflow/models/dagbag.py", line 339, in parse
    loader.exec_module(new_module)
  File "<frozen importlib._bootstrap_external>", line 724, in exec_module
  File "<frozen importlib._bootstrap_external>", line 860, in get_code
  File "<frozen importlib._bootstrap_external>", line 791, in source_to_code
  File "<frozen importlib._bootstrap>", line 219, in _call_with_frames_removed
  File "/opt/airflow/dags/etl_scripts/elt_fato_atendimento.py", line 7
    config.read('C:\Users\User\Documents\GitHub\processoseletivo-teste\airflow-docker\dags\etl_scripts\config.ini')
               ^
SyntaxError: (unicode error) 'unicodeescape' codec can't decode bytes in position 2-3: truncated \UXXXXXXXX escape
[2024-01-26T21:05:11.226+0000] {processor.py:755} WARNING - No viable dags retrieved from /opt/airflow/dags/etl_scripts/elt_fato_atendimento.py
[2024-01-26T21:05:11.252+0000] {processor.py:175} INFO - Processing /opt/airflow/dags/etl_scripts/elt_fato_atendimento.py took 0.059 seconds
[2024-01-26T21:05:41.825+0000] {processor.py:153} INFO - Started process (PID=38323) to work on /opt/airflow/dags/etl_scripts/elt_fato_atendimento.py
[2024-01-26T21:05:41.826+0000] {processor.py:743} INFO - Processing file /opt/airflow/dags/etl_scripts/elt_fato_atendimento.py for tasks to queue
[2024-01-26T21:05:41.827+0000] {logging_mixin.py:137} INFO - [2024-01-26T21:05:41.827+0000] {dagbag.py:538} INFO - Filling up the DagBag from /opt/airflow/dags/etl_scripts/elt_fato_atendimento.py
[2024-01-26T21:05:41.856+0000] {logging_mixin.py:137} INFO - [2024-01-26T21:05:41.855+0000] {dagbag.py:343} ERROR - Failed to import: /opt/airflow/dags/etl_scripts/elt_fato_atendimento.py
Traceback (most recent call last):
  File "/home/airflow/.local/lib/python3.7/site-packages/airflow/models/dagbag.py", line 339, in parse
    loader.exec_module(new_module)
  File "<frozen importlib._bootstrap_external>", line 724, in exec_module
  File "<frozen importlib._bootstrap_external>", line 860, in get_code
  File "<frozen importlib._bootstrap_external>", line 791, in source_to_code
  File "<frozen importlib._bootstrap>", line 219, in _call_with_frames_removed
  File "/opt/airflow/dags/etl_scripts/elt_fato_atendimento.py", line 7
    config.read('C:\Users\User\Documents\GitHub\processoseletivo-teste\airflow-docker\dags\etl_scripts\config.ini')
               ^
SyntaxError: (unicode error) 'unicodeescape' codec can't decode bytes in position 2-3: truncated \UXXXXXXXX escape
[2024-01-26T21:05:41.857+0000] {processor.py:755} WARNING - No viable dags retrieved from /opt/airflow/dags/etl_scripts/elt_fato_atendimento.py
[2024-01-26T21:05:41.891+0000] {processor.py:175} INFO - Processing /opt/airflow/dags/etl_scripts/elt_fato_atendimento.py took 0.069 seconds
[2024-01-26T21:06:12.354+0000] {processor.py:153} INFO - Started process (PID=38365) to work on /opt/airflow/dags/etl_scripts/elt_fato_atendimento.py
[2024-01-26T21:06:12.355+0000] {processor.py:743} INFO - Processing file /opt/airflow/dags/etl_scripts/elt_fato_atendimento.py for tasks to queue
[2024-01-26T21:06:12.357+0000] {logging_mixin.py:137} INFO - [2024-01-26T21:06:12.356+0000] {dagbag.py:538} INFO - Filling up the DagBag from /opt/airflow/dags/etl_scripts/elt_fato_atendimento.py
[2024-01-26T21:06:12.378+0000] {logging_mixin.py:137} INFO - [2024-01-26T21:06:12.377+0000] {dagbag.py:343} ERROR - Failed to import: /opt/airflow/dags/etl_scripts/elt_fato_atendimento.py
Traceback (most recent call last):
  File "/home/airflow/.local/lib/python3.7/site-packages/airflow/models/dagbag.py", line 339, in parse
    loader.exec_module(new_module)
  File "<frozen importlib._bootstrap_external>", line 724, in exec_module
  File "<frozen importlib._bootstrap_external>", line 860, in get_code
  File "<frozen importlib._bootstrap_external>", line 791, in source_to_code
  File "<frozen importlib._bootstrap>", line 219, in _call_with_frames_removed
  File "/opt/airflow/dags/etl_scripts/elt_fato_atendimento.py", line 7
    config.read('C:\Users\User\Documents\GitHub\processoseletivo-teste\airflow-docker\dags\etl_scripts\config.ini')
               ^
SyntaxError: (unicode error) 'unicodeescape' codec can't decode bytes in position 2-3: truncated \UXXXXXXXX escape
[2024-01-26T21:06:12.379+0000] {processor.py:755} WARNING - No viable dags retrieved from /opt/airflow/dags/etl_scripts/elt_fato_atendimento.py
[2024-01-26T21:06:12.403+0000] {processor.py:175} INFO - Processing /opt/airflow/dags/etl_scripts/elt_fato_atendimento.py took 0.052 seconds
[2024-01-26T21:06:39.790+0000] {processor.py:153} INFO - Started process (PID=38400) to work on /opt/airflow/dags/etl_scripts/elt_fato_atendimento.py
[2024-01-26T21:06:39.791+0000] {processor.py:743} INFO - Processing file /opt/airflow/dags/etl_scripts/elt_fato_atendimento.py for tasks to queue
[2024-01-26T21:06:39.792+0000] {logging_mixin.py:137} INFO - [2024-01-26T21:06:39.792+0000] {dagbag.py:538} INFO - Filling up the DagBag from /opt/airflow/dags/etl_scripts/elt_fato_atendimento.py
[2024-01-26T21:06:39.816+0000] {logging_mixin.py:137} INFO - [2024-01-26T21:06:39.816+0000] {dagbag.py:320} INFO - File /opt/airflow/dags/etl_scripts/elt_fato_atendimento.py assumed to contain no DAGs. Skipping.
[2024-01-26T21:06:39.816+0000] {processor.py:755} WARNING - No viable dags retrieved from /opt/airflow/dags/etl_scripts/elt_fato_atendimento.py
[2024-01-26T21:06:39.839+0000] {processor.py:175} INFO - Processing /opt/airflow/dags/etl_scripts/elt_fato_atendimento.py took 0.052 seconds
[2024-01-26T21:06:54.984+0000] {processor.py:153} INFO - Started process (PID=38417) to work on /opt/airflow/dags/etl_scripts/elt_fato_atendimento.py
[2024-01-26T21:06:54.985+0000] {processor.py:743} INFO - Processing file /opt/airflow/dags/etl_scripts/elt_fato_atendimento.py for tasks to queue
[2024-01-26T21:06:54.987+0000] {logging_mixin.py:137} INFO - [2024-01-26T21:06:54.986+0000] {dagbag.py:538} INFO - Filling up the DagBag from /opt/airflow/dags/etl_scripts/elt_fato_atendimento.py
[2024-01-26T21:06:55.025+0000] {logging_mixin.py:137} INFO - [2024-01-26T21:06:55.024+0000] {dagbag.py:320} INFO - File /opt/airflow/dags/etl_scripts/elt_fato_atendimento.py assumed to contain no DAGs. Skipping.
[2024-01-26T21:06:55.026+0000] {processor.py:755} WARNING - No viable dags retrieved from /opt/airflow/dags/etl_scripts/elt_fato_atendimento.py
[2024-01-26T21:06:55.051+0000] {processor.py:175} INFO - Processing /opt/airflow/dags/etl_scripts/elt_fato_atendimento.py took 0.070 seconds
[2024-01-26T21:07:14.416+0000] {processor.py:153} INFO - Started process (PID=38436) to work on /opt/airflow/dags/etl_scripts/elt_fato_atendimento.py
[2024-01-26T21:07:14.417+0000] {processor.py:743} INFO - Processing file /opt/airflow/dags/etl_scripts/elt_fato_atendimento.py for tasks to queue
[2024-01-26T21:07:14.418+0000] {logging_mixin.py:137} INFO - [2024-01-26T21:07:14.418+0000] {dagbag.py:538} INFO - Filling up the DagBag from /opt/airflow/dags/etl_scripts/elt_fato_atendimento.py
[2024-01-26T21:07:14.440+0000] {logging_mixin.py:137} INFO - [2024-01-26T21:07:14.439+0000] {dagbag.py:320} INFO - File /opt/airflow/dags/etl_scripts/elt_fato_atendimento.py assumed to contain no DAGs. Skipping.
[2024-01-26T21:07:14.440+0000] {processor.py:755} WARNING - No viable dags retrieved from /opt/airflow/dags/etl_scripts/elt_fato_atendimento.py
[2024-01-26T21:07:14.458+0000] {processor.py:175} INFO - Processing /opt/airflow/dags/etl_scripts/elt_fato_atendimento.py took 0.046 seconds
[2024-01-26T21:07:44.904+0000] {processor.py:153} INFO - Started process (PID=38487) to work on /opt/airflow/dags/etl_scripts/elt_fato_atendimento.py
[2024-01-26T21:07:44.906+0000] {processor.py:743} INFO - Processing file /opt/airflow/dags/etl_scripts/elt_fato_atendimento.py for tasks to queue
[2024-01-26T21:07:44.907+0000] {logging_mixin.py:137} INFO - [2024-01-26T21:07:44.907+0000] {dagbag.py:538} INFO - Filling up the DagBag from /opt/airflow/dags/etl_scripts/elt_fato_atendimento.py
[2024-01-26T21:07:44.918+0000] {logging_mixin.py:137} INFO - [2024-01-26T21:07:44.918+0000] {dagbag.py:320} INFO - File /opt/airflow/dags/etl_scripts/elt_fato_atendimento.py assumed to contain no DAGs. Skipping.
[2024-01-26T21:07:44.919+0000] {processor.py:755} WARNING - No viable dags retrieved from /opt/airflow/dags/etl_scripts/elt_fato_atendimento.py
[2024-01-26T21:07:44.938+0000] {processor.py:175} INFO - Processing /opt/airflow/dags/etl_scripts/elt_fato_atendimento.py took 0.037 seconds
[2024-01-26T21:08:15.324+0000] {processor.py:153} INFO - Started process (PID=38522) to work on /opt/airflow/dags/etl_scripts/elt_fato_atendimento.py
[2024-01-26T21:08:15.325+0000] {processor.py:743} INFO - Processing file /opt/airflow/dags/etl_scripts/elt_fato_atendimento.py for tasks to queue
[2024-01-26T21:08:15.326+0000] {logging_mixin.py:137} INFO - [2024-01-26T21:08:15.326+0000] {dagbag.py:538} INFO - Filling up the DagBag from /opt/airflow/dags/etl_scripts/elt_fato_atendimento.py
[2024-01-26T21:08:15.339+0000] {logging_mixin.py:137} INFO - [2024-01-26T21:08:15.339+0000] {dagbag.py:320} INFO - File /opt/airflow/dags/etl_scripts/elt_fato_atendimento.py assumed to contain no DAGs. Skipping.
[2024-01-26T21:08:15.340+0000] {processor.py:755} WARNING - No viable dags retrieved from /opt/airflow/dags/etl_scripts/elt_fato_atendimento.py
[2024-01-26T21:08:15.356+0000] {processor.py:175} INFO - Processing /opt/airflow/dags/etl_scripts/elt_fato_atendimento.py took 0.036 seconds
[2024-01-26T21:08:46.116+0000] {processor.py:153} INFO - Started process (PID=38558) to work on /opt/airflow/dags/etl_scripts/elt_fato_atendimento.py
[2024-01-26T21:08:46.117+0000] {processor.py:743} INFO - Processing file /opt/airflow/dags/etl_scripts/elt_fato_atendimento.py for tasks to queue
[2024-01-26T21:08:46.119+0000] {logging_mixin.py:137} INFO - [2024-01-26T21:08:46.118+0000] {dagbag.py:538} INFO - Filling up the DagBag from /opt/airflow/dags/etl_scripts/elt_fato_atendimento.py
[2024-01-26T21:08:46.132+0000] {logging_mixin.py:137} INFO - [2024-01-26T21:08:46.131+0000] {dagbag.py:320} INFO - File /opt/airflow/dags/etl_scripts/elt_fato_atendimento.py assumed to contain no DAGs. Skipping.
[2024-01-26T21:08:46.132+0000] {processor.py:755} WARNING - No viable dags retrieved from /opt/airflow/dags/etl_scripts/elt_fato_atendimento.py
[2024-01-26T21:08:46.147+0000] {processor.py:175} INFO - Processing /opt/airflow/dags/etl_scripts/elt_fato_atendimento.py took 0.034 seconds
[2024-01-26T21:09:16.587+0000] {processor.py:153} INFO - Started process (PID=38593) to work on /opt/airflow/dags/etl_scripts/elt_fato_atendimento.py
[2024-01-26T21:09:16.588+0000] {processor.py:743} INFO - Processing file /opt/airflow/dags/etl_scripts/elt_fato_atendimento.py for tasks to queue
[2024-01-26T21:09:16.589+0000] {logging_mixin.py:137} INFO - [2024-01-26T21:09:16.589+0000] {dagbag.py:538} INFO - Filling up the DagBag from /opt/airflow/dags/etl_scripts/elt_fato_atendimento.py
[2024-01-26T21:09:16.600+0000] {logging_mixin.py:137} INFO - [2024-01-26T21:09:16.600+0000] {dagbag.py:320} INFO - File /opt/airflow/dags/etl_scripts/elt_fato_atendimento.py assumed to contain no DAGs. Skipping.
[2024-01-26T21:09:16.600+0000] {processor.py:755} WARNING - No viable dags retrieved from /opt/airflow/dags/etl_scripts/elt_fato_atendimento.py
[2024-01-26T21:09:16.614+0000] {processor.py:175} INFO - Processing /opt/airflow/dags/etl_scripts/elt_fato_atendimento.py took 0.031 seconds
