[2024-01-26T15:54:06.100+0000] {processor.py:153} INFO - Started process (PID=14315) to work on /opt/airflow/dags/etl_scripts/etl_atendimentos_dl.py
[2024-01-26T15:54:06.101+0000] {processor.py:743} INFO - Processing file /opt/airflow/dags/etl_scripts/etl_atendimentos_dl.py for tasks to queue
[2024-01-26T15:54:06.102+0000] {logging_mixin.py:137} INFO - [2024-01-26T15:54:06.102+0000] {dagbag.py:538} INFO - Filling up the DagBag from /opt/airflow/dags/etl_scripts/etl_atendimentos_dl.py
[2024-01-26T15:54:09.417+0000] {logging_mixin.py:137} INFO - [2024-01-26T15:54:09.397+0000] {dagbag.py:343} ERROR - Failed to import: /opt/airflow/dags/etl_scripts/etl_atendimentos_dl.py
Traceback (most recent call last):
  File "/home/airflow/.local/lib/python3.7/site-packages/airflow/models/dagbag.py", line 339, in parse
    loader.exec_module(new_module)
  File "<frozen importlib._bootstrap_external>", line 728, in exec_module
  File "<frozen importlib._bootstrap>", line 219, in _call_with_frames_removed
  File "/opt/airflow/dags/etl_scripts/etl_atendimentos_dl.py", line 18, in <module>
    usuario = config.get('Database', 'user')
  File "/usr/local/lib/python3.7/configparser.py", line 780, in get
    d = self._unify_values(section, vars)
  File "/usr/local/lib/python3.7/configparser.py", line 1146, in _unify_values
    raise NoSectionError(section) from None
configparser.NoSectionError: No section: 'Database'
[2024-01-26T15:54:09.418+0000] {processor.py:755} WARNING - No viable dags retrieved from /opt/airflow/dags/etl_scripts/etl_atendimentos_dl.py
[2024-01-26T15:54:09.443+0000] {processor.py:175} INFO - Processing /opt/airflow/dags/etl_scripts/etl_atendimentos_dl.py took 3.345 seconds
[2024-01-26T15:54:39.515+0000] {processor.py:153} INFO - Started process (PID=14359) to work on /opt/airflow/dags/etl_scripts/etl_atendimentos_dl.py
[2024-01-26T15:54:39.517+0000] {processor.py:743} INFO - Processing file /opt/airflow/dags/etl_scripts/etl_atendimentos_dl.py for tasks to queue
[2024-01-26T15:54:39.518+0000] {logging_mixin.py:137} INFO - [2024-01-26T15:54:39.518+0000] {dagbag.py:538} INFO - Filling up the DagBag from /opt/airflow/dags/etl_scripts/etl_atendimentos_dl.py
[2024-01-26T15:54:39.825+0000] {logging_mixin.py:137} INFO - [2024-01-26T15:54:39.818+0000] {dagbag.py:343} ERROR - Failed to import: /opt/airflow/dags/etl_scripts/etl_atendimentos_dl.py
Traceback (most recent call last):
  File "/home/airflow/.local/lib/python3.7/site-packages/airflow/models/dagbag.py", line 339, in parse
    loader.exec_module(new_module)
  File "<frozen importlib._bootstrap_external>", line 728, in exec_module
  File "<frozen importlib._bootstrap>", line 219, in _call_with_frames_removed
  File "/opt/airflow/dags/etl_scripts/etl_atendimentos_dl.py", line 18, in <module>
    usuario = config.get('Database', 'user')
  File "/usr/local/lib/python3.7/configparser.py", line 780, in get
    d = self._unify_values(section, vars)
  File "/usr/local/lib/python3.7/configparser.py", line 1146, in _unify_values
    raise NoSectionError(section) from None
configparser.NoSectionError: No section: 'Database'
[2024-01-26T15:54:39.826+0000] {processor.py:755} WARNING - No viable dags retrieved from /opt/airflow/dags/etl_scripts/etl_atendimentos_dl.py
[2024-01-26T15:54:39.851+0000] {processor.py:175} INFO - Processing /opt/airflow/dags/etl_scripts/etl_atendimentos_dl.py took 0.338 seconds
[2024-01-26T15:55:09.918+0000] {processor.py:153} INFO - Started process (PID=14402) to work on /opt/airflow/dags/etl_scripts/etl_atendimentos_dl.py
[2024-01-26T15:55:09.920+0000] {processor.py:743} INFO - Processing file /opt/airflow/dags/etl_scripts/etl_atendimentos_dl.py for tasks to queue
[2024-01-26T15:55:09.921+0000] {logging_mixin.py:137} INFO - [2024-01-26T15:55:09.921+0000] {dagbag.py:538} INFO - Filling up the DagBag from /opt/airflow/dags/etl_scripts/etl_atendimentos_dl.py
[2024-01-26T15:55:10.278+0000] {logging_mixin.py:137} INFO - [2024-01-26T15:55:10.267+0000] {dagbag.py:343} ERROR - Failed to import: /opt/airflow/dags/etl_scripts/etl_atendimentos_dl.py
Traceback (most recent call last):
  File "/home/airflow/.local/lib/python3.7/site-packages/airflow/models/dagbag.py", line 339, in parse
    loader.exec_module(new_module)
  File "<frozen importlib._bootstrap_external>", line 728, in exec_module
  File "<frozen importlib._bootstrap>", line 219, in _call_with_frames_removed
  File "/opt/airflow/dags/etl_scripts/etl_atendimentos_dl.py", line 18, in <module>
    usuario = config.get('Database', 'user')
  File "/usr/local/lib/python3.7/configparser.py", line 780, in get
    d = self._unify_values(section, vars)
  File "/usr/local/lib/python3.7/configparser.py", line 1146, in _unify_values
    raise NoSectionError(section) from None
configparser.NoSectionError: No section: 'Database'
[2024-01-26T15:55:10.279+0000] {processor.py:755} WARNING - No viable dags retrieved from /opt/airflow/dags/etl_scripts/etl_atendimentos_dl.py
[2024-01-26T15:55:10.305+0000] {processor.py:175} INFO - Processing /opt/airflow/dags/etl_scripts/etl_atendimentos_dl.py took 0.390 seconds
[2024-01-26T15:55:40.484+0000] {processor.py:153} INFO - Started process (PID=14437) to work on /opt/airflow/dags/etl_scripts/etl_atendimentos_dl.py
[2024-01-26T15:55:40.489+0000] {processor.py:743} INFO - Processing file /opt/airflow/dags/etl_scripts/etl_atendimentos_dl.py for tasks to queue
[2024-01-26T15:55:40.491+0000] {logging_mixin.py:137} INFO - [2024-01-26T15:55:40.491+0000] {dagbag.py:538} INFO - Filling up the DagBag from /opt/airflow/dags/etl_scripts/etl_atendimentos_dl.py
[2024-01-26T15:55:41.064+0000] {logging_mixin.py:137} INFO - [2024-01-26T15:55:41.052+0000] {dagbag.py:343} ERROR - Failed to import: /opt/airflow/dags/etl_scripts/etl_atendimentos_dl.py
Traceback (most recent call last):
  File "/home/airflow/.local/lib/python3.7/site-packages/airflow/models/dagbag.py", line 339, in parse
    loader.exec_module(new_module)
  File "<frozen importlib._bootstrap_external>", line 728, in exec_module
  File "<frozen importlib._bootstrap>", line 219, in _call_with_frames_removed
  File "/opt/airflow/dags/etl_scripts/etl_atendimentos_dl.py", line 18, in <module>
    usuario = config.get('Database', 'user')
  File "/usr/local/lib/python3.7/configparser.py", line 780, in get
    d = self._unify_values(section, vars)
  File "/usr/local/lib/python3.7/configparser.py", line 1146, in _unify_values
    raise NoSectionError(section) from None
configparser.NoSectionError: No section: 'Database'
[2024-01-26T15:55:41.065+0000] {processor.py:755} WARNING - No viable dags retrieved from /opt/airflow/dags/etl_scripts/etl_atendimentos_dl.py
[2024-01-26T15:55:41.104+0000] {processor.py:175} INFO - Processing /opt/airflow/dags/etl_scripts/etl_atendimentos_dl.py took 0.627 seconds
[2024-01-26T15:56:11.725+0000] {processor.py:153} INFO - Started process (PID=14488) to work on /opt/airflow/dags/etl_scripts/etl_atendimentos_dl.py
[2024-01-26T15:56:11.726+0000] {processor.py:743} INFO - Processing file /opt/airflow/dags/etl_scripts/etl_atendimentos_dl.py for tasks to queue
[2024-01-26T15:56:11.727+0000] {logging_mixin.py:137} INFO - [2024-01-26T15:56:11.727+0000] {dagbag.py:538} INFO - Filling up the DagBag from /opt/airflow/dags/etl_scripts/etl_atendimentos_dl.py
[2024-01-26T15:56:12.088+0000] {logging_mixin.py:137} INFO - [2024-01-26T15:56:12.080+0000] {dagbag.py:343} ERROR - Failed to import: /opt/airflow/dags/etl_scripts/etl_atendimentos_dl.py
Traceback (most recent call last):
  File "/home/airflow/.local/lib/python3.7/site-packages/airflow/models/dagbag.py", line 339, in parse
    loader.exec_module(new_module)
  File "<frozen importlib._bootstrap_external>", line 728, in exec_module
  File "<frozen importlib._bootstrap>", line 219, in _call_with_frames_removed
  File "/opt/airflow/dags/etl_scripts/etl_atendimentos_dl.py", line 18, in <module>
    usuario = config.get('Database', 'user')
  File "/usr/local/lib/python3.7/configparser.py", line 780, in get
    d = self._unify_values(section, vars)
  File "/usr/local/lib/python3.7/configparser.py", line 1146, in _unify_values
    raise NoSectionError(section) from None
configparser.NoSectionError: No section: 'Database'
[2024-01-26T15:56:12.089+0000] {processor.py:755} WARNING - No viable dags retrieved from /opt/airflow/dags/etl_scripts/etl_atendimentos_dl.py
[2024-01-26T15:56:12.110+0000] {processor.py:175} INFO - Processing /opt/airflow/dags/etl_scripts/etl_atendimentos_dl.py took 0.389 seconds
[2024-01-26T15:56:42.513+0000] {processor.py:153} INFO - Started process (PID=14523) to work on /opt/airflow/dags/etl_scripts/etl_atendimentos_dl.py
[2024-01-26T15:56:42.514+0000] {processor.py:743} INFO - Processing file /opt/airflow/dags/etl_scripts/etl_atendimentos_dl.py for tasks to queue
[2024-01-26T15:56:42.515+0000] {logging_mixin.py:137} INFO - [2024-01-26T15:56:42.515+0000] {dagbag.py:538} INFO - Filling up the DagBag from /opt/airflow/dags/etl_scripts/etl_atendimentos_dl.py
[2024-01-26T15:56:42.798+0000] {logging_mixin.py:137} INFO - [2024-01-26T15:56:42.791+0000] {dagbag.py:343} ERROR - Failed to import: /opt/airflow/dags/etl_scripts/etl_atendimentos_dl.py
Traceback (most recent call last):
  File "/home/airflow/.local/lib/python3.7/site-packages/airflow/models/dagbag.py", line 339, in parse
    loader.exec_module(new_module)
  File "<frozen importlib._bootstrap_external>", line 728, in exec_module
  File "<frozen importlib._bootstrap>", line 219, in _call_with_frames_removed
  File "/opt/airflow/dags/etl_scripts/etl_atendimentos_dl.py", line 18, in <module>
    usuario = config.get('Database', 'user')
  File "/usr/local/lib/python3.7/configparser.py", line 780, in get
    d = self._unify_values(section, vars)
  File "/usr/local/lib/python3.7/configparser.py", line 1146, in _unify_values
    raise NoSectionError(section) from None
configparser.NoSectionError: No section: 'Database'
[2024-01-26T15:56:42.798+0000] {processor.py:755} WARNING - No viable dags retrieved from /opt/airflow/dags/etl_scripts/etl_atendimentos_dl.py
[2024-01-26T15:56:42.822+0000] {processor.py:175} INFO - Processing /opt/airflow/dags/etl_scripts/etl_atendimentos_dl.py took 0.313 seconds
[2024-01-26T15:57:12.948+0000] {processor.py:153} INFO - Started process (PID=14558) to work on /opt/airflow/dags/etl_scripts/etl_atendimentos_dl.py
[2024-01-26T15:57:12.949+0000] {processor.py:743} INFO - Processing file /opt/airflow/dags/etl_scripts/etl_atendimentos_dl.py for tasks to queue
[2024-01-26T15:57:12.951+0000] {logging_mixin.py:137} INFO - [2024-01-26T15:57:12.951+0000] {dagbag.py:538} INFO - Filling up the DagBag from /opt/airflow/dags/etl_scripts/etl_atendimentos_dl.py
[2024-01-26T15:57:13.356+0000] {logging_mixin.py:137} INFO - [2024-01-26T15:57:13.347+0000] {dagbag.py:343} ERROR - Failed to import: /opt/airflow/dags/etl_scripts/etl_atendimentos_dl.py
Traceback (most recent call last):
  File "/home/airflow/.local/lib/python3.7/site-packages/airflow/models/dagbag.py", line 339, in parse
    loader.exec_module(new_module)
  File "<frozen importlib._bootstrap_external>", line 728, in exec_module
  File "<frozen importlib._bootstrap>", line 219, in _call_with_frames_removed
  File "/opt/airflow/dags/etl_scripts/etl_atendimentos_dl.py", line 18, in <module>
    usuario = config.get('Database', 'user')
  File "/usr/local/lib/python3.7/configparser.py", line 780, in get
    d = self._unify_values(section, vars)
  File "/usr/local/lib/python3.7/configparser.py", line 1146, in _unify_values
    raise NoSectionError(section) from None
configparser.NoSectionError: No section: 'Database'
[2024-01-26T15:57:13.357+0000] {processor.py:755} WARNING - No viable dags retrieved from /opt/airflow/dags/etl_scripts/etl_atendimentos_dl.py
[2024-01-26T15:57:13.387+0000] {processor.py:175} INFO - Processing /opt/airflow/dags/etl_scripts/etl_atendimentos_dl.py took 0.443 seconds
[2024-01-26T15:57:43.638+0000] {processor.py:153} INFO - Started process (PID=14609) to work on /opt/airflow/dags/etl_scripts/etl_atendimentos_dl.py
[2024-01-26T15:57:43.641+0000] {processor.py:743} INFO - Processing file /opt/airflow/dags/etl_scripts/etl_atendimentos_dl.py for tasks to queue
[2024-01-26T15:57:43.643+0000] {logging_mixin.py:137} INFO - [2024-01-26T15:57:43.643+0000] {dagbag.py:538} INFO - Filling up the DagBag from /opt/airflow/dags/etl_scripts/etl_atendimentos_dl.py
[2024-01-26T15:57:45.055+0000] {logging_mixin.py:137} INFO - [2024-01-26T15:57:45.040+0000] {dagbag.py:343} ERROR - Failed to import: /opt/airflow/dags/etl_scripts/etl_atendimentos_dl.py
Traceback (most recent call last):
  File "/home/airflow/.local/lib/python3.7/site-packages/airflow/models/dagbag.py", line 339, in parse
    loader.exec_module(new_module)
  File "<frozen importlib._bootstrap_external>", line 728, in exec_module
  File "<frozen importlib._bootstrap>", line 219, in _call_with_frames_removed
  File "/opt/airflow/dags/etl_scripts/etl_atendimentos_dl.py", line 18, in <module>
    usuario = config.get('Database', 'user')
  File "/usr/local/lib/python3.7/configparser.py", line 780, in get
    d = self._unify_values(section, vars)
  File "/usr/local/lib/python3.7/configparser.py", line 1146, in _unify_values
    raise NoSectionError(section) from None
configparser.NoSectionError: No section: 'Database'
[2024-01-26T15:57:45.056+0000] {processor.py:755} WARNING - No viable dags retrieved from /opt/airflow/dags/etl_scripts/etl_atendimentos_dl.py
[2024-01-26T15:57:45.191+0000] {processor.py:175} INFO - Processing /opt/airflow/dags/etl_scripts/etl_atendimentos_dl.py took 1.560 seconds
[2024-01-26T15:58:15.966+0000] {processor.py:153} INFO - Started process (PID=14645) to work on /opt/airflow/dags/etl_scripts/etl_atendimentos_dl.py
[2024-01-26T15:58:15.967+0000] {processor.py:743} INFO - Processing file /opt/airflow/dags/etl_scripts/etl_atendimentos_dl.py for tasks to queue
[2024-01-26T15:58:15.969+0000] {logging_mixin.py:137} INFO - [2024-01-26T15:58:15.968+0000] {dagbag.py:538} INFO - Filling up the DagBag from /opt/airflow/dags/etl_scripts/etl_atendimentos_dl.py
[2024-01-26T15:58:16.281+0000] {logging_mixin.py:137} INFO - [2024-01-26T15:58:16.273+0000] {dagbag.py:343} ERROR - Failed to import: /opt/airflow/dags/etl_scripts/etl_atendimentos_dl.py
Traceback (most recent call last):
  File "/home/airflow/.local/lib/python3.7/site-packages/airflow/models/dagbag.py", line 339, in parse
    loader.exec_module(new_module)
  File "<frozen importlib._bootstrap_external>", line 728, in exec_module
  File "<frozen importlib._bootstrap>", line 219, in _call_with_frames_removed
  File "/opt/airflow/dags/etl_scripts/etl_atendimentos_dl.py", line 18, in <module>
    usuario = config.get('Database', 'user')
  File "/usr/local/lib/python3.7/configparser.py", line 780, in get
    d = self._unify_values(section, vars)
  File "/usr/local/lib/python3.7/configparser.py", line 1146, in _unify_values
    raise NoSectionError(section) from None
configparser.NoSectionError: No section: 'Database'
[2024-01-26T15:58:16.282+0000] {processor.py:755} WARNING - No viable dags retrieved from /opt/airflow/dags/etl_scripts/etl_atendimentos_dl.py
[2024-01-26T15:58:16.302+0000] {processor.py:175} INFO - Processing /opt/airflow/dags/etl_scripts/etl_atendimentos_dl.py took 0.341 seconds
[2024-01-26T15:58:46.363+0000] {processor.py:153} INFO - Started process (PID=14680) to work on /opt/airflow/dags/etl_scripts/etl_atendimentos_dl.py
[2024-01-26T15:58:46.364+0000] {processor.py:743} INFO - Processing file /opt/airflow/dags/etl_scripts/etl_atendimentos_dl.py for tasks to queue
[2024-01-26T15:58:46.365+0000] {logging_mixin.py:137} INFO - [2024-01-26T15:58:46.365+0000] {dagbag.py:538} INFO - Filling up the DagBag from /opt/airflow/dags/etl_scripts/etl_atendimentos_dl.py
[2024-01-26T15:58:46.655+0000] {logging_mixin.py:137} INFO - [2024-01-26T15:58:46.647+0000] {dagbag.py:343} ERROR - Failed to import: /opt/airflow/dags/etl_scripts/etl_atendimentos_dl.py
Traceback (most recent call last):
  File "/home/airflow/.local/lib/python3.7/site-packages/airflow/models/dagbag.py", line 339, in parse
    loader.exec_module(new_module)
  File "<frozen importlib._bootstrap_external>", line 728, in exec_module
  File "<frozen importlib._bootstrap>", line 219, in _call_with_frames_removed
  File "/opt/airflow/dags/etl_scripts/etl_atendimentos_dl.py", line 18, in <module>
    usuario = config.get('Database', 'user')
  File "/usr/local/lib/python3.7/configparser.py", line 780, in get
    d = self._unify_values(section, vars)
  File "/usr/local/lib/python3.7/configparser.py", line 1146, in _unify_values
    raise NoSectionError(section) from None
configparser.NoSectionError: No section: 'Database'
[2024-01-26T15:58:46.656+0000] {processor.py:755} WARNING - No viable dags retrieved from /opt/airflow/dags/etl_scripts/etl_atendimentos_dl.py
[2024-01-26T15:58:47.147+0000] {processor.py:175} INFO - Processing /opt/airflow/dags/etl_scripts/etl_atendimentos_dl.py took 0.787 seconds
[2024-01-26T15:59:17.798+0000] {processor.py:153} INFO - Started process (PID=14731) to work on /opt/airflow/dags/etl_scripts/etl_atendimentos_dl.py
[2024-01-26T15:59:17.800+0000] {processor.py:743} INFO - Processing file /opt/airflow/dags/etl_scripts/etl_atendimentos_dl.py for tasks to queue
[2024-01-26T15:59:17.801+0000] {logging_mixin.py:137} INFO - [2024-01-26T15:59:17.801+0000] {dagbag.py:538} INFO - Filling up the DagBag from /opt/airflow/dags/etl_scripts/etl_atendimentos_dl.py
[2024-01-26T15:59:18.242+0000] {logging_mixin.py:137} INFO - [2024-01-26T15:59:18.234+0000] {dagbag.py:343} ERROR - Failed to import: /opt/airflow/dags/etl_scripts/etl_atendimentos_dl.py
Traceback (most recent call last):
  File "/home/airflow/.local/lib/python3.7/site-packages/airflow/models/dagbag.py", line 339, in parse
    loader.exec_module(new_module)
  File "<frozen importlib._bootstrap_external>", line 728, in exec_module
  File "<frozen importlib._bootstrap>", line 219, in _call_with_frames_removed
  File "/opt/airflow/dags/etl_scripts/etl_atendimentos_dl.py", line 18, in <module>
    usuario = config.get('Database', 'user')
  File "/usr/local/lib/python3.7/configparser.py", line 780, in get
    d = self._unify_values(section, vars)
  File "/usr/local/lib/python3.7/configparser.py", line 1146, in _unify_values
    raise NoSectionError(section) from None
configparser.NoSectionError: No section: 'Database'
[2024-01-26T15:59:18.243+0000] {processor.py:755} WARNING - No viable dags retrieved from /opt/airflow/dags/etl_scripts/etl_atendimentos_dl.py
[2024-01-26T15:59:18.272+0000] {processor.py:175} INFO - Processing /opt/airflow/dags/etl_scripts/etl_atendimentos_dl.py took 0.477 seconds
[2024-01-26T15:59:49.158+0000] {processor.py:153} INFO - Started process (PID=14766) to work on /opt/airflow/dags/etl_scripts/etl_atendimentos_dl.py
[2024-01-26T15:59:49.159+0000] {processor.py:743} INFO - Processing file /opt/airflow/dags/etl_scripts/etl_atendimentos_dl.py for tasks to queue
[2024-01-26T15:59:49.160+0000] {logging_mixin.py:137} INFO - [2024-01-26T15:59:49.160+0000] {dagbag.py:538} INFO - Filling up the DagBag from /opt/airflow/dags/etl_scripts/etl_atendimentos_dl.py
[2024-01-26T15:59:49.421+0000] {logging_mixin.py:137} INFO - [2024-01-26T15:59:49.414+0000] {dagbag.py:343} ERROR - Failed to import: /opt/airflow/dags/etl_scripts/etl_atendimentos_dl.py
Traceback (most recent call last):
  File "/home/airflow/.local/lib/python3.7/site-packages/airflow/models/dagbag.py", line 339, in parse
    loader.exec_module(new_module)
  File "<frozen importlib._bootstrap_external>", line 728, in exec_module
  File "<frozen importlib._bootstrap>", line 219, in _call_with_frames_removed
  File "/opt/airflow/dags/etl_scripts/etl_atendimentos_dl.py", line 18, in <module>
    usuario = config.get('Database', 'user')
  File "/usr/local/lib/python3.7/configparser.py", line 780, in get
    d = self._unify_values(section, vars)
  File "/usr/local/lib/python3.7/configparser.py", line 1146, in _unify_values
    raise NoSectionError(section) from None
configparser.NoSectionError: No section: 'Database'
[2024-01-26T15:59:49.422+0000] {processor.py:755} WARNING - No viable dags retrieved from /opt/airflow/dags/etl_scripts/etl_atendimentos_dl.py
[2024-01-26T15:59:49.442+0000] {processor.py:175} INFO - Processing /opt/airflow/dags/etl_scripts/etl_atendimentos_dl.py took 0.287 seconds
[2024-01-26T16:00:19.543+0000] {processor.py:153} INFO - Started process (PID=14801) to work on /opt/airflow/dags/etl_scripts/etl_atendimentos_dl.py
[2024-01-26T16:00:19.544+0000] {processor.py:743} INFO - Processing file /opt/airflow/dags/etl_scripts/etl_atendimentos_dl.py for tasks to queue
[2024-01-26T16:00:19.545+0000] {logging_mixin.py:137} INFO - [2024-01-26T16:00:19.545+0000] {dagbag.py:538} INFO - Filling up the DagBag from /opt/airflow/dags/etl_scripts/etl_atendimentos_dl.py
[2024-01-26T16:00:19.802+0000] {logging_mixin.py:137} INFO - [2024-01-26T16:00:19.795+0000] {dagbag.py:343} ERROR - Failed to import: /opt/airflow/dags/etl_scripts/etl_atendimentos_dl.py
Traceback (most recent call last):
  File "/home/airflow/.local/lib/python3.7/site-packages/airflow/models/dagbag.py", line 339, in parse
    loader.exec_module(new_module)
  File "<frozen importlib._bootstrap_external>", line 728, in exec_module
  File "<frozen importlib._bootstrap>", line 219, in _call_with_frames_removed
  File "/opt/airflow/dags/etl_scripts/etl_atendimentos_dl.py", line 18, in <module>
    usuario = config.get('Database', 'user')
  File "/usr/local/lib/python3.7/configparser.py", line 780, in get
    d = self._unify_values(section, vars)
  File "/usr/local/lib/python3.7/configparser.py", line 1146, in _unify_values
    raise NoSectionError(section) from None
configparser.NoSectionError: No section: 'Database'
[2024-01-26T16:00:19.802+0000] {processor.py:755} WARNING - No viable dags retrieved from /opt/airflow/dags/etl_scripts/etl_atendimentos_dl.py
[2024-01-26T16:00:19.821+0000] {processor.py:175} INFO - Processing /opt/airflow/dags/etl_scripts/etl_atendimentos_dl.py took 0.281 seconds
[2024-01-26T16:00:49.935+0000] {processor.py:153} INFO - Started process (PID=14852) to work on /opt/airflow/dags/etl_scripts/etl_atendimentos_dl.py
[2024-01-26T16:00:49.936+0000] {processor.py:743} INFO - Processing file /opt/airflow/dags/etl_scripts/etl_atendimentos_dl.py for tasks to queue
[2024-01-26T16:00:49.938+0000] {logging_mixin.py:137} INFO - [2024-01-26T16:00:49.938+0000] {dagbag.py:538} INFO - Filling up the DagBag from /opt/airflow/dags/etl_scripts/etl_atendimentos_dl.py
[2024-01-26T16:00:50.244+0000] {logging_mixin.py:137} INFO - [2024-01-26T16:00:50.237+0000] {dagbag.py:343} ERROR - Failed to import: /opt/airflow/dags/etl_scripts/etl_atendimentos_dl.py
Traceback (most recent call last):
  File "/home/airflow/.local/lib/python3.7/site-packages/airflow/models/dagbag.py", line 339, in parse
    loader.exec_module(new_module)
  File "<frozen importlib._bootstrap_external>", line 728, in exec_module
  File "<frozen importlib._bootstrap>", line 219, in _call_with_frames_removed
  File "/opt/airflow/dags/etl_scripts/etl_atendimentos_dl.py", line 18, in <module>
    usuario = config.get('Database', 'user')
  File "/usr/local/lib/python3.7/configparser.py", line 780, in get
    d = self._unify_values(section, vars)
  File "/usr/local/lib/python3.7/configparser.py", line 1146, in _unify_values
    raise NoSectionError(section) from None
configparser.NoSectionError: No section: 'Database'
[2024-01-26T16:00:50.245+0000] {processor.py:755} WARNING - No viable dags retrieved from /opt/airflow/dags/etl_scripts/etl_atendimentos_dl.py
[2024-01-26T16:00:50.266+0000] {processor.py:175} INFO - Processing /opt/airflow/dags/etl_scripts/etl_atendimentos_dl.py took 0.334 seconds
[2024-01-26T16:01:20.575+0000] {processor.py:153} INFO - Started process (PID=14887) to work on /opt/airflow/dags/etl_scripts/etl_atendimentos_dl.py
[2024-01-26T16:01:20.576+0000] {processor.py:743} INFO - Processing file /opt/airflow/dags/etl_scripts/etl_atendimentos_dl.py for tasks to queue
[2024-01-26T16:01:20.577+0000] {logging_mixin.py:137} INFO - [2024-01-26T16:01:20.577+0000] {dagbag.py:538} INFO - Filling up the DagBag from /opt/airflow/dags/etl_scripts/etl_atendimentos_dl.py
[2024-01-26T16:01:20.881+0000] {logging_mixin.py:137} INFO - [2024-01-26T16:01:20.873+0000] {dagbag.py:343} ERROR - Failed to import: /opt/airflow/dags/etl_scripts/etl_atendimentos_dl.py
Traceback (most recent call last):
  File "/home/airflow/.local/lib/python3.7/site-packages/airflow/models/dagbag.py", line 339, in parse
    loader.exec_module(new_module)
  File "<frozen importlib._bootstrap_external>", line 728, in exec_module
  File "<frozen importlib._bootstrap>", line 219, in _call_with_frames_removed
  File "/opt/airflow/dags/etl_scripts/etl_atendimentos_dl.py", line 18, in <module>
    usuario = config.get('Database', 'user')
  File "/usr/local/lib/python3.7/configparser.py", line 780, in get
    d = self._unify_values(section, vars)
  File "/usr/local/lib/python3.7/configparser.py", line 1146, in _unify_values
    raise NoSectionError(section) from None
configparser.NoSectionError: No section: 'Database'
[2024-01-26T16:01:20.882+0000] {processor.py:755} WARNING - No viable dags retrieved from /opt/airflow/dags/etl_scripts/etl_atendimentos_dl.py
[2024-01-26T16:01:20.902+0000] {processor.py:175} INFO - Processing /opt/airflow/dags/etl_scripts/etl_atendimentos_dl.py took 0.331 seconds
[2024-01-26T16:01:51.035+0000] {processor.py:153} INFO - Started process (PID=14922) to work on /opt/airflow/dags/etl_scripts/etl_atendimentos_dl.py
[2024-01-26T16:01:51.036+0000] {processor.py:743} INFO - Processing file /opt/airflow/dags/etl_scripts/etl_atendimentos_dl.py for tasks to queue
[2024-01-26T16:01:51.037+0000] {logging_mixin.py:137} INFO - [2024-01-26T16:01:51.037+0000] {dagbag.py:538} INFO - Filling up the DagBag from /opt/airflow/dags/etl_scripts/etl_atendimentos_dl.py
[2024-01-26T16:01:51.345+0000] {logging_mixin.py:137} INFO - [2024-01-26T16:01:51.338+0000] {dagbag.py:343} ERROR - Failed to import: /opt/airflow/dags/etl_scripts/etl_atendimentos_dl.py
Traceback (most recent call last):
  File "/home/airflow/.local/lib/python3.7/site-packages/airflow/models/dagbag.py", line 339, in parse
    loader.exec_module(new_module)
  File "<frozen importlib._bootstrap_external>", line 728, in exec_module
  File "<frozen importlib._bootstrap>", line 219, in _call_with_frames_removed
  File "/opt/airflow/dags/etl_scripts/etl_atendimentos_dl.py", line 18, in <module>
    usuario = config.get('Database', 'user')
  File "/usr/local/lib/python3.7/configparser.py", line 780, in get
    d = self._unify_values(section, vars)
  File "/usr/local/lib/python3.7/configparser.py", line 1146, in _unify_values
    raise NoSectionError(section) from None
configparser.NoSectionError: No section: 'Database'
[2024-01-26T16:01:51.346+0000] {processor.py:755} WARNING - No viable dags retrieved from /opt/airflow/dags/etl_scripts/etl_atendimentos_dl.py
[2024-01-26T16:01:51.377+0000] {processor.py:175} INFO - Processing /opt/airflow/dags/etl_scripts/etl_atendimentos_dl.py took 0.348 seconds
[2024-01-26T16:02:14.242+0000] {processor.py:153} INFO - Started process (PID=14956) to work on /opt/airflow/dags/etl_scripts/etl_atendimentos_dl.py
[2024-01-26T16:02:14.243+0000] {processor.py:743} INFO - Processing file /opt/airflow/dags/etl_scripts/etl_atendimentos_dl.py for tasks to queue
[2024-01-26T16:02:14.245+0000] {logging_mixin.py:137} INFO - [2024-01-26T16:02:14.244+0000] {dagbag.py:538} INFO - Filling up the DagBag from /opt/airflow/dags/etl_scripts/etl_atendimentos_dl.py
[2024-01-26T16:02:14.785+0000] {logging_mixin.py:137} INFO - [2024-01-26T16:02:14.778+0000] {dagbag.py:343} ERROR - Failed to import: /opt/airflow/dags/etl_scripts/etl_atendimentos_dl.py
Traceback (most recent call last):
  File "/home/airflow/.local/lib/python3.7/site-packages/airflow/models/dagbag.py", line 339, in parse
    loader.exec_module(new_module)
  File "<frozen importlib._bootstrap_external>", line 728, in exec_module
  File "<frozen importlib._bootstrap>", line 219, in _call_with_frames_removed
  File "/opt/airflow/dags/etl_scripts/etl_atendimentos_dl.py", line 18, in <module>
    usuario = config.get('Database', 'user')
  File "/usr/local/lib/python3.7/configparser.py", line 780, in get
    d = self._unify_values(section, vars)
  File "/usr/local/lib/python3.7/configparser.py", line 1146, in _unify_values
    raise NoSectionError(section) from None
configparser.NoSectionError: No section: 'Database'
[2024-01-26T16:02:14.786+0000] {processor.py:755} WARNING - No viable dags retrieved from /opt/airflow/dags/etl_scripts/etl_atendimentos_dl.py
[2024-01-26T16:02:14.805+0000] {processor.py:175} INFO - Processing /opt/airflow/dags/etl_scripts/etl_atendimentos_dl.py took 0.568 seconds
[2024-01-26T16:02:42.846+0000] {processor.py:153} INFO - Started process (PID=14991) to work on /opt/airflow/dags/etl_scripts/etl_atendimentos_dl.py
[2024-01-26T16:02:42.847+0000] {processor.py:743} INFO - Processing file /opt/airflow/dags/etl_scripts/etl_atendimentos_dl.py for tasks to queue
[2024-01-26T16:02:42.848+0000] {logging_mixin.py:137} INFO - [2024-01-26T16:02:42.848+0000] {dagbag.py:538} INFO - Filling up the DagBag from /opt/airflow/dags/etl_scripts/etl_atendimentos_dl.py
[2024-01-26T16:02:43.230+0000] {logging_mixin.py:137} INFO - [2024-01-26T16:02:43.222+0000] {dagbag.py:343} ERROR - Failed to import: /opt/airflow/dags/etl_scripts/etl_atendimentos_dl.py
Traceback (most recent call last):
  File "/home/airflow/.local/lib/python3.7/site-packages/airflow/models/dagbag.py", line 339, in parse
    loader.exec_module(new_module)
  File "<frozen importlib._bootstrap_external>", line 728, in exec_module
  File "<frozen importlib._bootstrap>", line 219, in _call_with_frames_removed
  File "/opt/airflow/dags/etl_scripts/etl_atendimentos_dl.py", line 18, in <module>
    usuario = config.get('Database', 'user')
  File "/usr/local/lib/python3.7/configparser.py", line 780, in get
    d = self._unify_values(section, vars)
  File "/usr/local/lib/python3.7/configparser.py", line 1146, in _unify_values
    raise NoSectionError(section) from None
configparser.NoSectionError: No section: 'Database'
[2024-01-26T16:02:43.231+0000] {processor.py:755} WARNING - No viable dags retrieved from /opt/airflow/dags/etl_scripts/etl_atendimentos_dl.py
[2024-01-26T16:02:43.252+0000] {processor.py:175} INFO - Processing /opt/airflow/dags/etl_scripts/etl_atendimentos_dl.py took 0.411 seconds
[2024-01-26T16:03:13.431+0000] {processor.py:153} INFO - Started process (PID=15026) to work on /opt/airflow/dags/etl_scripts/etl_atendimentos_dl.py
[2024-01-26T16:03:13.433+0000] {processor.py:743} INFO - Processing file /opt/airflow/dags/etl_scripts/etl_atendimentos_dl.py for tasks to queue
[2024-01-26T16:03:13.434+0000] {logging_mixin.py:137} INFO - [2024-01-26T16:03:13.434+0000] {dagbag.py:538} INFO - Filling up the DagBag from /opt/airflow/dags/etl_scripts/etl_atendimentos_dl.py
[2024-01-26T16:03:13.746+0000] {logging_mixin.py:137} INFO - [2024-01-26T16:03:13.739+0000] {dagbag.py:343} ERROR - Failed to import: /opt/airflow/dags/etl_scripts/etl_atendimentos_dl.py
Traceback (most recent call last):
  File "/home/airflow/.local/lib/python3.7/site-packages/airflow/models/dagbag.py", line 339, in parse
    loader.exec_module(new_module)
  File "<frozen importlib._bootstrap_external>", line 728, in exec_module
  File "<frozen importlib._bootstrap>", line 219, in _call_with_frames_removed
  File "/opt/airflow/dags/etl_scripts/etl_atendimentos_dl.py", line 18, in <module>
    usuario = config.get('Database', 'user')
  File "/usr/local/lib/python3.7/configparser.py", line 780, in get
    d = self._unify_values(section, vars)
  File "/usr/local/lib/python3.7/configparser.py", line 1146, in _unify_values
    raise NoSectionError(section) from None
configparser.NoSectionError: No section: 'Database'
[2024-01-26T16:03:13.747+0000] {processor.py:755} WARNING - No viable dags retrieved from /opt/airflow/dags/etl_scripts/etl_atendimentos_dl.py
[2024-01-26T16:03:13.769+0000] {processor.py:175} INFO - Processing /opt/airflow/dags/etl_scripts/etl_atendimentos_dl.py took 0.341 seconds
[2024-01-26T16:03:44.694+0000] {processor.py:153} INFO - Started process (PID=15077) to work on /opt/airflow/dags/etl_scripts/etl_atendimentos_dl.py
[2024-01-26T16:03:44.695+0000] {processor.py:743} INFO - Processing file /opt/airflow/dags/etl_scripts/etl_atendimentos_dl.py for tasks to queue
[2024-01-26T16:03:44.696+0000] {logging_mixin.py:137} INFO - [2024-01-26T16:03:44.696+0000] {dagbag.py:538} INFO - Filling up the DagBag from /opt/airflow/dags/etl_scripts/etl_atendimentos_dl.py
[2024-01-26T16:03:44.975+0000] {logging_mixin.py:137} INFO - [2024-01-26T16:03:44.968+0000] {dagbag.py:343} ERROR - Failed to import: /opt/airflow/dags/etl_scripts/etl_atendimentos_dl.py
Traceback (most recent call last):
  File "/home/airflow/.local/lib/python3.7/site-packages/airflow/models/dagbag.py", line 339, in parse
    loader.exec_module(new_module)
  File "<frozen importlib._bootstrap_external>", line 728, in exec_module
  File "<frozen importlib._bootstrap>", line 219, in _call_with_frames_removed
  File "/opt/airflow/dags/etl_scripts/etl_atendimentos_dl.py", line 18, in <module>
    usuario = config.get('Database', 'user')
  File "/usr/local/lib/python3.7/configparser.py", line 780, in get
    d = self._unify_values(section, vars)
  File "/usr/local/lib/python3.7/configparser.py", line 1146, in _unify_values
    raise NoSectionError(section) from None
configparser.NoSectionError: No section: 'Database'
[2024-01-26T16:03:44.975+0000] {processor.py:755} WARNING - No viable dags retrieved from /opt/airflow/dags/etl_scripts/etl_atendimentos_dl.py
[2024-01-26T16:03:44.996+0000] {processor.py:175} INFO - Processing /opt/airflow/dags/etl_scripts/etl_atendimentos_dl.py took 0.306 seconds
[2024-01-26T16:04:15.294+0000] {processor.py:153} INFO - Started process (PID=15112) to work on /opt/airflow/dags/etl_scripts/etl_atendimentos_dl.py
[2024-01-26T16:04:15.295+0000] {processor.py:743} INFO - Processing file /opt/airflow/dags/etl_scripts/etl_atendimentos_dl.py for tasks to queue
[2024-01-26T16:04:15.296+0000] {logging_mixin.py:137} INFO - [2024-01-26T16:04:15.296+0000] {dagbag.py:538} INFO - Filling up the DagBag from /opt/airflow/dags/etl_scripts/etl_atendimentos_dl.py
[2024-01-26T16:04:15.582+0000] {logging_mixin.py:137} INFO - [2024-01-26T16:04:15.575+0000] {dagbag.py:343} ERROR - Failed to import: /opt/airflow/dags/etl_scripts/etl_atendimentos_dl.py
Traceback (most recent call last):
  File "/home/airflow/.local/lib/python3.7/site-packages/airflow/models/dagbag.py", line 339, in parse
    loader.exec_module(new_module)
  File "<frozen importlib._bootstrap_external>", line 728, in exec_module
  File "<frozen importlib._bootstrap>", line 219, in _call_with_frames_removed
  File "/opt/airflow/dags/etl_scripts/etl_atendimentos_dl.py", line 18, in <module>
    usuario = config.get('Database', 'user')
  File "/usr/local/lib/python3.7/configparser.py", line 780, in get
    d = self._unify_values(section, vars)
  File "/usr/local/lib/python3.7/configparser.py", line 1146, in _unify_values
    raise NoSectionError(section) from None
configparser.NoSectionError: No section: 'Database'
[2024-01-26T16:04:15.582+0000] {processor.py:755} WARNING - No viable dags retrieved from /opt/airflow/dags/etl_scripts/etl_atendimentos_dl.py
[2024-01-26T16:04:15.603+0000] {processor.py:175} INFO - Processing /opt/airflow/dags/etl_scripts/etl_atendimentos_dl.py took 0.313 seconds
[2024-01-26T16:04:45.736+0000] {processor.py:153} INFO - Started process (PID=15156) to work on /opt/airflow/dags/etl_scripts/etl_atendimentos_dl.py
[2024-01-26T16:04:45.737+0000] {processor.py:743} INFO - Processing file /opt/airflow/dags/etl_scripts/etl_atendimentos_dl.py for tasks to queue
[2024-01-26T16:04:45.739+0000] {logging_mixin.py:137} INFO - [2024-01-26T16:04:45.738+0000] {dagbag.py:538} INFO - Filling up the DagBag from /opt/airflow/dags/etl_scripts/etl_atendimentos_dl.py
[2024-01-26T16:04:46.091+0000] {logging_mixin.py:137} INFO - [2024-01-26T16:04:46.082+0000] {dagbag.py:343} ERROR - Failed to import: /opt/airflow/dags/etl_scripts/etl_atendimentos_dl.py
Traceback (most recent call last):
  File "/home/airflow/.local/lib/python3.7/site-packages/airflow/models/dagbag.py", line 339, in parse
    loader.exec_module(new_module)
  File "<frozen importlib._bootstrap_external>", line 728, in exec_module
  File "<frozen importlib._bootstrap>", line 219, in _call_with_frames_removed
  File "/opt/airflow/dags/etl_scripts/etl_atendimentos_dl.py", line 18, in <module>
    usuario = config.get('Database', 'user')
  File "/usr/local/lib/python3.7/configparser.py", line 780, in get
    d = self._unify_values(section, vars)
  File "/usr/local/lib/python3.7/configparser.py", line 1146, in _unify_values
    raise NoSectionError(section) from None
configparser.NoSectionError: No section: 'Database'
[2024-01-26T16:04:46.092+0000] {processor.py:755} WARNING - No viable dags retrieved from /opt/airflow/dags/etl_scripts/etl_atendimentos_dl.py
[2024-01-26T16:04:46.113+0000] {processor.py:175} INFO - Processing /opt/airflow/dags/etl_scripts/etl_atendimentos_dl.py took 0.382 seconds
[2024-01-26T16:05:17.013+0000] {processor.py:153} INFO - Started process (PID=15198) to work on /opt/airflow/dags/etl_scripts/etl_atendimentos_dl.py
[2024-01-26T16:05:17.015+0000] {processor.py:743} INFO - Processing file /opt/airflow/dags/etl_scripts/etl_atendimentos_dl.py for tasks to queue
[2024-01-26T16:05:17.016+0000] {logging_mixin.py:137} INFO - [2024-01-26T16:05:17.016+0000] {dagbag.py:538} INFO - Filling up the DagBag from /opt/airflow/dags/etl_scripts/etl_atendimentos_dl.py
[2024-01-26T16:05:17.305+0000] {logging_mixin.py:137} INFO - [2024-01-26T16:05:17.297+0000] {dagbag.py:343} ERROR - Failed to import: /opt/airflow/dags/etl_scripts/etl_atendimentos_dl.py
Traceback (most recent call last):
  File "/home/airflow/.local/lib/python3.7/site-packages/airflow/models/dagbag.py", line 339, in parse
    loader.exec_module(new_module)
  File "<frozen importlib._bootstrap_external>", line 728, in exec_module
  File "<frozen importlib._bootstrap>", line 219, in _call_with_frames_removed
  File "/opt/airflow/dags/etl_scripts/etl_atendimentos_dl.py", line 18, in <module>
    usuario = config.get('Database', 'user')
  File "/usr/local/lib/python3.7/configparser.py", line 780, in get
    d = self._unify_values(section, vars)
  File "/usr/local/lib/python3.7/configparser.py", line 1146, in _unify_values
    raise NoSectionError(section) from None
configparser.NoSectionError: No section: 'Database'
[2024-01-26T16:05:17.306+0000] {processor.py:755} WARNING - No viable dags retrieved from /opt/airflow/dags/etl_scripts/etl_atendimentos_dl.py
[2024-01-26T16:05:17.329+0000] {processor.py:175} INFO - Processing /opt/airflow/dags/etl_scripts/etl_atendimentos_dl.py took 0.318 seconds
[2024-01-26T16:05:47.402+0000] {processor.py:153} INFO - Started process (PID=15233) to work on /opt/airflow/dags/etl_scripts/etl_atendimentos_dl.py
[2024-01-26T16:05:47.403+0000] {processor.py:743} INFO - Processing file /opt/airflow/dags/etl_scripts/etl_atendimentos_dl.py for tasks to queue
[2024-01-26T16:05:47.405+0000] {logging_mixin.py:137} INFO - [2024-01-26T16:05:47.404+0000] {dagbag.py:538} INFO - Filling up the DagBag from /opt/airflow/dags/etl_scripts/etl_atendimentos_dl.py
[2024-01-26T16:05:47.785+0000] {logging_mixin.py:137} INFO - [2024-01-26T16:05:47.778+0000] {dagbag.py:343} ERROR - Failed to import: /opt/airflow/dags/etl_scripts/etl_atendimentos_dl.py
Traceback (most recent call last):
  File "/home/airflow/.local/lib/python3.7/site-packages/airflow/models/dagbag.py", line 339, in parse
    loader.exec_module(new_module)
  File "<frozen importlib._bootstrap_external>", line 728, in exec_module
  File "<frozen importlib._bootstrap>", line 219, in _call_with_frames_removed
  File "/opt/airflow/dags/etl_scripts/etl_atendimentos_dl.py", line 18, in <module>
    usuario = config.get('Database', 'user')
  File "/usr/local/lib/python3.7/configparser.py", line 780, in get
    d = self._unify_values(section, vars)
  File "/usr/local/lib/python3.7/configparser.py", line 1146, in _unify_values
    raise NoSectionError(section) from None
configparser.NoSectionError: No section: 'Database'
[2024-01-26T16:05:47.787+0000] {processor.py:755} WARNING - No viable dags retrieved from /opt/airflow/dags/etl_scripts/etl_atendimentos_dl.py
[2024-01-26T16:05:47.812+0000] {processor.py:175} INFO - Processing /opt/airflow/dags/etl_scripts/etl_atendimentos_dl.py took 0.414 seconds
[2024-01-26T16:06:17.949+0000] {processor.py:153} INFO - Started process (PID=15268) to work on /opt/airflow/dags/etl_scripts/etl_atendimentos_dl.py
[2024-01-26T16:06:17.950+0000] {processor.py:743} INFO - Processing file /opt/airflow/dags/etl_scripts/etl_atendimentos_dl.py for tasks to queue
[2024-01-26T16:06:17.951+0000] {logging_mixin.py:137} INFO - [2024-01-26T16:06:17.951+0000] {dagbag.py:538} INFO - Filling up the DagBag from /opt/airflow/dags/etl_scripts/etl_atendimentos_dl.py
[2024-01-26T16:06:18.231+0000] {logging_mixin.py:137} INFO - [2024-01-26T16:06:18.223+0000] {dagbag.py:343} ERROR - Failed to import: /opt/airflow/dags/etl_scripts/etl_atendimentos_dl.py
Traceback (most recent call last):
  File "/home/airflow/.local/lib/python3.7/site-packages/airflow/models/dagbag.py", line 339, in parse
    loader.exec_module(new_module)
  File "<frozen importlib._bootstrap_external>", line 728, in exec_module
  File "<frozen importlib._bootstrap>", line 219, in _call_with_frames_removed
  File "/opt/airflow/dags/etl_scripts/etl_atendimentos_dl.py", line 18, in <module>
    usuario = config.get('Database', 'user')
  File "/usr/local/lib/python3.7/configparser.py", line 780, in get
    d = self._unify_values(section, vars)
  File "/usr/local/lib/python3.7/configparser.py", line 1146, in _unify_values
    raise NoSectionError(section) from None
configparser.NoSectionError: No section: 'Database'
[2024-01-26T16:06:18.232+0000] {processor.py:755} WARNING - No viable dags retrieved from /opt/airflow/dags/etl_scripts/etl_atendimentos_dl.py
[2024-01-26T16:06:18.251+0000] {processor.py:175} INFO - Processing /opt/airflow/dags/etl_scripts/etl_atendimentos_dl.py took 0.306 seconds
[2024-01-26T16:06:48.547+0000] {processor.py:153} INFO - Started process (PID=15303) to work on /opt/airflow/dags/etl_scripts/etl_atendimentos_dl.py
[2024-01-26T16:06:48.548+0000] {processor.py:743} INFO - Processing file /opt/airflow/dags/etl_scripts/etl_atendimentos_dl.py for tasks to queue
[2024-01-26T16:06:48.550+0000] {logging_mixin.py:137} INFO - [2024-01-26T16:06:48.549+0000] {dagbag.py:538} INFO - Filling up the DagBag from /opt/airflow/dags/etl_scripts/etl_atendimentos_dl.py
[2024-01-26T16:06:49.032+0000] {logging_mixin.py:137} INFO - [2024-01-26T16:06:49.017+0000] {dagbag.py:343} ERROR - Failed to import: /opt/airflow/dags/etl_scripts/etl_atendimentos_dl.py
Traceback (most recent call last):
  File "/home/airflow/.local/lib/python3.7/site-packages/airflow/models/dagbag.py", line 339, in parse
    loader.exec_module(new_module)
  File "<frozen importlib._bootstrap_external>", line 728, in exec_module
  File "<frozen importlib._bootstrap>", line 219, in _call_with_frames_removed
  File "/opt/airflow/dags/etl_scripts/etl_atendimentos_dl.py", line 18, in <module>
    usuario = config.get('Database', 'user')
  File "/usr/local/lib/python3.7/configparser.py", line 780, in get
    d = self._unify_values(section, vars)
  File "/usr/local/lib/python3.7/configparser.py", line 1146, in _unify_values
    raise NoSectionError(section) from None
configparser.NoSectionError: No section: 'Database'
[2024-01-26T16:06:49.033+0000] {processor.py:755} WARNING - No viable dags retrieved from /opt/airflow/dags/etl_scripts/etl_atendimentos_dl.py
[2024-01-26T16:06:49.073+0000] {processor.py:175} INFO - Processing /opt/airflow/dags/etl_scripts/etl_atendimentos_dl.py took 0.530 seconds
[2024-01-26T16:07:19.904+0000] {processor.py:153} INFO - Started process (PID=15354) to work on /opt/airflow/dags/etl_scripts/etl_atendimentos_dl.py
[2024-01-26T16:07:19.905+0000] {processor.py:743} INFO - Processing file /opt/airflow/dags/etl_scripts/etl_atendimentos_dl.py for tasks to queue
[2024-01-26T16:07:19.906+0000] {logging_mixin.py:137} INFO - [2024-01-26T16:07:19.906+0000] {dagbag.py:538} INFO - Filling up the DagBag from /opt/airflow/dags/etl_scripts/etl_atendimentos_dl.py
[2024-01-26T16:07:20.237+0000] {logging_mixin.py:137} INFO - [2024-01-26T16:07:20.230+0000] {dagbag.py:343} ERROR - Failed to import: /opt/airflow/dags/etl_scripts/etl_atendimentos_dl.py
Traceback (most recent call last):
  File "/home/airflow/.local/lib/python3.7/site-packages/airflow/models/dagbag.py", line 339, in parse
    loader.exec_module(new_module)
  File "<frozen importlib._bootstrap_external>", line 728, in exec_module
  File "<frozen importlib._bootstrap>", line 219, in _call_with_frames_removed
  File "/opt/airflow/dags/etl_scripts/etl_atendimentos_dl.py", line 18, in <module>
    usuario = config.get('Database', 'user')
  File "/usr/local/lib/python3.7/configparser.py", line 780, in get
    d = self._unify_values(section, vars)
  File "/usr/local/lib/python3.7/configparser.py", line 1146, in _unify_values
    raise NoSectionError(section) from None
configparser.NoSectionError: No section: 'Database'
[2024-01-26T16:07:20.238+0000] {processor.py:755} WARNING - No viable dags retrieved from /opt/airflow/dags/etl_scripts/etl_atendimentos_dl.py
[2024-01-26T16:07:20.259+0000] {processor.py:175} INFO - Processing /opt/airflow/dags/etl_scripts/etl_atendimentos_dl.py took 0.357 seconds
[2024-01-26T16:07:50.413+0000] {processor.py:153} INFO - Started process (PID=15389) to work on /opt/airflow/dags/etl_scripts/etl_atendimentos_dl.py
[2024-01-26T16:07:50.415+0000] {processor.py:743} INFO - Processing file /opt/airflow/dags/etl_scripts/etl_atendimentos_dl.py for tasks to queue
[2024-01-26T16:07:50.416+0000] {logging_mixin.py:137} INFO - [2024-01-26T16:07:50.416+0000] {dagbag.py:538} INFO - Filling up the DagBag from /opt/airflow/dags/etl_scripts/etl_atendimentos_dl.py
[2024-01-26T16:07:50.796+0000] {logging_mixin.py:137} INFO - [2024-01-26T16:07:50.787+0000] {dagbag.py:343} ERROR - Failed to import: /opt/airflow/dags/etl_scripts/etl_atendimentos_dl.py
Traceback (most recent call last):
  File "/home/airflow/.local/lib/python3.7/site-packages/airflow/models/dagbag.py", line 339, in parse
    loader.exec_module(new_module)
  File "<frozen importlib._bootstrap_external>", line 728, in exec_module
  File "<frozen importlib._bootstrap>", line 219, in _call_with_frames_removed
  File "/opt/airflow/dags/etl_scripts/etl_atendimentos_dl.py", line 18, in <module>
    usuario = config.get('Database', 'user')
  File "/usr/local/lib/python3.7/configparser.py", line 780, in get
    d = self._unify_values(section, vars)
  File "/usr/local/lib/python3.7/configparser.py", line 1146, in _unify_values
    raise NoSectionError(section) from None
configparser.NoSectionError: No section: 'Database'
[2024-01-26T16:07:50.797+0000] {processor.py:755} WARNING - No viable dags retrieved from /opt/airflow/dags/etl_scripts/etl_atendimentos_dl.py
[2024-01-26T16:07:50.824+0000] {processor.py:175} INFO - Processing /opt/airflow/dags/etl_scripts/etl_atendimentos_dl.py took 0.414 seconds
[2024-01-26T16:08:21.095+0000] {processor.py:153} INFO - Started process (PID=15424) to work on /opt/airflow/dags/etl_scripts/etl_atendimentos_dl.py
[2024-01-26T16:08:21.096+0000] {processor.py:743} INFO - Processing file /opt/airflow/dags/etl_scripts/etl_atendimentos_dl.py for tasks to queue
[2024-01-26T16:08:21.097+0000] {logging_mixin.py:137} INFO - [2024-01-26T16:08:21.097+0000] {dagbag.py:538} INFO - Filling up the DagBag from /opt/airflow/dags/etl_scripts/etl_atendimentos_dl.py
[2024-01-26T16:08:21.450+0000] {logging_mixin.py:137} INFO - [2024-01-26T16:08:21.444+0000] {dagbag.py:343} ERROR - Failed to import: /opt/airflow/dags/etl_scripts/etl_atendimentos_dl.py
Traceback (most recent call last):
  File "/home/airflow/.local/lib/python3.7/site-packages/airflow/models/dagbag.py", line 339, in parse
    loader.exec_module(new_module)
  File "<frozen importlib._bootstrap_external>", line 728, in exec_module
  File "<frozen importlib._bootstrap>", line 219, in _call_with_frames_removed
  File "/opt/airflow/dags/etl_scripts/etl_atendimentos_dl.py", line 18, in <module>
    usuario = config.get('Database', 'user')
  File "/usr/local/lib/python3.7/configparser.py", line 780, in get
    d = self._unify_values(section, vars)
  File "/usr/local/lib/python3.7/configparser.py", line 1146, in _unify_values
    raise NoSectionError(section) from None
configparser.NoSectionError: No section: 'Database'
[2024-01-26T16:08:21.451+0000] {processor.py:755} WARNING - No viable dags retrieved from /opt/airflow/dags/etl_scripts/etl_atendimentos_dl.py
[2024-01-26T16:08:21.473+0000] {processor.py:175} INFO - Processing /opt/airflow/dags/etl_scripts/etl_atendimentos_dl.py took 0.381 seconds
[2024-01-26T16:08:52.383+0000] {processor.py:153} INFO - Started process (PID=15475) to work on /opt/airflow/dags/etl_scripts/etl_atendimentos_dl.py
[2024-01-26T16:08:52.421+0000] {processor.py:743} INFO - Processing file /opt/airflow/dags/etl_scripts/etl_atendimentos_dl.py for tasks to queue
[2024-01-26T16:08:52.423+0000] {logging_mixin.py:137} INFO - [2024-01-26T16:08:52.422+0000] {dagbag.py:538} INFO - Filling up the DagBag from /opt/airflow/dags/etl_scripts/etl_atendimentos_dl.py
[2024-01-26T16:08:52.754+0000] {logging_mixin.py:137} INFO - [2024-01-26T16:08:52.746+0000] {dagbag.py:343} ERROR - Failed to import: /opt/airflow/dags/etl_scripts/etl_atendimentos_dl.py
Traceback (most recent call last):
  File "/home/airflow/.local/lib/python3.7/site-packages/airflow/models/dagbag.py", line 339, in parse
    loader.exec_module(new_module)
  File "<frozen importlib._bootstrap_external>", line 728, in exec_module
  File "<frozen importlib._bootstrap>", line 219, in _call_with_frames_removed
  File "/opt/airflow/dags/etl_scripts/etl_atendimentos_dl.py", line 18, in <module>
    usuario = config.get('Database', 'user')
  File "/usr/local/lib/python3.7/configparser.py", line 780, in get
    d = self._unify_values(section, vars)
  File "/usr/local/lib/python3.7/configparser.py", line 1146, in _unify_values
    raise NoSectionError(section) from None
configparser.NoSectionError: No section: 'Database'
[2024-01-26T16:08:52.755+0000] {processor.py:755} WARNING - No viable dags retrieved from /opt/airflow/dags/etl_scripts/etl_atendimentos_dl.py
[2024-01-26T16:08:52.776+0000] {processor.py:175} INFO - Processing /opt/airflow/dags/etl_scripts/etl_atendimentos_dl.py took 0.398 seconds
[2024-01-26T16:09:22.950+0000] {processor.py:153} INFO - Started process (PID=15510) to work on /opt/airflow/dags/etl_scripts/etl_atendimentos_dl.py
[2024-01-26T16:09:22.951+0000] {processor.py:743} INFO - Processing file /opt/airflow/dags/etl_scripts/etl_atendimentos_dl.py for tasks to queue
[2024-01-26T16:09:22.952+0000] {logging_mixin.py:137} INFO - [2024-01-26T16:09:22.951+0000] {dagbag.py:538} INFO - Filling up the DagBag from /opt/airflow/dags/etl_scripts/etl_atendimentos_dl.py
[2024-01-26T16:09:23.260+0000] {logging_mixin.py:137} INFO - [2024-01-26T16:09:23.252+0000] {dagbag.py:343} ERROR - Failed to import: /opt/airflow/dags/etl_scripts/etl_atendimentos_dl.py
Traceback (most recent call last):
  File "/home/airflow/.local/lib/python3.7/site-packages/airflow/models/dagbag.py", line 339, in parse
    loader.exec_module(new_module)
  File "<frozen importlib._bootstrap_external>", line 728, in exec_module
  File "<frozen importlib._bootstrap>", line 219, in _call_with_frames_removed
  File "/opt/airflow/dags/etl_scripts/etl_atendimentos_dl.py", line 18, in <module>
    usuario = config.get('Database', 'user')
  File "/usr/local/lib/python3.7/configparser.py", line 780, in get
    d = self._unify_values(section, vars)
  File "/usr/local/lib/python3.7/configparser.py", line 1146, in _unify_values
    raise NoSectionError(section) from None
configparser.NoSectionError: No section: 'Database'
[2024-01-26T16:09:23.261+0000] {processor.py:755} WARNING - No viable dags retrieved from /opt/airflow/dags/etl_scripts/etl_atendimentos_dl.py
[2024-01-26T16:09:23.287+0000] {processor.py:175} INFO - Processing /opt/airflow/dags/etl_scripts/etl_atendimentos_dl.py took 0.340 seconds
[2024-01-26T16:09:53.380+0000] {processor.py:153} INFO - Started process (PID=15545) to work on /opt/airflow/dags/etl_scripts/etl_atendimentos_dl.py
[2024-01-26T16:09:53.382+0000] {processor.py:743} INFO - Processing file /opt/airflow/dags/etl_scripts/etl_atendimentos_dl.py for tasks to queue
[2024-01-26T16:09:53.383+0000] {logging_mixin.py:137} INFO - [2024-01-26T16:09:53.383+0000] {dagbag.py:538} INFO - Filling up the DagBag from /opt/airflow/dags/etl_scripts/etl_atendimentos_dl.py
[2024-01-26T16:09:53.691+0000] {logging_mixin.py:137} INFO - [2024-01-26T16:09:53.681+0000] {dagbag.py:343} ERROR - Failed to import: /opt/airflow/dags/etl_scripts/etl_atendimentos_dl.py
Traceback (most recent call last):
  File "/home/airflow/.local/lib/python3.7/site-packages/airflow/models/dagbag.py", line 339, in parse
    loader.exec_module(new_module)
  File "<frozen importlib._bootstrap_external>", line 728, in exec_module
  File "<frozen importlib._bootstrap>", line 219, in _call_with_frames_removed
  File "/opt/airflow/dags/etl_scripts/etl_atendimentos_dl.py", line 18, in <module>
    usuario = config.get('Database', 'user')
  File "/usr/local/lib/python3.7/configparser.py", line 780, in get
    d = self._unify_values(section, vars)
  File "/usr/local/lib/python3.7/configparser.py", line 1146, in _unify_values
    raise NoSectionError(section) from None
configparser.NoSectionError: No section: 'Database'
[2024-01-26T16:09:53.692+0000] {processor.py:755} WARNING - No viable dags retrieved from /opt/airflow/dags/etl_scripts/etl_atendimentos_dl.py
[2024-01-26T16:09:53.716+0000] {processor.py:175} INFO - Processing /opt/airflow/dags/etl_scripts/etl_atendimentos_dl.py took 0.339 seconds
[2024-01-26T16:10:23.804+0000] {processor.py:153} INFO - Started process (PID=15596) to work on /opt/airflow/dags/etl_scripts/etl_atendimentos_dl.py
[2024-01-26T16:10:23.805+0000] {processor.py:743} INFO - Processing file /opt/airflow/dags/etl_scripts/etl_atendimentos_dl.py for tasks to queue
[2024-01-26T16:10:23.807+0000] {logging_mixin.py:137} INFO - [2024-01-26T16:10:23.807+0000] {dagbag.py:538} INFO - Filling up the DagBag from /opt/airflow/dags/etl_scripts/etl_atendimentos_dl.py
[2024-01-26T16:10:24.315+0000] {logging_mixin.py:137} INFO - [2024-01-26T16:10:24.257+0000] {dagbag.py:343} ERROR - Failed to import: /opt/airflow/dags/etl_scripts/etl_atendimentos_dl.py
Traceback (most recent call last):
  File "/home/airflow/.local/lib/python3.7/site-packages/airflow/models/dagbag.py", line 339, in parse
    loader.exec_module(new_module)
  File "<frozen importlib._bootstrap_external>", line 728, in exec_module
  File "<frozen importlib._bootstrap>", line 219, in _call_with_frames_removed
  File "/opt/airflow/dags/etl_scripts/etl_atendimentos_dl.py", line 18, in <module>
    usuario = config.get('Database', 'user')
  File "/usr/local/lib/python3.7/configparser.py", line 780, in get
    d = self._unify_values(section, vars)
  File "/usr/local/lib/python3.7/configparser.py", line 1146, in _unify_values
    raise NoSectionError(section) from None
configparser.NoSectionError: No section: 'Database'
[2024-01-26T16:10:24.316+0000] {processor.py:755} WARNING - No viable dags retrieved from /opt/airflow/dags/etl_scripts/etl_atendimentos_dl.py
[2024-01-26T16:10:25.066+0000] {processor.py:175} INFO - Processing /opt/airflow/dags/etl_scripts/etl_atendimentos_dl.py took 1.266 seconds
[2024-01-26T16:10:55.272+0000] {processor.py:153} INFO - Started process (PID=15630) to work on /opt/airflow/dags/etl_scripts/etl_atendimentos_dl.py
[2024-01-26T16:10:55.274+0000] {processor.py:743} INFO - Processing file /opt/airflow/dags/etl_scripts/etl_atendimentos_dl.py for tasks to queue
[2024-01-26T16:10:55.274+0000] {logging_mixin.py:137} INFO - [2024-01-26T16:10:55.274+0000] {dagbag.py:538} INFO - Filling up the DagBag from /opt/airflow/dags/etl_scripts/etl_atendimentos_dl.py
[2024-01-26T16:10:55.541+0000] {logging_mixin.py:137} INFO - [2024-01-26T16:10:55.533+0000] {dagbag.py:343} ERROR - Failed to import: /opt/airflow/dags/etl_scripts/etl_atendimentos_dl.py
Traceback (most recent call last):
  File "/home/airflow/.local/lib/python3.7/site-packages/airflow/models/dagbag.py", line 339, in parse
    loader.exec_module(new_module)
  File "<frozen importlib._bootstrap_external>", line 728, in exec_module
  File "<frozen importlib._bootstrap>", line 219, in _call_with_frames_removed
  File "/opt/airflow/dags/etl_scripts/etl_atendimentos_dl.py", line 18, in <module>
    usuario = config.get('Database', 'user')
  File "/usr/local/lib/python3.7/configparser.py", line 780, in get
    d = self._unify_values(section, vars)
  File "/usr/local/lib/python3.7/configparser.py", line 1146, in _unify_values
    raise NoSectionError(section) from None
configparser.NoSectionError: No section: 'Database'
[2024-01-26T16:10:55.542+0000] {processor.py:755} WARNING - No viable dags retrieved from /opt/airflow/dags/etl_scripts/etl_atendimentos_dl.py
[2024-01-26T16:10:55.563+0000] {processor.py:175} INFO - Processing /opt/airflow/dags/etl_scripts/etl_atendimentos_dl.py took 0.294 seconds
[2024-01-26T16:11:25.642+0000] {processor.py:153} INFO - Started process (PID=15681) to work on /opt/airflow/dags/etl_scripts/etl_atendimentos_dl.py
[2024-01-26T16:11:25.643+0000] {processor.py:743} INFO - Processing file /opt/airflow/dags/etl_scripts/etl_atendimentos_dl.py for tasks to queue
[2024-01-26T16:11:25.644+0000] {logging_mixin.py:137} INFO - [2024-01-26T16:11:25.644+0000] {dagbag.py:538} INFO - Filling up the DagBag from /opt/airflow/dags/etl_scripts/etl_atendimentos_dl.py
[2024-01-26T16:11:25.957+0000] {logging_mixin.py:137} INFO - [2024-01-26T16:11:25.950+0000] {dagbag.py:343} ERROR - Failed to import: /opt/airflow/dags/etl_scripts/etl_atendimentos_dl.py
Traceback (most recent call last):
  File "/home/airflow/.local/lib/python3.7/site-packages/airflow/models/dagbag.py", line 339, in parse
    loader.exec_module(new_module)
  File "<frozen importlib._bootstrap_external>", line 728, in exec_module
  File "<frozen importlib._bootstrap>", line 219, in _call_with_frames_removed
  File "/opt/airflow/dags/etl_scripts/etl_atendimentos_dl.py", line 18, in <module>
    usuario = config.get('Database', 'user')
  File "/usr/local/lib/python3.7/configparser.py", line 780, in get
    d = self._unify_values(section, vars)
  File "/usr/local/lib/python3.7/configparser.py", line 1146, in _unify_values
    raise NoSectionError(section) from None
configparser.NoSectionError: No section: 'Database'
[2024-01-26T16:11:25.958+0000] {processor.py:755} WARNING - No viable dags retrieved from /opt/airflow/dags/etl_scripts/etl_atendimentos_dl.py
[2024-01-26T16:11:25.980+0000] {processor.py:175} INFO - Processing /opt/airflow/dags/etl_scripts/etl_atendimentos_dl.py took 0.341 seconds
[2024-01-26T16:11:56.074+0000] {processor.py:153} INFO - Started process (PID=15716) to work on /opt/airflow/dags/etl_scripts/etl_atendimentos_dl.py
[2024-01-26T16:11:56.076+0000] {processor.py:743} INFO - Processing file /opt/airflow/dags/etl_scripts/etl_atendimentos_dl.py for tasks to queue
[2024-01-26T16:11:56.077+0000] {logging_mixin.py:137} INFO - [2024-01-26T16:11:56.077+0000] {dagbag.py:538} INFO - Filling up the DagBag from /opt/airflow/dags/etl_scripts/etl_atendimentos_dl.py
[2024-01-26T16:11:56.480+0000] {logging_mixin.py:137} INFO - [2024-01-26T16:11:56.472+0000] {dagbag.py:343} ERROR - Failed to import: /opt/airflow/dags/etl_scripts/etl_atendimentos_dl.py
Traceback (most recent call last):
  File "/home/airflow/.local/lib/python3.7/site-packages/airflow/models/dagbag.py", line 339, in parse
    loader.exec_module(new_module)
  File "<frozen importlib._bootstrap_external>", line 728, in exec_module
  File "<frozen importlib._bootstrap>", line 219, in _call_with_frames_removed
  File "/opt/airflow/dags/etl_scripts/etl_atendimentos_dl.py", line 18, in <module>
    usuario = config.get('Database', 'user')
  File "/usr/local/lib/python3.7/configparser.py", line 780, in get
    d = self._unify_values(section, vars)
  File "/usr/local/lib/python3.7/configparser.py", line 1146, in _unify_values
    raise NoSectionError(section) from None
configparser.NoSectionError: No section: 'Database'
[2024-01-26T16:11:56.481+0000] {processor.py:755} WARNING - No viable dags retrieved from /opt/airflow/dags/etl_scripts/etl_atendimentos_dl.py
[2024-01-26T16:11:56.508+0000] {processor.py:175} INFO - Processing /opt/airflow/dags/etl_scripts/etl_atendimentos_dl.py took 0.439 seconds
[2024-01-26T16:12:27.341+0000] {processor.py:153} INFO - Started process (PID=15751) to work on /opt/airflow/dags/etl_scripts/etl_atendimentos_dl.py
[2024-01-26T16:12:27.342+0000] {processor.py:743} INFO - Processing file /opt/airflow/dags/etl_scripts/etl_atendimentos_dl.py for tasks to queue
[2024-01-26T16:12:27.343+0000] {logging_mixin.py:137} INFO - [2024-01-26T16:12:27.343+0000] {dagbag.py:538} INFO - Filling up the DagBag from /opt/airflow/dags/etl_scripts/etl_atendimentos_dl.py
[2024-01-26T16:12:27.653+0000] {logging_mixin.py:137} INFO - [2024-01-26T16:12:27.644+0000] {dagbag.py:343} ERROR - Failed to import: /opt/airflow/dags/etl_scripts/etl_atendimentos_dl.py
Traceback (most recent call last):
  File "/home/airflow/.local/lib/python3.7/site-packages/airflow/models/dagbag.py", line 339, in parse
    loader.exec_module(new_module)
  File "<frozen importlib._bootstrap_external>", line 728, in exec_module
  File "<frozen importlib._bootstrap>", line 219, in _call_with_frames_removed
  File "/opt/airflow/dags/etl_scripts/etl_atendimentos_dl.py", line 18, in <module>
    usuario = config.get('Database', 'user')
  File "/usr/local/lib/python3.7/configparser.py", line 780, in get
    d = self._unify_values(section, vars)
  File "/usr/local/lib/python3.7/configparser.py", line 1146, in _unify_values
    raise NoSectionError(section) from None
configparser.NoSectionError: No section: 'Database'
[2024-01-26T16:12:27.654+0000] {processor.py:755} WARNING - No viable dags retrieved from /opt/airflow/dags/etl_scripts/etl_atendimentos_dl.py
[2024-01-26T16:12:27.675+0000] {processor.py:175} INFO - Processing /opt/airflow/dags/etl_scripts/etl_atendimentos_dl.py took 0.337 seconds
[2024-01-26T16:12:57.862+0000] {processor.py:153} INFO - Started process (PID=15802) to work on /opt/airflow/dags/etl_scripts/etl_atendimentos_dl.py
[2024-01-26T16:12:57.864+0000] {processor.py:743} INFO - Processing file /opt/airflow/dags/etl_scripts/etl_atendimentos_dl.py for tasks to queue
[2024-01-26T16:12:57.866+0000] {logging_mixin.py:137} INFO - [2024-01-26T16:12:57.865+0000] {dagbag.py:538} INFO - Filling up the DagBag from /opt/airflow/dags/etl_scripts/etl_atendimentos_dl.py
[2024-01-26T16:12:58.470+0000] {logging_mixin.py:137} INFO - [2024-01-26T16:12:58.460+0000] {dagbag.py:343} ERROR - Failed to import: /opt/airflow/dags/etl_scripts/etl_atendimentos_dl.py
Traceback (most recent call last):
  File "/home/airflow/.local/lib/python3.7/site-packages/airflow/models/dagbag.py", line 339, in parse
    loader.exec_module(new_module)
  File "<frozen importlib._bootstrap_external>", line 728, in exec_module
  File "<frozen importlib._bootstrap>", line 219, in _call_with_frames_removed
  File "/opt/airflow/dags/etl_scripts/etl_atendimentos_dl.py", line 18, in <module>
    usuario = config.get('Database', 'user')
  File "/usr/local/lib/python3.7/configparser.py", line 780, in get
    d = self._unify_values(section, vars)
  File "/usr/local/lib/python3.7/configparser.py", line 1146, in _unify_values
    raise NoSectionError(section) from None
configparser.NoSectionError: No section: 'Database'
[2024-01-26T16:12:58.471+0000] {processor.py:755} WARNING - No viable dags retrieved from /opt/airflow/dags/etl_scripts/etl_atendimentos_dl.py
[2024-01-26T16:12:58.506+0000] {processor.py:175} INFO - Processing /opt/airflow/dags/etl_scripts/etl_atendimentos_dl.py took 0.650 seconds
[2024-01-26T16:13:28.732+0000] {processor.py:153} INFO - Started process (PID=15838) to work on /opt/airflow/dags/etl_scripts/etl_atendimentos_dl.py
[2024-01-26T16:13:28.734+0000] {processor.py:743} INFO - Processing file /opt/airflow/dags/etl_scripts/etl_atendimentos_dl.py for tasks to queue
[2024-01-26T16:13:28.737+0000] {logging_mixin.py:137} INFO - [2024-01-26T16:13:28.736+0000] {dagbag.py:538} INFO - Filling up the DagBag from /opt/airflow/dags/etl_scripts/etl_atendimentos_dl.py
[2024-01-26T16:13:29.492+0000] {logging_mixin.py:137} INFO - [2024-01-26T16:13:29.467+0000] {dagbag.py:343} ERROR - Failed to import: /opt/airflow/dags/etl_scripts/etl_atendimentos_dl.py
Traceback (most recent call last):
  File "/home/airflow/.local/lib/python3.7/site-packages/airflow/models/dagbag.py", line 339, in parse
    loader.exec_module(new_module)
  File "<frozen importlib._bootstrap_external>", line 728, in exec_module
  File "<frozen importlib._bootstrap>", line 219, in _call_with_frames_removed
  File "/opt/airflow/dags/etl_scripts/etl_atendimentos_dl.py", line 18, in <module>
    usuario = config.get('Database', 'user')
  File "/usr/local/lib/python3.7/configparser.py", line 780, in get
    d = self._unify_values(section, vars)
  File "/usr/local/lib/python3.7/configparser.py", line 1146, in _unify_values
    raise NoSectionError(section) from None
configparser.NoSectionError: No section: 'Database'
[2024-01-26T16:13:29.494+0000] {processor.py:755} WARNING - No viable dags retrieved from /opt/airflow/dags/etl_scripts/etl_atendimentos_dl.py
[2024-01-26T16:13:29.589+0000] {processor.py:175} INFO - Processing /opt/airflow/dags/etl_scripts/etl_atendimentos_dl.py took 0.863 seconds
[2024-01-26T16:14:00.012+0000] {processor.py:153} INFO - Started process (PID=15873) to work on /opt/airflow/dags/etl_scripts/etl_atendimentos_dl.py
[2024-01-26T16:14:00.014+0000] {processor.py:743} INFO - Processing file /opt/airflow/dags/etl_scripts/etl_atendimentos_dl.py for tasks to queue
[2024-01-26T16:14:00.016+0000] {logging_mixin.py:137} INFO - [2024-01-26T16:14:00.015+0000] {dagbag.py:538} INFO - Filling up the DagBag from /opt/airflow/dags/etl_scripts/etl_atendimentos_dl.py
[2024-01-26T16:14:00.385+0000] {logging_mixin.py:137} INFO - [2024-01-26T16:14:00.378+0000] {dagbag.py:343} ERROR - Failed to import: /opt/airflow/dags/etl_scripts/etl_atendimentos_dl.py
Traceback (most recent call last):
  File "/home/airflow/.local/lib/python3.7/site-packages/airflow/models/dagbag.py", line 339, in parse
    loader.exec_module(new_module)
  File "<frozen importlib._bootstrap_external>", line 728, in exec_module
  File "<frozen importlib._bootstrap>", line 219, in _call_with_frames_removed
  File "/opt/airflow/dags/etl_scripts/etl_atendimentos_dl.py", line 18, in <module>
    usuario = config.get('Database', 'user')
  File "/usr/local/lib/python3.7/configparser.py", line 780, in get
    d = self._unify_values(section, vars)
  File "/usr/local/lib/python3.7/configparser.py", line 1146, in _unify_values
    raise NoSectionError(section) from None
configparser.NoSectionError: No section: 'Database'
[2024-01-26T16:14:00.386+0000] {processor.py:755} WARNING - No viable dags retrieved from /opt/airflow/dags/etl_scripts/etl_atendimentos_dl.py
[2024-01-26T16:14:00.417+0000] {processor.py:175} INFO - Processing /opt/airflow/dags/etl_scripts/etl_atendimentos_dl.py took 0.408 seconds
[2024-01-26T16:14:30.903+0000] {processor.py:153} INFO - Started process (PID=15908) to work on /opt/airflow/dags/etl_scripts/etl_atendimentos_dl.py
[2024-01-26T16:14:30.904+0000] {processor.py:743} INFO - Processing file /opt/airflow/dags/etl_scripts/etl_atendimentos_dl.py for tasks to queue
[2024-01-26T16:14:30.906+0000] {logging_mixin.py:137} INFO - [2024-01-26T16:14:30.905+0000] {dagbag.py:538} INFO - Filling up the DagBag from /opt/airflow/dags/etl_scripts/etl_atendimentos_dl.py
[2024-01-26T16:14:31.351+0000] {logging_mixin.py:137} INFO - [2024-01-26T16:14:31.342+0000] {dagbag.py:343} ERROR - Failed to import: /opt/airflow/dags/etl_scripts/etl_atendimentos_dl.py
Traceback (most recent call last):
  File "/home/airflow/.local/lib/python3.7/site-packages/airflow/models/dagbag.py", line 339, in parse
    loader.exec_module(new_module)
  File "<frozen importlib._bootstrap_external>", line 728, in exec_module
  File "<frozen importlib._bootstrap>", line 219, in _call_with_frames_removed
  File "/opt/airflow/dags/etl_scripts/etl_atendimentos_dl.py", line 18, in <module>
    usuario = config.get('Database', 'user')
  File "/usr/local/lib/python3.7/configparser.py", line 780, in get
    d = self._unify_values(section, vars)
  File "/usr/local/lib/python3.7/configparser.py", line 1146, in _unify_values
    raise NoSectionError(section) from None
configparser.NoSectionError: No section: 'Database'
[2024-01-26T16:14:31.352+0000] {processor.py:755} WARNING - No viable dags retrieved from /opt/airflow/dags/etl_scripts/etl_atendimentos_dl.py
[2024-01-26T16:14:31.379+0000] {processor.py:175} INFO - Processing /opt/airflow/dags/etl_scripts/etl_atendimentos_dl.py took 0.479 seconds
[2024-01-26T16:15:01.484+0000] {processor.py:153} INFO - Started process (PID=15953) to work on /opt/airflow/dags/etl_scripts/etl_atendimentos_dl.py
[2024-01-26T16:15:01.485+0000] {processor.py:743} INFO - Processing file /opt/airflow/dags/etl_scripts/etl_atendimentos_dl.py for tasks to queue
[2024-01-26T16:15:01.487+0000] {logging_mixin.py:137} INFO - [2024-01-26T16:15:01.486+0000] {dagbag.py:538} INFO - Filling up the DagBag from /opt/airflow/dags/etl_scripts/etl_atendimentos_dl.py
[2024-01-26T16:15:01.849+0000] {logging_mixin.py:137} INFO - [2024-01-26T16:15:01.842+0000] {dagbag.py:343} ERROR - Failed to import: /opt/airflow/dags/etl_scripts/etl_atendimentos_dl.py
Traceback (most recent call last):
  File "/home/airflow/.local/lib/python3.7/site-packages/airflow/models/dagbag.py", line 339, in parse
    loader.exec_module(new_module)
  File "<frozen importlib._bootstrap_external>", line 728, in exec_module
  File "<frozen importlib._bootstrap>", line 219, in _call_with_frames_removed
  File "/opt/airflow/dags/etl_scripts/etl_atendimentos_dl.py", line 18, in <module>
    usuario = config.get('Database', 'user')
  File "/usr/local/lib/python3.7/configparser.py", line 780, in get
    d = self._unify_values(section, vars)
  File "/usr/local/lib/python3.7/configparser.py", line 1146, in _unify_values
    raise NoSectionError(section) from None
configparser.NoSectionError: No section: 'Database'
[2024-01-26T16:15:01.849+0000] {processor.py:755} WARNING - No viable dags retrieved from /opt/airflow/dags/etl_scripts/etl_atendimentos_dl.py
[2024-01-26T16:15:01.872+0000] {processor.py:175} INFO - Processing /opt/airflow/dags/etl_scripts/etl_atendimentos_dl.py took 0.394 seconds
[2024-01-26T16:15:32.049+0000] {processor.py:153} INFO - Started process (PID=15995) to work on /opt/airflow/dags/etl_scripts/etl_atendimentos_dl.py
[2024-01-26T16:15:32.050+0000] {processor.py:743} INFO - Processing file /opt/airflow/dags/etl_scripts/etl_atendimentos_dl.py for tasks to queue
[2024-01-26T16:15:32.051+0000] {logging_mixin.py:137} INFO - [2024-01-26T16:15:32.051+0000] {dagbag.py:538} INFO - Filling up the DagBag from /opt/airflow/dags/etl_scripts/etl_atendimentos_dl.py
[2024-01-26T16:15:32.323+0000] {logging_mixin.py:137} INFO - [2024-01-26T16:15:32.316+0000] {dagbag.py:343} ERROR - Failed to import: /opt/airflow/dags/etl_scripts/etl_atendimentos_dl.py
Traceback (most recent call last):
  File "/home/airflow/.local/lib/python3.7/site-packages/airflow/models/dagbag.py", line 339, in parse
    loader.exec_module(new_module)
  File "<frozen importlib._bootstrap_external>", line 728, in exec_module
  File "<frozen importlib._bootstrap>", line 219, in _call_with_frames_removed
  File "/opt/airflow/dags/etl_scripts/etl_atendimentos_dl.py", line 18, in <module>
    usuario = config.get('Database', 'user')
  File "/usr/local/lib/python3.7/configparser.py", line 780, in get
    d = self._unify_values(section, vars)
  File "/usr/local/lib/python3.7/configparser.py", line 1146, in _unify_values
    raise NoSectionError(section) from None
configparser.NoSectionError: No section: 'Database'
[2024-01-26T16:15:32.324+0000] {processor.py:755} WARNING - No viable dags retrieved from /opt/airflow/dags/etl_scripts/etl_atendimentos_dl.py
[2024-01-26T16:15:32.344+0000] {processor.py:175} INFO - Processing /opt/airflow/dags/etl_scripts/etl_atendimentos_dl.py took 0.298 seconds
[2024-01-26T16:16:02.427+0000] {processor.py:153} INFO - Started process (PID=16030) to work on /opt/airflow/dags/etl_scripts/etl_atendimentos_dl.py
[2024-01-26T16:16:02.429+0000] {processor.py:743} INFO - Processing file /opt/airflow/dags/etl_scripts/etl_atendimentos_dl.py for tasks to queue
[2024-01-26T16:16:02.430+0000] {logging_mixin.py:137} INFO - [2024-01-26T16:16:02.429+0000] {dagbag.py:538} INFO - Filling up the DagBag from /opt/airflow/dags/etl_scripts/etl_atendimentos_dl.py
[2024-01-26T16:16:02.696+0000] {logging_mixin.py:137} INFO - [2024-01-26T16:16:02.689+0000] {dagbag.py:343} ERROR - Failed to import: /opt/airflow/dags/etl_scripts/etl_atendimentos_dl.py
Traceback (most recent call last):
  File "/home/airflow/.local/lib/python3.7/site-packages/airflow/models/dagbag.py", line 339, in parse
    loader.exec_module(new_module)
  File "<frozen importlib._bootstrap_external>", line 728, in exec_module
  File "<frozen importlib._bootstrap>", line 219, in _call_with_frames_removed
  File "/opt/airflow/dags/etl_scripts/etl_atendimentos_dl.py", line 18, in <module>
    usuario = config.get('Database', 'user')
  File "/usr/local/lib/python3.7/configparser.py", line 780, in get
    d = self._unify_values(section, vars)
  File "/usr/local/lib/python3.7/configparser.py", line 1146, in _unify_values
    raise NoSectionError(section) from None
configparser.NoSectionError: No section: 'Database'
[2024-01-26T16:16:02.697+0000] {processor.py:755} WARNING - No viable dags retrieved from /opt/airflow/dags/etl_scripts/etl_atendimentos_dl.py
[2024-01-26T16:16:02.719+0000] {processor.py:175} INFO - Processing /opt/airflow/dags/etl_scripts/etl_atendimentos_dl.py took 0.294 seconds
[2024-01-26T16:16:32.817+0000] {processor.py:153} INFO - Started process (PID=16081) to work on /opt/airflow/dags/etl_scripts/etl_atendimentos_dl.py
[2024-01-26T16:16:32.818+0000] {processor.py:743} INFO - Processing file /opt/airflow/dags/etl_scripts/etl_atendimentos_dl.py for tasks to queue
[2024-01-26T16:16:32.819+0000] {logging_mixin.py:137} INFO - [2024-01-26T16:16:32.819+0000] {dagbag.py:538} INFO - Filling up the DagBag from /opt/airflow/dags/etl_scripts/etl_atendimentos_dl.py
[2024-01-26T16:16:33.103+0000] {logging_mixin.py:137} INFO - [2024-01-26T16:16:33.095+0000] {dagbag.py:343} ERROR - Failed to import: /opt/airflow/dags/etl_scripts/etl_atendimentos_dl.py
Traceback (most recent call last):
  File "/home/airflow/.local/lib/python3.7/site-packages/airflow/models/dagbag.py", line 339, in parse
    loader.exec_module(new_module)
  File "<frozen importlib._bootstrap_external>", line 728, in exec_module
  File "<frozen importlib._bootstrap>", line 219, in _call_with_frames_removed
  File "/opt/airflow/dags/etl_scripts/etl_atendimentos_dl.py", line 18, in <module>
    usuario = config.get('Database', 'user')
  File "/usr/local/lib/python3.7/configparser.py", line 780, in get
    d = self._unify_values(section, vars)
  File "/usr/local/lib/python3.7/configparser.py", line 1146, in _unify_values
    raise NoSectionError(section) from None
configparser.NoSectionError: No section: 'Database'
[2024-01-26T16:16:33.105+0000] {processor.py:755} WARNING - No viable dags retrieved from /opt/airflow/dags/etl_scripts/etl_atendimentos_dl.py
[2024-01-26T16:16:33.129+0000] {processor.py:175} INFO - Processing /opt/airflow/dags/etl_scripts/etl_atendimentos_dl.py took 0.315 seconds
[2024-01-26T16:17:03.228+0000] {processor.py:153} INFO - Started process (PID=16116) to work on /opt/airflow/dags/etl_scripts/etl_atendimentos_dl.py
[2024-01-26T16:17:03.230+0000] {processor.py:743} INFO - Processing file /opt/airflow/dags/etl_scripts/etl_atendimentos_dl.py for tasks to queue
[2024-01-26T16:17:03.231+0000] {logging_mixin.py:137} INFO - [2024-01-26T16:17:03.231+0000] {dagbag.py:538} INFO - Filling up the DagBag from /opt/airflow/dags/etl_scripts/etl_atendimentos_dl.py
[2024-01-26T16:17:03.492+0000] {logging_mixin.py:137} INFO - [2024-01-26T16:17:03.484+0000] {dagbag.py:343} ERROR - Failed to import: /opt/airflow/dags/etl_scripts/etl_atendimentos_dl.py
Traceback (most recent call last):
  File "/home/airflow/.local/lib/python3.7/site-packages/airflow/models/dagbag.py", line 339, in parse
    loader.exec_module(new_module)
  File "<frozen importlib._bootstrap_external>", line 728, in exec_module
  File "<frozen importlib._bootstrap>", line 219, in _call_with_frames_removed
  File "/opt/airflow/dags/etl_scripts/etl_atendimentos_dl.py", line 18, in <module>
    usuario = config.get('Database', 'user')
  File "/usr/local/lib/python3.7/configparser.py", line 780, in get
    d = self._unify_values(section, vars)
  File "/usr/local/lib/python3.7/configparser.py", line 1146, in _unify_values
    raise NoSectionError(section) from None
configparser.NoSectionError: No section: 'Database'
[2024-01-26T16:17:03.493+0000] {processor.py:755} WARNING - No viable dags retrieved from /opt/airflow/dags/etl_scripts/etl_atendimentos_dl.py
[2024-01-26T16:17:03.514+0000] {processor.py:175} INFO - Processing /opt/airflow/dags/etl_scripts/etl_atendimentos_dl.py took 0.288 seconds
[2024-01-26T16:17:33.624+0000] {processor.py:153} INFO - Started process (PID=16167) to work on /opt/airflow/dags/etl_scripts/etl_atendimentos_dl.py
[2024-01-26T16:17:33.625+0000] {processor.py:743} INFO - Processing file /opt/airflow/dags/etl_scripts/etl_atendimentos_dl.py for tasks to queue
[2024-01-26T16:17:33.626+0000] {logging_mixin.py:137} INFO - [2024-01-26T16:17:33.626+0000] {dagbag.py:538} INFO - Filling up the DagBag from /opt/airflow/dags/etl_scripts/etl_atendimentos_dl.py
[2024-01-26T16:17:33.883+0000] {logging_mixin.py:137} INFO - [2024-01-26T16:17:33.876+0000] {dagbag.py:343} ERROR - Failed to import: /opt/airflow/dags/etl_scripts/etl_atendimentos_dl.py
Traceback (most recent call last):
  File "/home/airflow/.local/lib/python3.7/site-packages/airflow/models/dagbag.py", line 339, in parse
    loader.exec_module(new_module)
  File "<frozen importlib._bootstrap_external>", line 728, in exec_module
  File "<frozen importlib._bootstrap>", line 219, in _call_with_frames_removed
  File "/opt/airflow/dags/etl_scripts/etl_atendimentos_dl.py", line 18, in <module>
    usuario = config.get('Database', 'user')
  File "/usr/local/lib/python3.7/configparser.py", line 780, in get
    d = self._unify_values(section, vars)
  File "/usr/local/lib/python3.7/configparser.py", line 1146, in _unify_values
    raise NoSectionError(section) from None
configparser.NoSectionError: No section: 'Database'
[2024-01-26T16:17:33.884+0000] {processor.py:755} WARNING - No viable dags retrieved from /opt/airflow/dags/etl_scripts/etl_atendimentos_dl.py
[2024-01-26T16:17:33.907+0000] {processor.py:175} INFO - Processing /opt/airflow/dags/etl_scripts/etl_atendimentos_dl.py took 0.285 seconds
[2024-01-26T16:17:48.759+0000] {processor.py:153} INFO - Started process (PID=16185) to work on /opt/airflow/dags/etl_scripts/etl_atendimentos_dl.py
[2024-01-26T16:17:48.761+0000] {processor.py:743} INFO - Processing file /opt/airflow/dags/etl_scripts/etl_atendimentos_dl.py for tasks to queue
[2024-01-26T16:17:48.763+0000] {logging_mixin.py:137} INFO - [2024-01-26T16:17:48.762+0000] {dagbag.py:538} INFO - Filling up the DagBag from /opt/airflow/dags/etl_scripts/etl_atendimentos_dl.py
[2024-01-26T16:17:49.344+0000] {logging_mixin.py:137} INFO - [2024-01-26T16:17:49.335+0000] {dagbag.py:343} ERROR - Failed to import: /opt/airflow/dags/etl_scripts/etl_atendimentos_dl.py
Traceback (most recent call last):
  File "/home/airflow/.local/lib/python3.7/site-packages/airflow/models/dagbag.py", line 339, in parse
    loader.exec_module(new_module)
  File "<frozen importlib._bootstrap_external>", line 728, in exec_module
  File "<frozen importlib._bootstrap>", line 219, in _call_with_frames_removed
  File "/opt/airflow/dags/etl_scripts/etl_atendimentos_dl.py", line 18, in <module>
    usuario = config.get('Database', 'user')
  File "/usr/local/lib/python3.7/configparser.py", line 780, in get
    d = self._unify_values(section, vars)
  File "/usr/local/lib/python3.7/configparser.py", line 1146, in _unify_values
    raise NoSectionError(section) from None
configparser.NoSectionError: No section: 'Database'
[2024-01-26T16:17:49.345+0000] {processor.py:755} WARNING - No viable dags retrieved from /opt/airflow/dags/etl_scripts/etl_atendimentos_dl.py
[2024-01-26T16:17:49.375+0000] {processor.py:175} INFO - Processing /opt/airflow/dags/etl_scripts/etl_atendimentos_dl.py took 0.620 seconds
[2024-01-26T16:18:05.241+0000] {processor.py:153} INFO - Started process (PID=16204) to work on /opt/airflow/dags/etl_scripts/etl_atendimentos_dl.py
[2024-01-26T16:18:05.242+0000] {processor.py:743} INFO - Processing file /opt/airflow/dags/etl_scripts/etl_atendimentos_dl.py for tasks to queue
[2024-01-26T16:18:05.244+0000] {logging_mixin.py:137} INFO - [2024-01-26T16:18:05.244+0000] {dagbag.py:538} INFO - Filling up the DagBag from /opt/airflow/dags/etl_scripts/etl_atendimentos_dl.py
[2024-01-26T16:18:05.717+0000] {logging_mixin.py:137} INFO - [2024-01-26T16:18:05.705+0000] {dagbag.py:343} ERROR - Failed to import: /opt/airflow/dags/etl_scripts/etl_atendimentos_dl.py
Traceback (most recent call last):
  File "/home/airflow/.local/lib/python3.7/site-packages/airflow/models/dagbag.py", line 339, in parse
    loader.exec_module(new_module)
  File "<frozen importlib._bootstrap_external>", line 728, in exec_module
  File "<frozen importlib._bootstrap>", line 219, in _call_with_frames_removed
  File "/opt/airflow/dags/etl_scripts/etl_atendimentos_dl.py", line 18, in <module>
    usuario = config.get('Database', 'user')
  File "/usr/local/lib/python3.7/configparser.py", line 780, in get
    d = self._unify_values(section, vars)
  File "/usr/local/lib/python3.7/configparser.py", line 1146, in _unify_values
    raise NoSectionError(section) from None
configparser.NoSectionError: No section: 'Database'
[2024-01-26T16:18:05.718+0000] {processor.py:755} WARNING - No viable dags retrieved from /opt/airflow/dags/etl_scripts/etl_atendimentos_dl.py
[2024-01-26T16:18:05.755+0000] {processor.py:175} INFO - Processing /opt/airflow/dags/etl_scripts/etl_atendimentos_dl.py took 0.518 seconds
[2024-01-26T16:18:35.856+0000] {processor.py:153} INFO - Started process (PID=16239) to work on /opt/airflow/dags/etl_scripts/etl_atendimentos_dl.py
[2024-01-26T16:18:35.857+0000] {processor.py:743} INFO - Processing file /opt/airflow/dags/etl_scripts/etl_atendimentos_dl.py for tasks to queue
[2024-01-26T16:18:35.858+0000] {logging_mixin.py:137} INFO - [2024-01-26T16:18:35.858+0000] {dagbag.py:538} INFO - Filling up the DagBag from /opt/airflow/dags/etl_scripts/etl_atendimentos_dl.py
[2024-01-26T16:18:36.223+0000] {logging_mixin.py:137} INFO - [2024-01-26T16:18:36.216+0000] {dagbag.py:343} ERROR - Failed to import: /opt/airflow/dags/etl_scripts/etl_atendimentos_dl.py
Traceback (most recent call last):
  File "/home/airflow/.local/lib/python3.7/site-packages/airflow/models/dagbag.py", line 339, in parse
    loader.exec_module(new_module)
  File "<frozen importlib._bootstrap_external>", line 728, in exec_module
  File "<frozen importlib._bootstrap>", line 219, in _call_with_frames_removed
  File "/opt/airflow/dags/etl_scripts/etl_atendimentos_dl.py", line 18, in <module>
    usuario = config.get('Database', 'user')
  File "/usr/local/lib/python3.7/configparser.py", line 780, in get
    d = self._unify_values(section, vars)
  File "/usr/local/lib/python3.7/configparser.py", line 1146, in _unify_values
    raise NoSectionError(section) from None
configparser.NoSectionError: No section: 'Database'
[2024-01-26T16:18:36.224+0000] {processor.py:755} WARNING - No viable dags retrieved from /opt/airflow/dags/etl_scripts/etl_atendimentos_dl.py
[2024-01-26T16:18:36.247+0000] {processor.py:175} INFO - Processing /opt/airflow/dags/etl_scripts/etl_atendimentos_dl.py took 0.395 seconds
[2024-01-26T16:19:06.555+0000] {processor.py:153} INFO - Started process (PID=16290) to work on /opt/airflow/dags/etl_scripts/etl_atendimentos_dl.py
[2024-01-26T16:19:06.557+0000] {processor.py:743} INFO - Processing file /opt/airflow/dags/etl_scripts/etl_atendimentos_dl.py for tasks to queue
[2024-01-26T16:19:06.558+0000] {logging_mixin.py:137} INFO - [2024-01-26T16:19:06.558+0000] {dagbag.py:538} INFO - Filling up the DagBag from /opt/airflow/dags/etl_scripts/etl_atendimentos_dl.py
[2024-01-26T16:19:07.007+0000] {logging_mixin.py:137} INFO - [2024-01-26T16:19:06.999+0000] {dagbag.py:343} ERROR - Failed to import: /opt/airflow/dags/etl_scripts/etl_atendimentos_dl.py
Traceback (most recent call last):
  File "/home/airflow/.local/lib/python3.7/site-packages/airflow/models/dagbag.py", line 339, in parse
    loader.exec_module(new_module)
  File "<frozen importlib._bootstrap_external>", line 728, in exec_module
  File "<frozen importlib._bootstrap>", line 219, in _call_with_frames_removed
  File "/opt/airflow/dags/etl_scripts/etl_atendimentos_dl.py", line 18, in <module>
    usuario = config.get('Database', 'user')
  File "/usr/local/lib/python3.7/configparser.py", line 780, in get
    d = self._unify_values(section, vars)
  File "/usr/local/lib/python3.7/configparser.py", line 1146, in _unify_values
    raise NoSectionError(section) from None
configparser.NoSectionError: No section: 'Database'
[2024-01-26T16:19:07.008+0000] {processor.py:755} WARNING - No viable dags retrieved from /opt/airflow/dags/etl_scripts/etl_atendimentos_dl.py
[2024-01-26T16:19:07.030+0000] {processor.py:175} INFO - Processing /opt/airflow/dags/etl_scripts/etl_atendimentos_dl.py took 0.479 seconds
[2024-01-26T16:19:29.123+0000] {processor.py:153} INFO - Started process (PID=16308) to work on /opt/airflow/dags/etl_scripts/etl_atendimentos_dl.py
[2024-01-26T16:19:29.124+0000] {processor.py:743} INFO - Processing file /opt/airflow/dags/etl_scripts/etl_atendimentos_dl.py for tasks to queue
[2024-01-26T16:19:29.126+0000] {logging_mixin.py:137} INFO - [2024-01-26T16:19:29.125+0000] {dagbag.py:538} INFO - Filling up the DagBag from /opt/airflow/dags/etl_scripts/etl_atendimentos_dl.py
[2024-01-26T16:19:29.558+0000] {logging_mixin.py:137} INFO - [2024-01-26T16:19:29.549+0000] {dagbag.py:343} ERROR - Failed to import: /opt/airflow/dags/etl_scripts/etl_atendimentos_dl.py
Traceback (most recent call last):
  File "/home/airflow/.local/lib/python3.7/site-packages/airflow/models/dagbag.py", line 339, in parse
    loader.exec_module(new_module)
  File "<frozen importlib._bootstrap_external>", line 728, in exec_module
  File "<frozen importlib._bootstrap>", line 219, in _call_with_frames_removed
  File "/opt/airflow/dags/etl_scripts/etl_atendimentos_dl.py", line 18, in <module>
    usuario = config.get('Database', 'user')
  File "/usr/local/lib/python3.7/configparser.py", line 780, in get
    d = self._unify_values(section, vars)
  File "/usr/local/lib/python3.7/configparser.py", line 1146, in _unify_values
    raise NoSectionError(section) from None
configparser.NoSectionError: No section: 'Database'
[2024-01-26T16:19:29.559+0000] {processor.py:755} WARNING - No viable dags retrieved from /opt/airflow/dags/etl_scripts/etl_atendimentos_dl.py
[2024-01-26T16:19:29.585+0000] {processor.py:175} INFO - Processing /opt/airflow/dags/etl_scripts/etl_atendimentos_dl.py took 0.466 seconds
[2024-01-26T16:19:37.687+0000] {processor.py:153} INFO - Started process (PID=16327) to work on /opt/airflow/dags/etl_scripts/etl_atendimentos_dl.py
[2024-01-26T16:19:37.689+0000] {processor.py:743} INFO - Processing file /opt/airflow/dags/etl_scripts/etl_atendimentos_dl.py for tasks to queue
[2024-01-26T16:19:37.690+0000] {logging_mixin.py:137} INFO - [2024-01-26T16:19:37.690+0000] {dagbag.py:538} INFO - Filling up the DagBag from /opt/airflow/dags/etl_scripts/etl_atendimentos_dl.py
[2024-01-26T16:19:38.245+0000] {logging_mixin.py:137} INFO - [2024-01-26T16:19:38.233+0000] {dagbag.py:343} ERROR - Failed to import: /opt/airflow/dags/etl_scripts/etl_atendimentos_dl.py
Traceback (most recent call last):
  File "/home/airflow/.local/lib/python3.7/site-packages/airflow/models/dagbag.py", line 339, in parse
    loader.exec_module(new_module)
  File "<frozen importlib._bootstrap_external>", line 728, in exec_module
  File "<frozen importlib._bootstrap>", line 219, in _call_with_frames_removed
  File "/opt/airflow/dags/etl_scripts/etl_atendimentos_dl.py", line 18, in <module>
    usuario = config.get('Database', 'user')
  File "/usr/local/lib/python3.7/configparser.py", line 780, in get
    d = self._unify_values(section, vars)
  File "/usr/local/lib/python3.7/configparser.py", line 1146, in _unify_values
    raise NoSectionError(section) from None
configparser.NoSectionError: No section: 'Database'
[2024-01-26T16:19:38.247+0000] {processor.py:755} WARNING - No viable dags retrieved from /opt/airflow/dags/etl_scripts/etl_atendimentos_dl.py
[2024-01-26T16:19:38.293+0000] {processor.py:175} INFO - Processing /opt/airflow/dags/etl_scripts/etl_atendimentos_dl.py took 0.609 seconds
[2024-01-26T16:20:09.153+0000] {processor.py:153} INFO - Started process (PID=16369) to work on /opt/airflow/dags/etl_scripts/etl_atendimentos_dl.py
[2024-01-26T16:20:09.155+0000] {processor.py:743} INFO - Processing file /opt/airflow/dags/etl_scripts/etl_atendimentos_dl.py for tasks to queue
[2024-01-26T16:20:09.156+0000] {logging_mixin.py:137} INFO - [2024-01-26T16:20:09.156+0000] {dagbag.py:538} INFO - Filling up the DagBag from /opt/airflow/dags/etl_scripts/etl_atendimentos_dl.py
[2024-01-26T16:20:09.627+0000] {logging_mixin.py:137} INFO - [2024-01-26T16:20:09.616+0000] {dagbag.py:343} ERROR - Failed to import: /opt/airflow/dags/etl_scripts/etl_atendimentos_dl.py
Traceback (most recent call last):
  File "/home/airflow/.local/lib/python3.7/site-packages/airflow/models/dagbag.py", line 339, in parse
    loader.exec_module(new_module)
  File "<frozen importlib._bootstrap_external>", line 728, in exec_module
  File "<frozen importlib._bootstrap>", line 219, in _call_with_frames_removed
  File "/opt/airflow/dags/etl_scripts/etl_atendimentos_dl.py", line 18, in <module>
    usuario = config.get('Database', 'user')
  File "/usr/local/lib/python3.7/configparser.py", line 780, in get
    d = self._unify_values(section, vars)
  File "/usr/local/lib/python3.7/configparser.py", line 1146, in _unify_values
    raise NoSectionError(section) from None
configparser.NoSectionError: No section: 'Database'
[2024-01-26T16:20:09.628+0000] {processor.py:755} WARNING - No viable dags retrieved from /opt/airflow/dags/etl_scripts/etl_atendimentos_dl.py
[2024-01-26T16:20:09.655+0000] {processor.py:175} INFO - Processing /opt/airflow/dags/etl_scripts/etl_atendimentos_dl.py took 0.507 seconds
[2024-01-26T16:20:39.767+0000] {processor.py:153} INFO - Started process (PID=16405) to work on /opt/airflow/dags/etl_scripts/etl_atendimentos_dl.py
[2024-01-26T16:20:39.769+0000] {processor.py:743} INFO - Processing file /opt/airflow/dags/etl_scripts/etl_atendimentos_dl.py for tasks to queue
[2024-01-26T16:20:39.772+0000] {logging_mixin.py:137} INFO - [2024-01-26T16:20:39.771+0000] {dagbag.py:538} INFO - Filling up the DagBag from /opt/airflow/dags/etl_scripts/etl_atendimentos_dl.py
[2024-01-26T16:20:40.310+0000] {logging_mixin.py:137} INFO - [2024-01-26T16:20:40.293+0000] {dagbag.py:343} ERROR - Failed to import: /opt/airflow/dags/etl_scripts/etl_atendimentos_dl.py
Traceback (most recent call last):
  File "/home/airflow/.local/lib/python3.7/site-packages/airflow/models/dagbag.py", line 339, in parse
    loader.exec_module(new_module)
  File "<frozen importlib._bootstrap_external>", line 728, in exec_module
  File "<frozen importlib._bootstrap>", line 219, in _call_with_frames_removed
  File "/opt/airflow/dags/etl_scripts/etl_atendimentos_dl.py", line 18, in <module>
    usuario = config.get('Database', 'user')
  File "/usr/local/lib/python3.7/configparser.py", line 780, in get
    d = self._unify_values(section, vars)
  File "/usr/local/lib/python3.7/configparser.py", line 1146, in _unify_values
    raise NoSectionError(section) from None
configparser.NoSectionError: No section: 'Database'
[2024-01-26T16:20:40.312+0000] {processor.py:755} WARNING - No viable dags retrieved from /opt/airflow/dags/etl_scripts/etl_atendimentos_dl.py
[2024-01-26T16:20:40.351+0000] {processor.py:175} INFO - Processing /opt/airflow/dags/etl_scripts/etl_atendimentos_dl.py took 0.590 seconds
[2024-01-26T16:21:11.245+0000] {processor.py:153} INFO - Started process (PID=16447) to work on /opt/airflow/dags/etl_scripts/etl_atendimentos_dl.py
[2024-01-26T16:21:11.248+0000] {processor.py:743} INFO - Processing file /opt/airflow/dags/etl_scripts/etl_atendimentos_dl.py for tasks to queue
[2024-01-26T16:21:11.250+0000] {logging_mixin.py:137} INFO - [2024-01-26T16:21:11.250+0000] {dagbag.py:538} INFO - Filling up the DagBag from /opt/airflow/dags/etl_scripts/etl_atendimentos_dl.py
[2024-01-26T16:21:11.739+0000] {logging_mixin.py:137} INFO - [2024-01-26T16:21:11.711+0000] {dagbag.py:343} ERROR - Failed to import: /opt/airflow/dags/etl_scripts/etl_atendimentos_dl.py
Traceback (most recent call last):
  File "/home/airflow/.local/lib/python3.7/site-packages/airflow/models/dagbag.py", line 339, in parse
    loader.exec_module(new_module)
  File "<frozen importlib._bootstrap_external>", line 728, in exec_module
  File "<frozen importlib._bootstrap>", line 219, in _call_with_frames_removed
  File "/opt/airflow/dags/etl_scripts/etl_atendimentos_dl.py", line 18, in <module>
    usuario = config.get('Database', 'user')
  File "/usr/local/lib/python3.7/configparser.py", line 780, in get
    d = self._unify_values(section, vars)
  File "/usr/local/lib/python3.7/configparser.py", line 1146, in _unify_values
    raise NoSectionError(section) from None
configparser.NoSectionError: No section: 'Database'
[2024-01-26T16:21:11.741+0000] {processor.py:755} WARNING - No viable dags retrieved from /opt/airflow/dags/etl_scripts/etl_atendimentos_dl.py
[2024-01-26T16:21:11.781+0000] {processor.py:175} INFO - Processing /opt/airflow/dags/etl_scripts/etl_atendimentos_dl.py took 0.541 seconds
[2024-01-26T16:21:42.038+0000] {processor.py:153} INFO - Started process (PID=16482) to work on /opt/airflow/dags/etl_scripts/etl_atendimentos_dl.py
[2024-01-26T16:21:42.039+0000] {processor.py:743} INFO - Processing file /opt/airflow/dags/etl_scripts/etl_atendimentos_dl.py for tasks to queue
[2024-01-26T16:21:42.042+0000] {logging_mixin.py:137} INFO - [2024-01-26T16:21:42.042+0000] {dagbag.py:538} INFO - Filling up the DagBag from /opt/airflow/dags/etl_scripts/etl_atendimentos_dl.py
[2024-01-26T16:21:42.448+0000] {logging_mixin.py:137} INFO - [2024-01-26T16:21:42.438+0000] {dagbag.py:343} ERROR - Failed to import: /opt/airflow/dags/etl_scripts/etl_atendimentos_dl.py
Traceback (most recent call last):
  File "/home/airflow/.local/lib/python3.7/site-packages/airflow/models/dagbag.py", line 339, in parse
    loader.exec_module(new_module)
  File "<frozen importlib._bootstrap_external>", line 728, in exec_module
  File "<frozen importlib._bootstrap>", line 219, in _call_with_frames_removed
  File "/opt/airflow/dags/etl_scripts/etl_atendimentos_dl.py", line 18, in <module>
    usuario = config.get('Database', 'user')
  File "/usr/local/lib/python3.7/configparser.py", line 780, in get
    d = self._unify_values(section, vars)
  File "/usr/local/lib/python3.7/configparser.py", line 1146, in _unify_values
    raise NoSectionError(section) from None
configparser.NoSectionError: No section: 'Database'
[2024-01-26T16:21:42.449+0000] {processor.py:755} WARNING - No viable dags retrieved from /opt/airflow/dags/etl_scripts/etl_atendimentos_dl.py
[2024-01-26T16:21:42.472+0000] {processor.py:175} INFO - Processing /opt/airflow/dags/etl_scripts/etl_atendimentos_dl.py took 0.439 seconds
[2024-01-26T16:22:12.542+0000] {processor.py:153} INFO - Started process (PID=16517) to work on /opt/airflow/dags/etl_scripts/etl_atendimentos_dl.py
[2024-01-26T16:22:12.543+0000] {processor.py:743} INFO - Processing file /opt/airflow/dags/etl_scripts/etl_atendimentos_dl.py for tasks to queue
[2024-01-26T16:22:12.544+0000] {logging_mixin.py:137} INFO - [2024-01-26T16:22:12.544+0000] {dagbag.py:538} INFO - Filling up the DagBag from /opt/airflow/dags/etl_scripts/etl_atendimentos_dl.py
[2024-01-26T16:22:12.969+0000] {logging_mixin.py:137} INFO - [2024-01-26T16:22:12.960+0000] {dagbag.py:343} ERROR - Failed to import: /opt/airflow/dags/etl_scripts/etl_atendimentos_dl.py
Traceback (most recent call last):
  File "/home/airflow/.local/lib/python3.7/site-packages/airflow/models/dagbag.py", line 339, in parse
    loader.exec_module(new_module)
  File "<frozen importlib._bootstrap_external>", line 728, in exec_module
  File "<frozen importlib._bootstrap>", line 219, in _call_with_frames_removed
  File "/opt/airflow/dags/etl_scripts/etl_atendimentos_dl.py", line 18, in <module>
    usuario = config.get('Database', 'user')
  File "/usr/local/lib/python3.7/configparser.py", line 780, in get
    d = self._unify_values(section, vars)
  File "/usr/local/lib/python3.7/configparser.py", line 1146, in _unify_values
    raise NoSectionError(section) from None
configparser.NoSectionError: No section: 'Database'
[2024-01-26T16:22:12.970+0000] {processor.py:755} WARNING - No viable dags retrieved from /opt/airflow/dags/etl_scripts/etl_atendimentos_dl.py
[2024-01-26T16:22:13.015+0000] {processor.py:175} INFO - Processing /opt/airflow/dags/etl_scripts/etl_atendimentos_dl.py took 0.477 seconds
[2024-01-26T16:22:16.959+0000] {processor.py:153} INFO - Started process (PID=16519) to work on /opt/airflow/dags/etl_scripts/etl_atendimentos_dl.py
[2024-01-26T16:22:16.962+0000] {processor.py:743} INFO - Processing file /opt/airflow/dags/etl_scripts/etl_atendimentos_dl.py for tasks to queue
[2024-01-26T16:22:16.964+0000] {logging_mixin.py:137} INFO - [2024-01-26T16:22:16.963+0000] {dagbag.py:538} INFO - Filling up the DagBag from /opt/airflow/dags/etl_scripts/etl_atendimentos_dl.py
[2024-01-26T16:22:17.021+0000] {logging_mixin.py:137} INFO - [2024-01-26T16:22:17.019+0000] {dagbag.py:343} ERROR - Failed to import: /opt/airflow/dags/etl_scripts/etl_atendimentos_dl.py
Traceback (most recent call last):
  File "/home/airflow/.local/lib/python3.7/site-packages/airflow/models/dagbag.py", line 339, in parse
    loader.exec_module(new_module)
  File "<frozen importlib._bootstrap_external>", line 724, in exec_module
  File "<frozen importlib._bootstrap_external>", line 860, in get_code
  File "<frozen importlib._bootstrap_external>", line 791, in source_to_code
  File "<frozen importlib._bootstrap>", line 219, in _call_with_frames_removed
  File "/opt/airflow/dags/etl_scripts/etl_atendimentos_dl.py", line 14
    config.read('C:\Users\User\Documents\GitHub\processoseletivo-teste\airflow-docker\dags\etl_scripts\confi_atendimento_dl.ini')
               ^
SyntaxError: (unicode error) 'unicodeescape' codec can't decode bytes in position 2-3: truncated \UXXXXXXXX escape
[2024-01-26T16:22:17.024+0000] {processor.py:755} WARNING - No viable dags retrieved from /opt/airflow/dags/etl_scripts/etl_atendimentos_dl.py
[2024-01-26T16:22:17.075+0000] {processor.py:175} INFO - Processing /opt/airflow/dags/etl_scripts/etl_atendimentos_dl.py took 0.121 seconds
[2024-01-26T16:22:34.097+0000] {processor.py:153} INFO - Started process (PID=16544) to work on /opt/airflow/dags/etl_scripts/etl_atendimentos_dl.py
[2024-01-26T16:22:34.100+0000] {processor.py:743} INFO - Processing file /opt/airflow/dags/etl_scripts/etl_atendimentos_dl.py for tasks to queue
[2024-01-26T16:22:34.105+0000] {logging_mixin.py:137} INFO - [2024-01-26T16:22:34.104+0000] {dagbag.py:538} INFO - Filling up the DagBag from /opt/airflow/dags/etl_scripts/etl_atendimentos_dl.py
[2024-01-26T16:22:34.995+0000] {logging_mixin.py:137} INFO - [2024-01-26T16:22:34.975+0000] {dagbag.py:343} ERROR - Failed to import: /opt/airflow/dags/etl_scripts/etl_atendimentos_dl.py
Traceback (most recent call last):
  File "/home/airflow/.local/lib/python3.7/site-packages/airflow/models/dagbag.py", line 339, in parse
    loader.exec_module(new_module)
  File "<frozen importlib._bootstrap_external>", line 728, in exec_module
  File "<frozen importlib._bootstrap>", line 219, in _call_with_frames_removed
  File "/opt/airflow/dags/etl_scripts/etl_atendimentos_dl.py", line 18, in <module>
    usuario = config.get('Database', 'user')
  File "/usr/local/lib/python3.7/configparser.py", line 780, in get
    d = self._unify_values(section, vars)
  File "/usr/local/lib/python3.7/configparser.py", line 1146, in _unify_values
    raise NoSectionError(section) from None
configparser.NoSectionError: No section: 'Database'
[2024-01-26T16:22:34.997+0000] {processor.py:755} WARNING - No viable dags retrieved from /opt/airflow/dags/etl_scripts/etl_atendimentos_dl.py
[2024-01-26T16:22:35.067+0000] {processor.py:175} INFO - Processing /opt/airflow/dags/etl_scripts/etl_atendimentos_dl.py took 0.978 seconds
[2024-01-26T16:23:05.536+0000] {processor.py:153} INFO - Started process (PID=16588) to work on /opt/airflow/dags/etl_scripts/etl_atendimentos_dl.py
[2024-01-26T16:23:05.538+0000] {processor.py:743} INFO - Processing file /opt/airflow/dags/etl_scripts/etl_atendimentos_dl.py for tasks to queue
[2024-01-26T16:23:05.539+0000] {logging_mixin.py:137} INFO - [2024-01-26T16:23:05.539+0000] {dagbag.py:538} INFO - Filling up the DagBag from /opt/airflow/dags/etl_scripts/etl_atendimentos_dl.py
[2024-01-26T16:23:06.189+0000] {logging_mixin.py:137} INFO - [2024-01-26T16:23:06.179+0000] {dagbag.py:343} ERROR - Failed to import: /opt/airflow/dags/etl_scripts/etl_atendimentos_dl.py
Traceback (most recent call last):
  File "/home/airflow/.local/lib/python3.7/site-packages/airflow/models/dagbag.py", line 339, in parse
    loader.exec_module(new_module)
  File "<frozen importlib._bootstrap_external>", line 728, in exec_module
  File "<frozen importlib._bootstrap>", line 219, in _call_with_frames_removed
  File "/opt/airflow/dags/etl_scripts/etl_atendimentos_dl.py", line 18, in <module>
    usuario = config.get('Database', 'user')
  File "/usr/local/lib/python3.7/configparser.py", line 780, in get
    d = self._unify_values(section, vars)
  File "/usr/local/lib/python3.7/configparser.py", line 1146, in _unify_values
    raise NoSectionError(section) from None
configparser.NoSectionError: No section: 'Database'
[2024-01-26T16:23:06.190+0000] {processor.py:755} WARNING - No viable dags retrieved from /opt/airflow/dags/etl_scripts/etl_atendimentos_dl.py
[2024-01-26T16:23:06.222+0000] {processor.py:175} INFO - Processing /opt/airflow/dags/etl_scripts/etl_atendimentos_dl.py took 0.693 seconds
[2024-01-26T16:23:36.665+0000] {processor.py:153} INFO - Started process (PID=16623) to work on /opt/airflow/dags/etl_scripts/etl_atendimentos_dl.py
[2024-01-26T16:23:36.667+0000] {processor.py:743} INFO - Processing file /opt/airflow/dags/etl_scripts/etl_atendimentos_dl.py for tasks to queue
[2024-01-26T16:23:36.669+0000] {logging_mixin.py:137} INFO - [2024-01-26T16:23:36.668+0000] {dagbag.py:538} INFO - Filling up the DagBag from /opt/airflow/dags/etl_scripts/etl_atendimentos_dl.py
[2024-01-26T16:23:37.029+0000] {logging_mixin.py:137} INFO - [2024-01-26T16:23:37.017+0000] {dagbag.py:343} ERROR - Failed to import: /opt/airflow/dags/etl_scripts/etl_atendimentos_dl.py
Traceback (most recent call last):
  File "/home/airflow/.local/lib/python3.7/site-packages/airflow/models/dagbag.py", line 339, in parse
    loader.exec_module(new_module)
  File "<frozen importlib._bootstrap_external>", line 728, in exec_module
  File "<frozen importlib._bootstrap>", line 219, in _call_with_frames_removed
  File "/opt/airflow/dags/etl_scripts/etl_atendimentos_dl.py", line 18, in <module>
    usuario = config.get('Database', 'user')
  File "/usr/local/lib/python3.7/configparser.py", line 780, in get
    d = self._unify_values(section, vars)
  File "/usr/local/lib/python3.7/configparser.py", line 1146, in _unify_values
    raise NoSectionError(section) from None
configparser.NoSectionError: No section: 'Database'
[2024-01-26T16:23:37.030+0000] {processor.py:755} WARNING - No viable dags retrieved from /opt/airflow/dags/etl_scripts/etl_atendimentos_dl.py
[2024-01-26T16:23:37.052+0000] {processor.py:175} INFO - Processing /opt/airflow/dags/etl_scripts/etl_atendimentos_dl.py took 0.390 seconds
[2024-01-26T16:24:07.108+0000] {processor.py:153} INFO - Started process (PID=16658) to work on /opt/airflow/dags/etl_scripts/etl_atendimentos_dl.py
[2024-01-26T16:24:07.109+0000] {processor.py:743} INFO - Processing file /opt/airflow/dags/etl_scripts/etl_atendimentos_dl.py for tasks to queue
[2024-01-26T16:24:07.110+0000] {logging_mixin.py:137} INFO - [2024-01-26T16:24:07.110+0000] {dagbag.py:538} INFO - Filling up the DagBag from /opt/airflow/dags/etl_scripts/etl_atendimentos_dl.py
[2024-01-26T16:24:07.553+0000] {logging_mixin.py:137} INFO - [2024-01-26T16:24:07.542+0000] {dagbag.py:343} ERROR - Failed to import: /opt/airflow/dags/etl_scripts/etl_atendimentos_dl.py
Traceback (most recent call last):
  File "/home/airflow/.local/lib/python3.7/site-packages/airflow/models/dagbag.py", line 339, in parse
    loader.exec_module(new_module)
  File "<frozen importlib._bootstrap_external>", line 728, in exec_module
  File "<frozen importlib._bootstrap>", line 219, in _call_with_frames_removed
  File "/opt/airflow/dags/etl_scripts/etl_atendimentos_dl.py", line 18, in <module>
    usuario = config.get('Database', 'user')
  File "/usr/local/lib/python3.7/configparser.py", line 780, in get
    d = self._unify_values(section, vars)
  File "/usr/local/lib/python3.7/configparser.py", line 1146, in _unify_values
    raise NoSectionError(section) from None
configparser.NoSectionError: No section: 'Database'
[2024-01-26T16:24:07.555+0000] {processor.py:755} WARNING - No viable dags retrieved from /opt/airflow/dags/etl_scripts/etl_atendimentos_dl.py
[2024-01-26T16:24:07.590+0000] {processor.py:175} INFO - Processing /opt/airflow/dags/etl_scripts/etl_atendimentos_dl.py took 0.486 seconds
[2024-01-26T16:24:37.667+0000] {processor.py:153} INFO - Started process (PID=16693) to work on /opt/airflow/dags/etl_scripts/etl_atendimentos_dl.py
[2024-01-26T16:24:37.668+0000] {processor.py:743} INFO - Processing file /opt/airflow/dags/etl_scripts/etl_atendimentos_dl.py for tasks to queue
[2024-01-26T16:24:37.669+0000] {logging_mixin.py:137} INFO - [2024-01-26T16:24:37.669+0000] {dagbag.py:538} INFO - Filling up the DagBag from /opt/airflow/dags/etl_scripts/etl_atendimentos_dl.py
[2024-01-26T16:24:38.262+0000] {logging_mixin.py:137} INFO - [2024-01-26T16:24:38.251+0000] {dagbag.py:343} ERROR - Failed to import: /opt/airflow/dags/etl_scripts/etl_atendimentos_dl.py
Traceback (most recent call last):
  File "/home/airflow/.local/lib/python3.7/site-packages/airflow/models/dagbag.py", line 339, in parse
    loader.exec_module(new_module)
  File "<frozen importlib._bootstrap_external>", line 728, in exec_module
  File "<frozen importlib._bootstrap>", line 219, in _call_with_frames_removed
  File "/opt/airflow/dags/etl_scripts/etl_atendimentos_dl.py", line 18, in <module>
    usuario = config.get('Database', 'user')
  File "/usr/local/lib/python3.7/configparser.py", line 780, in get
    d = self._unify_values(section, vars)
  File "/usr/local/lib/python3.7/configparser.py", line 1146, in _unify_values
    raise NoSectionError(section) from None
configparser.NoSectionError: No section: 'Database'
[2024-01-26T16:24:38.264+0000] {processor.py:755} WARNING - No viable dags retrieved from /opt/airflow/dags/etl_scripts/etl_atendimentos_dl.py
[2024-01-26T16:24:38.368+0000] {processor.py:175} INFO - Processing /opt/airflow/dags/etl_scripts/etl_atendimentos_dl.py took 0.705 seconds
[2024-01-26T16:25:08.549+0000] {processor.py:153} INFO - Started process (PID=16729) to work on /opt/airflow/dags/etl_scripts/etl_atendimentos_dl.py
[2024-01-26T16:25:08.552+0000] {processor.py:743} INFO - Processing file /opt/airflow/dags/etl_scripts/etl_atendimentos_dl.py for tasks to queue
[2024-01-26T16:25:08.554+0000] {logging_mixin.py:137} INFO - [2024-01-26T16:25:08.554+0000] {dagbag.py:538} INFO - Filling up the DagBag from /opt/airflow/dags/etl_scripts/etl_atendimentos_dl.py
[2024-01-26T16:25:09.048+0000] {logging_mixin.py:137} INFO - [2024-01-26T16:25:09.029+0000] {dagbag.py:343} ERROR - Failed to import: /opt/airflow/dags/etl_scripts/etl_atendimentos_dl.py
Traceback (most recent call last):
  File "/home/airflow/.local/lib/python3.7/site-packages/airflow/models/dagbag.py", line 339, in parse
    loader.exec_module(new_module)
  File "<frozen importlib._bootstrap_external>", line 728, in exec_module
  File "<frozen importlib._bootstrap>", line 219, in _call_with_frames_removed
  File "/opt/airflow/dags/etl_scripts/etl_atendimentos_dl.py", line 18, in <module>
    usuario = config.get('Database', 'user')
  File "/usr/local/lib/python3.7/configparser.py", line 780, in get
    d = self._unify_values(section, vars)
  File "/usr/local/lib/python3.7/configparser.py", line 1146, in _unify_values
    raise NoSectionError(section) from None
configparser.NoSectionError: No section: 'Database'
[2024-01-26T16:25:09.050+0000] {processor.py:755} WARNING - No viable dags retrieved from /opt/airflow/dags/etl_scripts/etl_atendimentos_dl.py
[2024-01-26T16:25:09.108+0000] {processor.py:175} INFO - Processing /opt/airflow/dags/etl_scripts/etl_atendimentos_dl.py took 0.565 seconds
[2024-01-26T16:25:13.880+0000] {processor.py:153} INFO - Started process (PID=16748) to work on /opt/airflow/dags/etl_scripts/etl_atendimentos_dl.py
[2024-01-26T16:25:13.882+0000] {processor.py:743} INFO - Processing file /opt/airflow/dags/etl_scripts/etl_atendimentos_dl.py for tasks to queue
[2024-01-26T16:25:13.888+0000] {logging_mixin.py:137} INFO - [2024-01-26T16:25:13.886+0000] {dagbag.py:538} INFO - Filling up the DagBag from /opt/airflow/dags/etl_scripts/etl_atendimentos_dl.py
[2024-01-26T16:25:14.966+0000] {logging_mixin.py:137} INFO - [2024-01-26T16:25:14.935+0000] {dagbag.py:343} ERROR - Failed to import: /opt/airflow/dags/etl_scripts/etl_atendimentos_dl.py
Traceback (most recent call last):
  File "/home/airflow/.local/lib/python3.7/site-packages/airflow/models/dagbag.py", line 339, in parse
    loader.exec_module(new_module)
  File "<frozen importlib._bootstrap_external>", line 728, in exec_module
  File "<frozen importlib._bootstrap>", line 219, in _call_with_frames_removed
  File "/opt/airflow/dags/etl_scripts/etl_atendimentos_dl.py", line 18, in <module>
    usuario = config.get('Database', 'user')
  File "/usr/local/lib/python3.7/configparser.py", line 780, in get
    d = self._unify_values(section, vars)
  File "/usr/local/lib/python3.7/configparser.py", line 1146, in _unify_values
    raise NoSectionError(section) from None
configparser.NoSectionError: No section: 'Database'
[2024-01-26T16:25:14.967+0000] {processor.py:755} WARNING - No viable dags retrieved from /opt/airflow/dags/etl_scripts/etl_atendimentos_dl.py
[2024-01-26T16:25:14.998+0000] {processor.py:175} INFO - Processing /opt/airflow/dags/etl_scripts/etl_atendimentos_dl.py took 1.133 seconds
[2024-01-26T16:25:45.457+0000] {processor.py:153} INFO - Started process (PID=16783) to work on /opt/airflow/dags/etl_scripts/etl_atendimentos_dl.py
[2024-01-26T16:25:45.458+0000] {processor.py:743} INFO - Processing file /opt/airflow/dags/etl_scripts/etl_atendimentos_dl.py for tasks to queue
[2024-01-26T16:25:45.459+0000] {logging_mixin.py:137} INFO - [2024-01-26T16:25:45.459+0000] {dagbag.py:538} INFO - Filling up the DagBag from /opt/airflow/dags/etl_scripts/etl_atendimentos_dl.py
[2024-01-26T16:25:45.986+0000] {logging_mixin.py:137} INFO - [2024-01-26T16:25:45.977+0000] {dagbag.py:343} ERROR - Failed to import: /opt/airflow/dags/etl_scripts/etl_atendimentos_dl.py
Traceback (most recent call last):
  File "/home/airflow/.local/lib/python3.7/site-packages/airflow/models/dagbag.py", line 339, in parse
    loader.exec_module(new_module)
  File "<frozen importlib._bootstrap_external>", line 728, in exec_module
  File "<frozen importlib._bootstrap>", line 219, in _call_with_frames_removed
  File "/opt/airflow/dags/etl_scripts/etl_atendimentos_dl.py", line 18, in <module>
    usuario = config.get('Database', 'user')
  File "/usr/local/lib/python3.7/configparser.py", line 780, in get
    d = self._unify_values(section, vars)
  File "/usr/local/lib/python3.7/configparser.py", line 1146, in _unify_values
    raise NoSectionError(section) from None
configparser.NoSectionError: No section: 'Database'
[2024-01-26T16:25:45.988+0000] {processor.py:755} WARNING - No viable dags retrieved from /opt/airflow/dags/etl_scripts/etl_atendimentos_dl.py
[2024-01-26T16:25:46.016+0000] {processor.py:175} INFO - Processing /opt/airflow/dags/etl_scripts/etl_atendimentos_dl.py took 0.563 seconds
[2024-01-26T16:26:16.761+0000] {processor.py:153} INFO - Started process (PID=16818) to work on /opt/airflow/dags/etl_scripts/etl_atendimentos_dl.py
[2024-01-26T16:26:16.763+0000] {processor.py:743} INFO - Processing file /opt/airflow/dags/etl_scripts/etl_atendimentos_dl.py for tasks to queue
[2024-01-26T16:26:16.765+0000] {logging_mixin.py:137} INFO - [2024-01-26T16:26:16.765+0000] {dagbag.py:538} INFO - Filling up the DagBag from /opt/airflow/dags/etl_scripts/etl_atendimentos_dl.py
[2024-01-26T16:26:17.400+0000] {logging_mixin.py:137} INFO - [2024-01-26T16:26:17.390+0000] {dagbag.py:343} ERROR - Failed to import: /opt/airflow/dags/etl_scripts/etl_atendimentos_dl.py
Traceback (most recent call last):
  File "/home/airflow/.local/lib/python3.7/site-packages/airflow/models/dagbag.py", line 339, in parse
    loader.exec_module(new_module)
  File "<frozen importlib._bootstrap_external>", line 728, in exec_module
  File "<frozen importlib._bootstrap>", line 219, in _call_with_frames_removed
  File "/opt/airflow/dags/etl_scripts/etl_atendimentos_dl.py", line 18, in <module>
    usuario = config.get('Database', 'user')
  File "/usr/local/lib/python3.7/configparser.py", line 780, in get
    d = self._unify_values(section, vars)
  File "/usr/local/lib/python3.7/configparser.py", line 1146, in _unify_values
    raise NoSectionError(section) from None
configparser.NoSectionError: No section: 'Database'
[2024-01-26T16:26:17.402+0000] {processor.py:755} WARNING - No viable dags retrieved from /opt/airflow/dags/etl_scripts/etl_atendimentos_dl.py
[2024-01-26T16:26:17.433+0000] {processor.py:175} INFO - Processing /opt/airflow/dags/etl_scripts/etl_atendimentos_dl.py took 0.676 seconds
[2024-01-26T16:26:47.590+0000] {processor.py:153} INFO - Started process (PID=16853) to work on /opt/airflow/dags/etl_scripts/etl_atendimentos_dl.py
[2024-01-26T16:26:47.592+0000] {processor.py:743} INFO - Processing file /opt/airflow/dags/etl_scripts/etl_atendimentos_dl.py for tasks to queue
[2024-01-26T16:26:47.595+0000] {logging_mixin.py:137} INFO - [2024-01-26T16:26:47.594+0000] {dagbag.py:538} INFO - Filling up the DagBag from /opt/airflow/dags/etl_scripts/etl_atendimentos_dl.py
[2024-01-26T16:26:48.218+0000] {logging_mixin.py:137} INFO - [2024-01-26T16:26:48.211+0000] {dagbag.py:343} ERROR - Failed to import: /opt/airflow/dags/etl_scripts/etl_atendimentos_dl.py
Traceback (most recent call last):
  File "/home/airflow/.local/lib/python3.7/site-packages/airflow/models/dagbag.py", line 339, in parse
    loader.exec_module(new_module)
  File "<frozen importlib._bootstrap_external>", line 728, in exec_module
  File "<frozen importlib._bootstrap>", line 219, in _call_with_frames_removed
  File "/opt/airflow/dags/etl_scripts/etl_atendimentos_dl.py", line 18, in <module>
    usuario = config.get('Database', 'user')
  File "/usr/local/lib/python3.7/configparser.py", line 780, in get
    d = self._unify_values(section, vars)
  File "/usr/local/lib/python3.7/configparser.py", line 1146, in _unify_values
    raise NoSectionError(section) from None
configparser.NoSectionError: No section: 'Database'
[2024-01-26T16:26:48.219+0000] {processor.py:755} WARNING - No viable dags retrieved from /opt/airflow/dags/etl_scripts/etl_atendimentos_dl.py
[2024-01-26T16:26:48.248+0000] {processor.py:175} INFO - Processing /opt/airflow/dags/etl_scripts/etl_atendimentos_dl.py took 0.664 seconds
[2024-01-26T16:27:18.636+0000] {processor.py:153} INFO - Started process (PID=16888) to work on /opt/airflow/dags/etl_scripts/etl_atendimentos_dl.py
[2024-01-26T16:27:18.637+0000] {processor.py:743} INFO - Processing file /opt/airflow/dags/etl_scripts/etl_atendimentos_dl.py for tasks to queue
[2024-01-26T16:27:18.639+0000] {logging_mixin.py:137} INFO - [2024-01-26T16:27:18.638+0000] {dagbag.py:538} INFO - Filling up the DagBag from /opt/airflow/dags/etl_scripts/etl_atendimentos_dl.py
[2024-01-26T16:27:18.936+0000] {logging_mixin.py:137} INFO - [2024-01-26T16:27:18.929+0000] {dagbag.py:343} ERROR - Failed to import: /opt/airflow/dags/etl_scripts/etl_atendimentos_dl.py
Traceback (most recent call last):
  File "/home/airflow/.local/lib/python3.7/site-packages/airflow/models/dagbag.py", line 339, in parse
    loader.exec_module(new_module)
  File "<frozen importlib._bootstrap_external>", line 728, in exec_module
  File "<frozen importlib._bootstrap>", line 219, in _call_with_frames_removed
  File "/opt/airflow/dags/etl_scripts/etl_atendimentos_dl.py", line 18, in <module>
    usuario = config.get('Database', 'user')
  File "/usr/local/lib/python3.7/configparser.py", line 780, in get
    d = self._unify_values(section, vars)
  File "/usr/local/lib/python3.7/configparser.py", line 1146, in _unify_values
    raise NoSectionError(section) from None
configparser.NoSectionError: No section: 'Database'
[2024-01-26T16:27:18.937+0000] {processor.py:755} WARNING - No viable dags retrieved from /opt/airflow/dags/etl_scripts/etl_atendimentos_dl.py
[2024-01-26T16:27:18.958+0000] {processor.py:175} INFO - Processing /opt/airflow/dags/etl_scripts/etl_atendimentos_dl.py took 0.326 seconds
[2024-01-26T16:27:49.024+0000] {processor.py:153} INFO - Started process (PID=16939) to work on /opt/airflow/dags/etl_scripts/etl_atendimentos_dl.py
[2024-01-26T16:27:49.026+0000] {processor.py:743} INFO - Processing file /opt/airflow/dags/etl_scripts/etl_atendimentos_dl.py for tasks to queue
[2024-01-26T16:27:49.027+0000] {logging_mixin.py:137} INFO - [2024-01-26T16:27:49.026+0000] {dagbag.py:538} INFO - Filling up the DagBag from /opt/airflow/dags/etl_scripts/etl_atendimentos_dl.py
[2024-01-26T16:27:49.858+0000] {logging_mixin.py:137} INFO - [2024-01-26T16:27:49.830+0000] {dagbag.py:343} ERROR - Failed to import: /opt/airflow/dags/etl_scripts/etl_atendimentos_dl.py
Traceback (most recent call last):
  File "/home/airflow/.local/lib/python3.7/site-packages/airflow/models/dagbag.py", line 339, in parse
    loader.exec_module(new_module)
  File "<frozen importlib._bootstrap_external>", line 728, in exec_module
  File "<frozen importlib._bootstrap>", line 219, in _call_with_frames_removed
  File "/opt/airflow/dags/etl_scripts/etl_atendimentos_dl.py", line 18, in <module>
    usuario = config.get('Database', 'user')
  File "/usr/local/lib/python3.7/configparser.py", line 780, in get
    d = self._unify_values(section, vars)
  File "/usr/local/lib/python3.7/configparser.py", line 1146, in _unify_values
    raise NoSectionError(section) from None
configparser.NoSectionError: No section: 'Database'
[2024-01-26T16:27:49.859+0000] {processor.py:755} WARNING - No viable dags retrieved from /opt/airflow/dags/etl_scripts/etl_atendimentos_dl.py
[2024-01-26T16:27:49.883+0000] {processor.py:175} INFO - Processing /opt/airflow/dags/etl_scripts/etl_atendimentos_dl.py took 0.863 seconds
[2024-01-26T16:28:20.403+0000] {processor.py:153} INFO - Started process (PID=16974) to work on /opt/airflow/dags/etl_scripts/etl_atendimentos_dl.py
[2024-01-26T16:28:20.404+0000] {processor.py:743} INFO - Processing file /opt/airflow/dags/etl_scripts/etl_atendimentos_dl.py for tasks to queue
[2024-01-26T16:28:20.405+0000] {logging_mixin.py:137} INFO - [2024-01-26T16:28:20.405+0000] {dagbag.py:538} INFO - Filling up the DagBag from /opt/airflow/dags/etl_scripts/etl_atendimentos_dl.py
[2024-01-26T16:28:20.738+0000] {logging_mixin.py:137} INFO - [2024-01-26T16:28:20.732+0000] {dagbag.py:343} ERROR - Failed to import: /opt/airflow/dags/etl_scripts/etl_atendimentos_dl.py
Traceback (most recent call last):
  File "/home/airflow/.local/lib/python3.7/site-packages/airflow/models/dagbag.py", line 339, in parse
    loader.exec_module(new_module)
  File "<frozen importlib._bootstrap_external>", line 728, in exec_module
  File "<frozen importlib._bootstrap>", line 219, in _call_with_frames_removed
  File "/opt/airflow/dags/etl_scripts/etl_atendimentos_dl.py", line 18, in <module>
    usuario = config.get('Database', 'user')
  File "/usr/local/lib/python3.7/configparser.py", line 780, in get
    d = self._unify_values(section, vars)
  File "/usr/local/lib/python3.7/configparser.py", line 1146, in _unify_values
    raise NoSectionError(section) from None
configparser.NoSectionError: No section: 'Database'
[2024-01-26T16:28:20.739+0000] {processor.py:755} WARNING - No viable dags retrieved from /opt/airflow/dags/etl_scripts/etl_atendimentos_dl.py
[2024-01-26T16:28:20.760+0000] {processor.py:175} INFO - Processing /opt/airflow/dags/etl_scripts/etl_atendimentos_dl.py took 0.360 seconds
[2024-01-26T16:28:50.809+0000] {processor.py:153} INFO - Started process (PID=17009) to work on /opt/airflow/dags/etl_scripts/etl_atendimentos_dl.py
[2024-01-26T16:28:50.810+0000] {processor.py:743} INFO - Processing file /opt/airflow/dags/etl_scripts/etl_atendimentos_dl.py for tasks to queue
[2024-01-26T16:28:50.811+0000] {logging_mixin.py:137} INFO - [2024-01-26T16:28:50.811+0000] {dagbag.py:538} INFO - Filling up the DagBag from /opt/airflow/dags/etl_scripts/etl_atendimentos_dl.py
[2024-01-26T16:28:51.108+0000] {logging_mixin.py:137} INFO - [2024-01-26T16:28:51.100+0000] {dagbag.py:343} ERROR - Failed to import: /opt/airflow/dags/etl_scripts/etl_atendimentos_dl.py
Traceback (most recent call last):
  File "/home/airflow/.local/lib/python3.7/site-packages/airflow/models/dagbag.py", line 339, in parse
    loader.exec_module(new_module)
  File "<frozen importlib._bootstrap_external>", line 728, in exec_module
  File "<frozen importlib._bootstrap>", line 219, in _call_with_frames_removed
  File "/opt/airflow/dags/etl_scripts/etl_atendimentos_dl.py", line 18, in <module>
    usuario = config.get('Database', 'user')
  File "/usr/local/lib/python3.7/configparser.py", line 780, in get
    d = self._unify_values(section, vars)
  File "/usr/local/lib/python3.7/configparser.py", line 1146, in _unify_values
    raise NoSectionError(section) from None
configparser.NoSectionError: No section: 'Database'
[2024-01-26T16:28:51.109+0000] {processor.py:755} WARNING - No viable dags retrieved from /opt/airflow/dags/etl_scripts/etl_atendimentos_dl.py
[2024-01-26T16:28:51.132+0000] {processor.py:175} INFO - Processing /opt/airflow/dags/etl_scripts/etl_atendimentos_dl.py took 0.327 seconds
[2024-01-26T16:29:21.200+0000] {processor.py:153} INFO - Started process (PID=17060) to work on /opt/airflow/dags/etl_scripts/etl_atendimentos_dl.py
[2024-01-26T16:29:21.201+0000] {processor.py:743} INFO - Processing file /opt/airflow/dags/etl_scripts/etl_atendimentos_dl.py for tasks to queue
[2024-01-26T16:29:21.202+0000] {logging_mixin.py:137} INFO - [2024-01-26T16:29:21.202+0000] {dagbag.py:538} INFO - Filling up the DagBag from /opt/airflow/dags/etl_scripts/etl_atendimentos_dl.py
[2024-01-26T16:29:21.522+0000] {logging_mixin.py:137} INFO - [2024-01-26T16:29:21.515+0000] {dagbag.py:343} ERROR - Failed to import: /opt/airflow/dags/etl_scripts/etl_atendimentos_dl.py
Traceback (most recent call last):
  File "/home/airflow/.local/lib/python3.7/site-packages/airflow/models/dagbag.py", line 339, in parse
    loader.exec_module(new_module)
  File "<frozen importlib._bootstrap_external>", line 728, in exec_module
  File "<frozen importlib._bootstrap>", line 219, in _call_with_frames_removed
  File "/opt/airflow/dags/etl_scripts/etl_atendimentos_dl.py", line 18, in <module>
    usuario = config.get('Database', 'user')
  File "/usr/local/lib/python3.7/configparser.py", line 780, in get
    d = self._unify_values(section, vars)
  File "/usr/local/lib/python3.7/configparser.py", line 1146, in _unify_values
    raise NoSectionError(section) from None
configparser.NoSectionError: No section: 'Database'
[2024-01-26T16:29:21.523+0000] {processor.py:755} WARNING - No viable dags retrieved from /opt/airflow/dags/etl_scripts/etl_atendimentos_dl.py
[2024-01-26T16:29:21.543+0000] {processor.py:175} INFO - Processing /opt/airflow/dags/etl_scripts/etl_atendimentos_dl.py took 0.346 seconds
[2024-01-26T16:29:51.611+0000] {processor.py:153} INFO - Started process (PID=17095) to work on /opt/airflow/dags/etl_scripts/etl_atendimentos_dl.py
[2024-01-26T16:29:51.613+0000] {processor.py:743} INFO - Processing file /opt/airflow/dags/etl_scripts/etl_atendimentos_dl.py for tasks to queue
[2024-01-26T16:29:51.615+0000] {logging_mixin.py:137} INFO - [2024-01-26T16:29:51.614+0000] {dagbag.py:538} INFO - Filling up the DagBag from /opt/airflow/dags/etl_scripts/etl_atendimentos_dl.py
[2024-01-26T16:29:51.867+0000] {logging_mixin.py:137} INFO - [2024-01-26T16:29:51.859+0000] {dagbag.py:343} ERROR - Failed to import: /opt/airflow/dags/etl_scripts/etl_atendimentos_dl.py
Traceback (most recent call last):
  File "/home/airflow/.local/lib/python3.7/site-packages/airflow/models/dagbag.py", line 339, in parse
    loader.exec_module(new_module)
  File "<frozen importlib._bootstrap_external>", line 728, in exec_module
  File "<frozen importlib._bootstrap>", line 219, in _call_with_frames_removed
  File "/opt/airflow/dags/etl_scripts/etl_atendimentos_dl.py", line 18, in <module>
    usuario = config.get('Database', 'user')
  File "/usr/local/lib/python3.7/configparser.py", line 780, in get
    d = self._unify_values(section, vars)
  File "/usr/local/lib/python3.7/configparser.py", line 1146, in _unify_values
    raise NoSectionError(section) from None
configparser.NoSectionError: No section: 'Database'
[2024-01-26T16:29:51.868+0000] {processor.py:755} WARNING - No viable dags retrieved from /opt/airflow/dags/etl_scripts/etl_atendimentos_dl.py
[2024-01-26T16:29:51.887+0000] {processor.py:175} INFO - Processing /opt/airflow/dags/etl_scripts/etl_atendimentos_dl.py took 0.279 seconds
[2024-01-26T16:30:22.003+0000] {processor.py:153} INFO - Started process (PID=17130) to work on /opt/airflow/dags/etl_scripts/etl_atendimentos_dl.py
[2024-01-26T16:30:22.004+0000] {processor.py:743} INFO - Processing file /opt/airflow/dags/etl_scripts/etl_atendimentos_dl.py for tasks to queue
[2024-01-26T16:30:22.005+0000] {logging_mixin.py:137} INFO - [2024-01-26T16:30:22.005+0000] {dagbag.py:538} INFO - Filling up the DagBag from /opt/airflow/dags/etl_scripts/etl_atendimentos_dl.py
[2024-01-26T16:30:22.378+0000] {logging_mixin.py:137} INFO - [2024-01-26T16:30:22.364+0000] {dagbag.py:343} ERROR - Failed to import: /opt/airflow/dags/etl_scripts/etl_atendimentos_dl.py
Traceback (most recent call last):
  File "/home/airflow/.local/lib/python3.7/site-packages/airflow/models/dagbag.py", line 339, in parse
    loader.exec_module(new_module)
  File "<frozen importlib._bootstrap_external>", line 728, in exec_module
  File "<frozen importlib._bootstrap>", line 219, in _call_with_frames_removed
  File "/opt/airflow/dags/etl_scripts/etl_atendimentos_dl.py", line 18, in <module>
    usuario = config.get('Database', 'user')
  File "/usr/local/lib/python3.7/configparser.py", line 780, in get
    d = self._unify_values(section, vars)
  File "/usr/local/lib/python3.7/configparser.py", line 1146, in _unify_values
    raise NoSectionError(section) from None
configparser.NoSectionError: No section: 'Database'
[2024-01-26T16:30:22.379+0000] {processor.py:755} WARNING - No viable dags retrieved from /opt/airflow/dags/etl_scripts/etl_atendimentos_dl.py
[2024-01-26T16:30:22.446+0000] {processor.py:175} INFO - Processing /opt/airflow/dags/etl_scripts/etl_atendimentos_dl.py took 0.446 seconds
[2024-01-26T16:30:53.267+0000] {processor.py:153} INFO - Started process (PID=17181) to work on /opt/airflow/dags/etl_scripts/etl_atendimentos_dl.py
[2024-01-26T16:30:53.269+0000] {processor.py:743} INFO - Processing file /opt/airflow/dags/etl_scripts/etl_atendimentos_dl.py for tasks to queue
[2024-01-26T16:30:53.270+0000] {logging_mixin.py:137} INFO - [2024-01-26T16:30:53.269+0000] {dagbag.py:538} INFO - Filling up the DagBag from /opt/airflow/dags/etl_scripts/etl_atendimentos_dl.py
[2024-01-26T16:30:53.535+0000] {logging_mixin.py:137} INFO - [2024-01-26T16:30:53.527+0000] {dagbag.py:343} ERROR - Failed to import: /opt/airflow/dags/etl_scripts/etl_atendimentos_dl.py
Traceback (most recent call last):
  File "/home/airflow/.local/lib/python3.7/site-packages/airflow/models/dagbag.py", line 339, in parse
    loader.exec_module(new_module)
  File "<frozen importlib._bootstrap_external>", line 728, in exec_module
  File "<frozen importlib._bootstrap>", line 219, in _call_with_frames_removed
  File "/opt/airflow/dags/etl_scripts/etl_atendimentos_dl.py", line 18, in <module>
    usuario = config.get('Database', 'user')
  File "/usr/local/lib/python3.7/configparser.py", line 780, in get
    d = self._unify_values(section, vars)
  File "/usr/local/lib/python3.7/configparser.py", line 1146, in _unify_values
    raise NoSectionError(section) from None
configparser.NoSectionError: No section: 'Database'
[2024-01-26T16:30:53.535+0000] {processor.py:755} WARNING - No viable dags retrieved from /opt/airflow/dags/etl_scripts/etl_atendimentos_dl.py
[2024-01-26T16:30:53.556+0000] {processor.py:175} INFO - Processing /opt/airflow/dags/etl_scripts/etl_atendimentos_dl.py took 0.292 seconds
[2024-01-26T16:31:23.819+0000] {processor.py:153} INFO - Started process (PID=17216) to work on /opt/airflow/dags/etl_scripts/etl_atendimentos_dl.py
[2024-01-26T16:31:23.821+0000] {processor.py:743} INFO - Processing file /opt/airflow/dags/etl_scripts/etl_atendimentos_dl.py for tasks to queue
[2024-01-26T16:31:23.822+0000] {logging_mixin.py:137} INFO - [2024-01-26T16:31:23.822+0000] {dagbag.py:538} INFO - Filling up the DagBag from /opt/airflow/dags/etl_scripts/etl_atendimentos_dl.py
[2024-01-26T16:31:24.153+0000] {logging_mixin.py:137} INFO - [2024-01-26T16:31:24.144+0000] {dagbag.py:343} ERROR - Failed to import: /opt/airflow/dags/etl_scripts/etl_atendimentos_dl.py
Traceback (most recent call last):
  File "/home/airflow/.local/lib/python3.7/site-packages/airflow/models/dagbag.py", line 339, in parse
    loader.exec_module(new_module)
  File "<frozen importlib._bootstrap_external>", line 728, in exec_module
  File "<frozen importlib._bootstrap>", line 219, in _call_with_frames_removed
  File "/opt/airflow/dags/etl_scripts/etl_atendimentos_dl.py", line 18, in <module>
    usuario = config.get('Database', 'user')
  File "/usr/local/lib/python3.7/configparser.py", line 780, in get
    d = self._unify_values(section, vars)
  File "/usr/local/lib/python3.7/configparser.py", line 1146, in _unify_values
    raise NoSectionError(section) from None
configparser.NoSectionError: No section: 'Database'
[2024-01-26T16:31:24.154+0000] {processor.py:755} WARNING - No viable dags retrieved from /opt/airflow/dags/etl_scripts/etl_atendimentos_dl.py
[2024-01-26T16:31:24.178+0000] {processor.py:175} INFO - Processing /opt/airflow/dags/etl_scripts/etl_atendimentos_dl.py took 0.362 seconds
[2024-01-26T16:31:54.222+0000] {processor.py:153} INFO - Started process (PID=17267) to work on /opt/airflow/dags/etl_scripts/etl_atendimentos_dl.py
[2024-01-26T16:31:54.224+0000] {processor.py:743} INFO - Processing file /opt/airflow/dags/etl_scripts/etl_atendimentos_dl.py for tasks to queue
[2024-01-26T16:31:54.225+0000] {logging_mixin.py:137} INFO - [2024-01-26T16:31:54.224+0000] {dagbag.py:538} INFO - Filling up the DagBag from /opt/airflow/dags/etl_scripts/etl_atendimentos_dl.py
[2024-01-26T16:31:54.482+0000] {logging_mixin.py:137} INFO - [2024-01-26T16:31:54.475+0000] {dagbag.py:343} ERROR - Failed to import: /opt/airflow/dags/etl_scripts/etl_atendimentos_dl.py
Traceback (most recent call last):
  File "/home/airflow/.local/lib/python3.7/site-packages/airflow/models/dagbag.py", line 339, in parse
    loader.exec_module(new_module)
  File "<frozen importlib._bootstrap_external>", line 728, in exec_module
  File "<frozen importlib._bootstrap>", line 219, in _call_with_frames_removed
  File "/opt/airflow/dags/etl_scripts/etl_atendimentos_dl.py", line 18, in <module>
    usuario = config.get('Database', 'user')
  File "/usr/local/lib/python3.7/configparser.py", line 780, in get
    d = self._unify_values(section, vars)
  File "/usr/local/lib/python3.7/configparser.py", line 1146, in _unify_values
    raise NoSectionError(section) from None
configparser.NoSectionError: No section: 'Database'
[2024-01-26T16:31:54.484+0000] {processor.py:755} WARNING - No viable dags retrieved from /opt/airflow/dags/etl_scripts/etl_atendimentos_dl.py
[2024-01-26T16:31:54.506+0000] {processor.py:175} INFO - Processing /opt/airflow/dags/etl_scripts/etl_atendimentos_dl.py took 0.287 seconds
[2024-01-26T16:32:24.658+0000] {processor.py:153} INFO - Started process (PID=17302) to work on /opt/airflow/dags/etl_scripts/etl_atendimentos_dl.py
[2024-01-26T16:32:24.659+0000] {processor.py:743} INFO - Processing file /opt/airflow/dags/etl_scripts/etl_atendimentos_dl.py for tasks to queue
[2024-01-26T16:32:24.660+0000] {logging_mixin.py:137} INFO - [2024-01-26T16:32:24.660+0000] {dagbag.py:538} INFO - Filling up the DagBag from /opt/airflow/dags/etl_scripts/etl_atendimentos_dl.py
[2024-01-26T16:32:24.971+0000] {logging_mixin.py:137} INFO - [2024-01-26T16:32:24.963+0000] {dagbag.py:343} ERROR - Failed to import: /opt/airflow/dags/etl_scripts/etl_atendimentos_dl.py
Traceback (most recent call last):
  File "/home/airflow/.local/lib/python3.7/site-packages/airflow/models/dagbag.py", line 339, in parse
    loader.exec_module(new_module)
  File "<frozen importlib._bootstrap_external>", line 728, in exec_module
  File "<frozen importlib._bootstrap>", line 219, in _call_with_frames_removed
  File "/opt/airflow/dags/etl_scripts/etl_atendimentos_dl.py", line 18, in <module>
    usuario = config.get('Database', 'user')
  File "/usr/local/lib/python3.7/configparser.py", line 780, in get
    d = self._unify_values(section, vars)
  File "/usr/local/lib/python3.7/configparser.py", line 1146, in _unify_values
    raise NoSectionError(section) from None
configparser.NoSectionError: No section: 'Database'
[2024-01-26T16:32:24.971+0000] {processor.py:755} WARNING - No viable dags retrieved from /opt/airflow/dags/etl_scripts/etl_atendimentos_dl.py
[2024-01-26T16:32:24.995+0000] {processor.py:175} INFO - Processing /opt/airflow/dags/etl_scripts/etl_atendimentos_dl.py took 0.340 seconds
[2024-01-26T16:32:55.032+0000] {processor.py:153} INFO - Started process (PID=17337) to work on /opt/airflow/dags/etl_scripts/etl_atendimentos_dl.py
[2024-01-26T16:32:55.033+0000] {processor.py:743} INFO - Processing file /opt/airflow/dags/etl_scripts/etl_atendimentos_dl.py for tasks to queue
[2024-01-26T16:32:55.034+0000] {logging_mixin.py:137} INFO - [2024-01-26T16:32:55.034+0000] {dagbag.py:538} INFO - Filling up the DagBag from /opt/airflow/dags/etl_scripts/etl_atendimentos_dl.py
[2024-01-26T16:32:55.318+0000] {logging_mixin.py:137} INFO - [2024-01-26T16:32:55.312+0000] {dagbag.py:343} ERROR - Failed to import: /opt/airflow/dags/etl_scripts/etl_atendimentos_dl.py
Traceback (most recent call last):
  File "/home/airflow/.local/lib/python3.7/site-packages/airflow/models/dagbag.py", line 339, in parse
    loader.exec_module(new_module)
  File "<frozen importlib._bootstrap_external>", line 728, in exec_module
  File "<frozen importlib._bootstrap>", line 219, in _call_with_frames_removed
  File "/opt/airflow/dags/etl_scripts/etl_atendimentos_dl.py", line 18, in <module>
    usuario = config.get('Database', 'user')
  File "/usr/local/lib/python3.7/configparser.py", line 780, in get
    d = self._unify_values(section, vars)
  File "/usr/local/lib/python3.7/configparser.py", line 1146, in _unify_values
    raise NoSectionError(section) from None
configparser.NoSectionError: No section: 'Database'
[2024-01-26T16:32:55.319+0000] {processor.py:755} WARNING - No viable dags retrieved from /opt/airflow/dags/etl_scripts/etl_atendimentos_dl.py
[2024-01-26T16:32:55.342+0000] {processor.py:175} INFO - Processing /opt/airflow/dags/etl_scripts/etl_atendimentos_dl.py took 0.314 seconds
[2024-01-26T16:33:25.453+0000] {processor.py:153} INFO - Started process (PID=17388) to work on /opt/airflow/dags/etl_scripts/etl_atendimentos_dl.py
[2024-01-26T16:33:25.454+0000] {processor.py:743} INFO - Processing file /opt/airflow/dags/etl_scripts/etl_atendimentos_dl.py for tasks to queue
[2024-01-26T16:33:25.455+0000] {logging_mixin.py:137} INFO - [2024-01-26T16:33:25.455+0000] {dagbag.py:538} INFO - Filling up the DagBag from /opt/airflow/dags/etl_scripts/etl_atendimentos_dl.py
[2024-01-26T16:33:25.826+0000] {logging_mixin.py:137} INFO - [2024-01-26T16:33:25.818+0000] {dagbag.py:343} ERROR - Failed to import: /opt/airflow/dags/etl_scripts/etl_atendimentos_dl.py
Traceback (most recent call last):
  File "/home/airflow/.local/lib/python3.7/site-packages/airflow/models/dagbag.py", line 339, in parse
    loader.exec_module(new_module)
  File "<frozen importlib._bootstrap_external>", line 728, in exec_module
  File "<frozen importlib._bootstrap>", line 219, in _call_with_frames_removed
  File "/opt/airflow/dags/etl_scripts/etl_atendimentos_dl.py", line 18, in <module>
    usuario = config.get('Database', 'user')
  File "/usr/local/lib/python3.7/configparser.py", line 780, in get
    d = self._unify_values(section, vars)
  File "/usr/local/lib/python3.7/configparser.py", line 1146, in _unify_values
    raise NoSectionError(section) from None
configparser.NoSectionError: No section: 'Database'
[2024-01-26T16:33:25.827+0000] {processor.py:755} WARNING - No viable dags retrieved from /opt/airflow/dags/etl_scripts/etl_atendimentos_dl.py
[2024-01-26T16:33:25.853+0000] {processor.py:175} INFO - Processing /opt/airflow/dags/etl_scripts/etl_atendimentos_dl.py took 0.405 seconds
[2024-01-26T16:33:56.713+0000] {processor.py:153} INFO - Started process (PID=17423) to work on /opt/airflow/dags/etl_scripts/etl_atendimentos_dl.py
[2024-01-26T16:33:56.714+0000] {processor.py:743} INFO - Processing file /opt/airflow/dags/etl_scripts/etl_atendimentos_dl.py for tasks to queue
[2024-01-26T16:33:56.715+0000] {logging_mixin.py:137} INFO - [2024-01-26T16:33:56.715+0000] {dagbag.py:538} INFO - Filling up the DagBag from /opt/airflow/dags/etl_scripts/etl_atendimentos_dl.py
[2024-01-26T16:33:56.991+0000] {logging_mixin.py:137} INFO - [2024-01-26T16:33:56.983+0000] {dagbag.py:343} ERROR - Failed to import: /opt/airflow/dags/etl_scripts/etl_atendimentos_dl.py
Traceback (most recent call last):
  File "/home/airflow/.local/lib/python3.7/site-packages/airflow/models/dagbag.py", line 339, in parse
    loader.exec_module(new_module)
  File "<frozen importlib._bootstrap_external>", line 728, in exec_module
  File "<frozen importlib._bootstrap>", line 219, in _call_with_frames_removed
  File "/opt/airflow/dags/etl_scripts/etl_atendimentos_dl.py", line 18, in <module>
    usuario = config.get('Database', 'user')
  File "/usr/local/lib/python3.7/configparser.py", line 780, in get
    d = self._unify_values(section, vars)
  File "/usr/local/lib/python3.7/configparser.py", line 1146, in _unify_values
    raise NoSectionError(section) from None
configparser.NoSectionError: No section: 'Database'
[2024-01-26T16:33:56.991+0000] {processor.py:755} WARNING - No viable dags retrieved from /opt/airflow/dags/etl_scripts/etl_atendimentos_dl.py
[2024-01-26T16:33:57.011+0000] {processor.py:175} INFO - Processing /opt/airflow/dags/etl_scripts/etl_atendimentos_dl.py took 0.302 seconds
[2024-01-26T16:34:27.336+0000] {processor.py:153} INFO - Started process (PID=17458) to work on /opt/airflow/dags/etl_scripts/etl_atendimentos_dl.py
[2024-01-26T16:34:27.337+0000] {processor.py:743} INFO - Processing file /opt/airflow/dags/etl_scripts/etl_atendimentos_dl.py for tasks to queue
[2024-01-26T16:34:27.339+0000] {logging_mixin.py:137} INFO - [2024-01-26T16:34:27.338+0000] {dagbag.py:538} INFO - Filling up the DagBag from /opt/airflow/dags/etl_scripts/etl_atendimentos_dl.py
[2024-01-26T16:34:27.696+0000] {logging_mixin.py:137} INFO - [2024-01-26T16:34:27.689+0000] {dagbag.py:343} ERROR - Failed to import: /opt/airflow/dags/etl_scripts/etl_atendimentos_dl.py
Traceback (most recent call last):
  File "/home/airflow/.local/lib/python3.7/site-packages/airflow/models/dagbag.py", line 339, in parse
    loader.exec_module(new_module)
  File "<frozen importlib._bootstrap_external>", line 728, in exec_module
  File "<frozen importlib._bootstrap>", line 219, in _call_with_frames_removed
  File "/opt/airflow/dags/etl_scripts/etl_atendimentos_dl.py", line 18, in <module>
    usuario = config.get('Database', 'user')
  File "/usr/local/lib/python3.7/configparser.py", line 780, in get
    d = self._unify_values(section, vars)
  File "/usr/local/lib/python3.7/configparser.py", line 1146, in _unify_values
    raise NoSectionError(section) from None
configparser.NoSectionError: No section: 'Database'
[2024-01-26T16:34:27.697+0000] {processor.py:755} WARNING - No viable dags retrieved from /opt/airflow/dags/etl_scripts/etl_atendimentos_dl.py
[2024-01-26T16:34:27.728+0000] {processor.py:175} INFO - Processing /opt/airflow/dags/etl_scripts/etl_atendimentos_dl.py took 0.395 seconds
[2024-01-26T16:34:58.111+0000] {processor.py:153} INFO - Started process (PID=17509) to work on /opt/airflow/dags/etl_scripts/etl_atendimentos_dl.py
[2024-01-26T16:34:58.112+0000] {processor.py:743} INFO - Processing file /opt/airflow/dags/etl_scripts/etl_atendimentos_dl.py for tasks to queue
[2024-01-26T16:34:58.114+0000] {logging_mixin.py:137} INFO - [2024-01-26T16:34:58.114+0000] {dagbag.py:538} INFO - Filling up the DagBag from /opt/airflow/dags/etl_scripts/etl_atendimentos_dl.py
[2024-01-26T16:34:58.425+0000] {logging_mixin.py:137} INFO - [2024-01-26T16:34:58.418+0000] {dagbag.py:343} ERROR - Failed to import: /opt/airflow/dags/etl_scripts/etl_atendimentos_dl.py
Traceback (most recent call last):
  File "/home/airflow/.local/lib/python3.7/site-packages/airflow/models/dagbag.py", line 339, in parse
    loader.exec_module(new_module)
  File "<frozen importlib._bootstrap_external>", line 728, in exec_module
  File "<frozen importlib._bootstrap>", line 219, in _call_with_frames_removed
  File "/opt/airflow/dags/etl_scripts/etl_atendimentos_dl.py", line 18, in <module>
    usuario = config.get('Database', 'user')
  File "/usr/local/lib/python3.7/configparser.py", line 780, in get
    d = self._unify_values(section, vars)
  File "/usr/local/lib/python3.7/configparser.py", line 1146, in _unify_values
    raise NoSectionError(section) from None
configparser.NoSectionError: No section: 'Database'
[2024-01-26T16:34:58.426+0000] {processor.py:755} WARNING - No viable dags retrieved from /opt/airflow/dags/etl_scripts/etl_atendimentos_dl.py
[2024-01-26T16:34:58.470+0000] {processor.py:175} INFO - Processing /opt/airflow/dags/etl_scripts/etl_atendimentos_dl.py took 0.361 seconds
[2024-01-26T16:35:28.707+0000] {processor.py:153} INFO - Started process (PID=17544) to work on /opt/airflow/dags/etl_scripts/etl_atendimentos_dl.py
[2024-01-26T16:35:28.710+0000] {processor.py:743} INFO - Processing file /opt/airflow/dags/etl_scripts/etl_atendimentos_dl.py for tasks to queue
[2024-01-26T16:35:28.713+0000] {logging_mixin.py:137} INFO - [2024-01-26T16:35:28.713+0000] {dagbag.py:538} INFO - Filling up the DagBag from /opt/airflow/dags/etl_scripts/etl_atendimentos_dl.py
[2024-01-26T16:35:29.426+0000] {logging_mixin.py:137} INFO - [2024-01-26T16:35:29.417+0000] {dagbag.py:343} ERROR - Failed to import: /opt/airflow/dags/etl_scripts/etl_atendimentos_dl.py
Traceback (most recent call last):
  File "/home/airflow/.local/lib/python3.7/site-packages/airflow/models/dagbag.py", line 339, in parse
    loader.exec_module(new_module)
  File "<frozen importlib._bootstrap_external>", line 728, in exec_module
  File "<frozen importlib._bootstrap>", line 219, in _call_with_frames_removed
  File "/opt/airflow/dags/etl_scripts/etl_atendimentos_dl.py", line 18, in <module>
    usuario = config.get('Database', 'user')
  File "/usr/local/lib/python3.7/configparser.py", line 780, in get
    d = self._unify_values(section, vars)
  File "/usr/local/lib/python3.7/configparser.py", line 1146, in _unify_values
    raise NoSectionError(section) from None
configparser.NoSectionError: No section: 'Database'
[2024-01-26T16:35:29.427+0000] {processor.py:755} WARNING - No viable dags retrieved from /opt/airflow/dags/etl_scripts/etl_atendimentos_dl.py
[2024-01-26T16:35:29.459+0000] {processor.py:175} INFO - Processing /opt/airflow/dags/etl_scripts/etl_atendimentos_dl.py took 0.769 seconds
[2024-01-26T16:35:59.773+0000] {processor.py:153} INFO - Started process (PID=17579) to work on /opt/airflow/dags/etl_scripts/etl_atendimentos_dl.py
[2024-01-26T16:35:59.774+0000] {processor.py:743} INFO - Processing file /opt/airflow/dags/etl_scripts/etl_atendimentos_dl.py for tasks to queue
[2024-01-26T16:35:59.775+0000] {logging_mixin.py:137} INFO - [2024-01-26T16:35:59.775+0000] {dagbag.py:538} INFO - Filling up the DagBag from /opt/airflow/dags/etl_scripts/etl_atendimentos_dl.py
[2024-01-26T16:36:00.079+0000] {logging_mixin.py:137} INFO - [2024-01-26T16:36:00.071+0000] {dagbag.py:343} ERROR - Failed to import: /opt/airflow/dags/etl_scripts/etl_atendimentos_dl.py
Traceback (most recent call last):
  File "/home/airflow/.local/lib/python3.7/site-packages/airflow/models/dagbag.py", line 339, in parse
    loader.exec_module(new_module)
  File "<frozen importlib._bootstrap_external>", line 728, in exec_module
  File "<frozen importlib._bootstrap>", line 219, in _call_with_frames_removed
  File "/opt/airflow/dags/etl_scripts/etl_atendimentos_dl.py", line 18, in <module>
    usuario = config.get('Database', 'user')
  File "/usr/local/lib/python3.7/configparser.py", line 780, in get
    d = self._unify_values(section, vars)
  File "/usr/local/lib/python3.7/configparser.py", line 1146, in _unify_values
    raise NoSectionError(section) from None
configparser.NoSectionError: No section: 'Database'
[2024-01-26T16:36:00.080+0000] {processor.py:755} WARNING - No viable dags retrieved from /opt/airflow/dags/etl_scripts/etl_atendimentos_dl.py
[2024-01-26T16:36:00.105+0000] {processor.py:175} INFO - Processing /opt/airflow/dags/etl_scripts/etl_atendimentos_dl.py took 0.337 seconds
[2024-01-26T16:36:30.386+0000] {processor.py:153} INFO - Started process (PID=17623) to work on /opt/airflow/dags/etl_scripts/etl_atendimentos_dl.py
[2024-01-26T16:36:30.387+0000] {processor.py:743} INFO - Processing file /opt/airflow/dags/etl_scripts/etl_atendimentos_dl.py for tasks to queue
[2024-01-26T16:36:30.389+0000] {logging_mixin.py:137} INFO - [2024-01-26T16:36:30.388+0000] {dagbag.py:538} INFO - Filling up the DagBag from /opt/airflow/dags/etl_scripts/etl_atendimentos_dl.py
[2024-01-26T16:36:30.791+0000] {logging_mixin.py:137} INFO - [2024-01-26T16:36:30.782+0000] {dagbag.py:343} ERROR - Failed to import: /opt/airflow/dags/etl_scripts/etl_atendimentos_dl.py
Traceback (most recent call last):
  File "/home/airflow/.local/lib/python3.7/site-packages/airflow/models/dagbag.py", line 339, in parse
    loader.exec_module(new_module)
  File "<frozen importlib._bootstrap_external>", line 728, in exec_module
  File "<frozen importlib._bootstrap>", line 219, in _call_with_frames_removed
  File "/opt/airflow/dags/etl_scripts/etl_atendimentos_dl.py", line 18, in <module>
    usuario = config.get('Database', 'user')
  File "/usr/local/lib/python3.7/configparser.py", line 780, in get
    d = self._unify_values(section, vars)
  File "/usr/local/lib/python3.7/configparser.py", line 1146, in _unify_values
    raise NoSectionError(section) from None
configparser.NoSectionError: No section: 'Database'
[2024-01-26T16:36:30.792+0000] {processor.py:755} WARNING - No viable dags retrieved from /opt/airflow/dags/etl_scripts/etl_atendimentos_dl.py
[2024-01-26T16:36:30.818+0000] {processor.py:175} INFO - Processing /opt/airflow/dags/etl_scripts/etl_atendimentos_dl.py took 0.436 seconds
[2024-01-26T16:37:01.725+0000] {processor.py:153} INFO - Started process (PID=17665) to work on /opt/airflow/dags/etl_scripts/etl_atendimentos_dl.py
[2024-01-26T16:37:01.727+0000] {processor.py:743} INFO - Processing file /opt/airflow/dags/etl_scripts/etl_atendimentos_dl.py for tasks to queue
[2024-01-26T16:37:01.728+0000] {logging_mixin.py:137} INFO - [2024-01-26T16:37:01.728+0000] {dagbag.py:538} INFO - Filling up the DagBag from /opt/airflow/dags/etl_scripts/etl_atendimentos_dl.py
[2024-01-26T16:37:02.005+0000] {logging_mixin.py:137} INFO - [2024-01-26T16:37:01.997+0000] {dagbag.py:343} ERROR - Failed to import: /opt/airflow/dags/etl_scripts/etl_atendimentos_dl.py
Traceback (most recent call last):
  File "/home/airflow/.local/lib/python3.7/site-packages/airflow/models/dagbag.py", line 339, in parse
    loader.exec_module(new_module)
  File "<frozen importlib._bootstrap_external>", line 728, in exec_module
  File "<frozen importlib._bootstrap>", line 219, in _call_with_frames_removed
  File "/opt/airflow/dags/etl_scripts/etl_atendimentos_dl.py", line 18, in <module>
    usuario = config.get('Database', 'user')
  File "/usr/local/lib/python3.7/configparser.py", line 780, in get
    d = self._unify_values(section, vars)
  File "/usr/local/lib/python3.7/configparser.py", line 1146, in _unify_values
    raise NoSectionError(section) from None
configparser.NoSectionError: No section: 'Database'
[2024-01-26T16:37:02.006+0000] {processor.py:755} WARNING - No viable dags retrieved from /opt/airflow/dags/etl_scripts/etl_atendimentos_dl.py
[2024-01-26T16:37:02.027+0000] {processor.py:175} INFO - Processing /opt/airflow/dags/etl_scripts/etl_atendimentos_dl.py took 0.305 seconds
[2024-01-26T16:37:32.098+0000] {processor.py:153} INFO - Started process (PID=17700) to work on /opt/airflow/dags/etl_scripts/etl_atendimentos_dl.py
[2024-01-26T16:37:32.100+0000] {processor.py:743} INFO - Processing file /opt/airflow/dags/etl_scripts/etl_atendimentos_dl.py for tasks to queue
[2024-01-26T16:37:32.101+0000] {logging_mixin.py:137} INFO - [2024-01-26T16:37:32.101+0000] {dagbag.py:538} INFO - Filling up the DagBag from /opt/airflow/dags/etl_scripts/etl_atendimentos_dl.py
[2024-01-26T16:37:32.399+0000] {logging_mixin.py:137} INFO - [2024-01-26T16:37:32.391+0000] {dagbag.py:343} ERROR - Failed to import: /opt/airflow/dags/etl_scripts/etl_atendimentos_dl.py
Traceback (most recent call last):
  File "/home/airflow/.local/lib/python3.7/site-packages/airflow/models/dagbag.py", line 339, in parse
    loader.exec_module(new_module)
  File "<frozen importlib._bootstrap_external>", line 728, in exec_module
  File "<frozen importlib._bootstrap>", line 219, in _call_with_frames_removed
  File "/opt/airflow/dags/etl_scripts/etl_atendimentos_dl.py", line 18, in <module>
    usuario = config.get('Database', 'user')
  File "/usr/local/lib/python3.7/configparser.py", line 780, in get
    d = self._unify_values(section, vars)
  File "/usr/local/lib/python3.7/configparser.py", line 1146, in _unify_values
    raise NoSectionError(section) from None
configparser.NoSectionError: No section: 'Database'
[2024-01-26T16:37:32.401+0000] {processor.py:755} WARNING - No viable dags retrieved from /opt/airflow/dags/etl_scripts/etl_atendimentos_dl.py
[2024-01-26T16:37:32.422+0000] {processor.py:175} INFO - Processing /opt/airflow/dags/etl_scripts/etl_atendimentos_dl.py took 0.327 seconds
[2024-01-26T16:38:02.711+0000] {processor.py:153} INFO - Started process (PID=17751) to work on /opt/airflow/dags/etl_scripts/etl_atendimentos_dl.py
[2024-01-26T16:38:02.712+0000] {processor.py:743} INFO - Processing file /opt/airflow/dags/etl_scripts/etl_atendimentos_dl.py for tasks to queue
[2024-01-26T16:38:02.714+0000] {logging_mixin.py:137} INFO - [2024-01-26T16:38:02.713+0000] {dagbag.py:538} INFO - Filling up the DagBag from /opt/airflow/dags/etl_scripts/etl_atendimentos_dl.py
[2024-01-26T16:38:03.093+0000] {logging_mixin.py:137} INFO - [2024-01-26T16:38:03.085+0000] {dagbag.py:343} ERROR - Failed to import: /opt/airflow/dags/etl_scripts/etl_atendimentos_dl.py
Traceback (most recent call last):
  File "/home/airflow/.local/lib/python3.7/site-packages/airflow/models/dagbag.py", line 339, in parse
    loader.exec_module(new_module)
  File "<frozen importlib._bootstrap_external>", line 728, in exec_module
  File "<frozen importlib._bootstrap>", line 219, in _call_with_frames_removed
  File "/opt/airflow/dags/etl_scripts/etl_atendimentos_dl.py", line 18, in <module>
    usuario = config.get('Database', 'user')
  File "/usr/local/lib/python3.7/configparser.py", line 780, in get
    d = self._unify_values(section, vars)
  File "/usr/local/lib/python3.7/configparser.py", line 1146, in _unify_values
    raise NoSectionError(section) from None
configparser.NoSectionError: No section: 'Database'
[2024-01-26T16:38:03.094+0000] {processor.py:755} WARNING - No viable dags retrieved from /opt/airflow/dags/etl_scripts/etl_atendimentos_dl.py
[2024-01-26T16:38:03.114+0000] {processor.py:175} INFO - Processing /opt/airflow/dags/etl_scripts/etl_atendimentos_dl.py took 0.407 seconds
[2024-01-26T16:38:33.305+0000] {processor.py:153} INFO - Started process (PID=17786) to work on /opt/airflow/dags/etl_scripts/etl_atendimentos_dl.py
[2024-01-26T16:38:33.306+0000] {processor.py:743} INFO - Processing file /opt/airflow/dags/etl_scripts/etl_atendimentos_dl.py for tasks to queue
[2024-01-26T16:38:33.307+0000] {logging_mixin.py:137} INFO - [2024-01-26T16:38:33.307+0000] {dagbag.py:538} INFO - Filling up the DagBag from /opt/airflow/dags/etl_scripts/etl_atendimentos_dl.py
[2024-01-26T16:38:33.574+0000] {logging_mixin.py:137} INFO - [2024-01-26T16:38:33.566+0000] {dagbag.py:343} ERROR - Failed to import: /opt/airflow/dags/etl_scripts/etl_atendimentos_dl.py
Traceback (most recent call last):
  File "/home/airflow/.local/lib/python3.7/site-packages/airflow/models/dagbag.py", line 339, in parse
    loader.exec_module(new_module)
  File "<frozen importlib._bootstrap_external>", line 728, in exec_module
  File "<frozen importlib._bootstrap>", line 219, in _call_with_frames_removed
  File "/opt/airflow/dags/etl_scripts/etl_atendimentos_dl.py", line 18, in <module>
    usuario = config.get('Database', 'user')
  File "/usr/local/lib/python3.7/configparser.py", line 780, in get
    d = self._unify_values(section, vars)
  File "/usr/local/lib/python3.7/configparser.py", line 1146, in _unify_values
    raise NoSectionError(section) from None
configparser.NoSectionError: No section: 'Database'
[2024-01-26T16:38:33.575+0000] {processor.py:755} WARNING - No viable dags retrieved from /opt/airflow/dags/etl_scripts/etl_atendimentos_dl.py
[2024-01-26T16:38:33.597+0000] {processor.py:175} INFO - Processing /opt/airflow/dags/etl_scripts/etl_atendimentos_dl.py took 0.295 seconds
[2024-01-26T16:39:03.734+0000] {processor.py:153} INFO - Started process (PID=17821) to work on /opt/airflow/dags/etl_scripts/etl_atendimentos_dl.py
[2024-01-26T16:39:03.735+0000] {processor.py:743} INFO - Processing file /opt/airflow/dags/etl_scripts/etl_atendimentos_dl.py for tasks to queue
[2024-01-26T16:39:03.736+0000] {logging_mixin.py:137} INFO - [2024-01-26T16:39:03.736+0000] {dagbag.py:538} INFO - Filling up the DagBag from /opt/airflow/dags/etl_scripts/etl_atendimentos_dl.py
[2024-01-26T16:39:04.020+0000] {logging_mixin.py:137} INFO - [2024-01-26T16:39:04.011+0000] {dagbag.py:343} ERROR - Failed to import: /opt/airflow/dags/etl_scripts/etl_atendimentos_dl.py
Traceback (most recent call last):
  File "/home/airflow/.local/lib/python3.7/site-packages/airflow/models/dagbag.py", line 339, in parse
    loader.exec_module(new_module)
  File "<frozen importlib._bootstrap_external>", line 728, in exec_module
  File "<frozen importlib._bootstrap>", line 219, in _call_with_frames_removed
  File "/opt/airflow/dags/etl_scripts/etl_atendimentos_dl.py", line 18, in <module>
    usuario = config.get('Database', 'user')
  File "/usr/local/lib/python3.7/configparser.py", line 780, in get
    d = self._unify_values(section, vars)
  File "/usr/local/lib/python3.7/configparser.py", line 1146, in _unify_values
    raise NoSectionError(section) from None
configparser.NoSectionError: No section: 'Database'
[2024-01-26T16:39:04.021+0000] {processor.py:755} WARNING - No viable dags retrieved from /opt/airflow/dags/etl_scripts/etl_atendimentos_dl.py
[2024-01-26T16:39:04.044+0000] {processor.py:175} INFO - Processing /opt/airflow/dags/etl_scripts/etl_atendimentos_dl.py took 0.313 seconds
[2024-01-26T16:39:34.102+0000] {processor.py:153} INFO - Started process (PID=17872) to work on /opt/airflow/dags/etl_scripts/etl_atendimentos_dl.py
[2024-01-26T16:39:34.103+0000] {processor.py:743} INFO - Processing file /opt/airflow/dags/etl_scripts/etl_atendimentos_dl.py for tasks to queue
[2024-01-26T16:39:34.104+0000] {logging_mixin.py:137} INFO - [2024-01-26T16:39:34.104+0000] {dagbag.py:538} INFO - Filling up the DagBag from /opt/airflow/dags/etl_scripts/etl_atendimentos_dl.py
[2024-01-26T16:39:34.547+0000] {logging_mixin.py:137} INFO - [2024-01-26T16:39:34.537+0000] {dagbag.py:343} ERROR - Failed to import: /opt/airflow/dags/etl_scripts/etl_atendimentos_dl.py
Traceback (most recent call last):
  File "/home/airflow/.local/lib/python3.7/site-packages/airflow/models/dagbag.py", line 339, in parse
    loader.exec_module(new_module)
  File "<frozen importlib._bootstrap_external>", line 728, in exec_module
  File "<frozen importlib._bootstrap>", line 219, in _call_with_frames_removed
  File "/opt/airflow/dags/etl_scripts/etl_atendimentos_dl.py", line 18, in <module>
    usuario = config.get('Database', 'user')
  File "/usr/local/lib/python3.7/configparser.py", line 780, in get
    d = self._unify_values(section, vars)
  File "/usr/local/lib/python3.7/configparser.py", line 1146, in _unify_values
    raise NoSectionError(section) from None
configparser.NoSectionError: No section: 'Database'
[2024-01-26T16:39:34.548+0000] {processor.py:755} WARNING - No viable dags retrieved from /opt/airflow/dags/etl_scripts/etl_atendimentos_dl.py
[2024-01-26T16:39:34.577+0000] {processor.py:175} INFO - Processing /opt/airflow/dags/etl_scripts/etl_atendimentos_dl.py took 0.477 seconds
[2024-01-26T16:40:05.458+0000] {processor.py:153} INFO - Started process (PID=17907) to work on /opt/airflow/dags/etl_scripts/etl_atendimentos_dl.py
[2024-01-26T16:40:05.459+0000] {processor.py:743} INFO - Processing file /opt/airflow/dags/etl_scripts/etl_atendimentos_dl.py for tasks to queue
[2024-01-26T16:40:05.460+0000] {logging_mixin.py:137} INFO - [2024-01-26T16:40:05.460+0000] {dagbag.py:538} INFO - Filling up the DagBag from /opt/airflow/dags/etl_scripts/etl_atendimentos_dl.py
[2024-01-26T16:40:05.723+0000] {logging_mixin.py:137} INFO - [2024-01-26T16:40:05.717+0000] {dagbag.py:343} ERROR - Failed to import: /opt/airflow/dags/etl_scripts/etl_atendimentos_dl.py
Traceback (most recent call last):
  File "/home/airflow/.local/lib/python3.7/site-packages/airflow/models/dagbag.py", line 339, in parse
    loader.exec_module(new_module)
  File "<frozen importlib._bootstrap_external>", line 728, in exec_module
  File "<frozen importlib._bootstrap>", line 219, in _call_with_frames_removed
  File "/opt/airflow/dags/etl_scripts/etl_atendimentos_dl.py", line 18, in <module>
    usuario = config.get('Database', 'user')
  File "/usr/local/lib/python3.7/configparser.py", line 780, in get
    d = self._unify_values(section, vars)
  File "/usr/local/lib/python3.7/configparser.py", line 1146, in _unify_values
    raise NoSectionError(section) from None
configparser.NoSectionError: No section: 'Database'
[2024-01-26T16:40:05.724+0000] {processor.py:755} WARNING - No viable dags retrieved from /opt/airflow/dags/etl_scripts/etl_atendimentos_dl.py
[2024-01-26T16:40:05.743+0000] {processor.py:175} INFO - Processing /opt/airflow/dags/etl_scripts/etl_atendimentos_dl.py took 0.289 seconds
[2024-01-26T16:40:35.888+0000] {processor.py:153} INFO - Started process (PID=17942) to work on /opt/airflow/dags/etl_scripts/etl_atendimentos_dl.py
[2024-01-26T16:40:35.889+0000] {processor.py:743} INFO - Processing file /opt/airflow/dags/etl_scripts/etl_atendimentos_dl.py for tasks to queue
[2024-01-26T16:40:35.890+0000] {logging_mixin.py:137} INFO - [2024-01-26T16:40:35.890+0000] {dagbag.py:538} INFO - Filling up the DagBag from /opt/airflow/dags/etl_scripts/etl_atendimentos_dl.py
[2024-01-26T16:40:36.216+0000] {logging_mixin.py:137} INFO - [2024-01-26T16:40:36.208+0000] {dagbag.py:343} ERROR - Failed to import: /opt/airflow/dags/etl_scripts/etl_atendimentos_dl.py
Traceback (most recent call last):
  File "/home/airflow/.local/lib/python3.7/site-packages/airflow/models/dagbag.py", line 339, in parse
    loader.exec_module(new_module)
  File "<frozen importlib._bootstrap_external>", line 728, in exec_module
  File "<frozen importlib._bootstrap>", line 219, in _call_with_frames_removed
  File "/opt/airflow/dags/etl_scripts/etl_atendimentos_dl.py", line 18, in <module>
    usuario = config.get('Database', 'user')
  File "/usr/local/lib/python3.7/configparser.py", line 780, in get
    d = self._unify_values(section, vars)
  File "/usr/local/lib/python3.7/configparser.py", line 1146, in _unify_values
    raise NoSectionError(section) from None
configparser.NoSectionError: No section: 'Database'
[2024-01-26T16:40:36.217+0000] {processor.py:755} WARNING - No viable dags retrieved from /opt/airflow/dags/etl_scripts/etl_atendimentos_dl.py
[2024-01-26T16:40:36.241+0000] {processor.py:175} INFO - Processing /opt/airflow/dags/etl_scripts/etl_atendimentos_dl.py took 0.356 seconds
[2024-01-26T16:41:06.410+0000] {processor.py:153} INFO - Started process (PID=17987) to work on /opt/airflow/dags/etl_scripts/etl_atendimentos_dl.py
[2024-01-26T16:41:06.412+0000] {processor.py:743} INFO - Processing file /opt/airflow/dags/etl_scripts/etl_atendimentos_dl.py for tasks to queue
[2024-01-26T16:41:06.413+0000] {logging_mixin.py:137} INFO - [2024-01-26T16:41:06.413+0000] {dagbag.py:538} INFO - Filling up the DagBag from /opt/airflow/dags/etl_scripts/etl_atendimentos_dl.py
[2024-01-26T16:41:06.726+0000] {logging_mixin.py:137} INFO - [2024-01-26T16:41:06.718+0000] {dagbag.py:343} ERROR - Failed to import: /opt/airflow/dags/etl_scripts/etl_atendimentos_dl.py
Traceback (most recent call last):
  File "/home/airflow/.local/lib/python3.7/site-packages/airflow/models/dagbag.py", line 339, in parse
    loader.exec_module(new_module)
  File "<frozen importlib._bootstrap_external>", line 728, in exec_module
  File "<frozen importlib._bootstrap>", line 219, in _call_with_frames_removed
  File "/opt/airflow/dags/etl_scripts/etl_atendimentos_dl.py", line 18, in <module>
    usuario = config.get('Database', 'user')
  File "/usr/local/lib/python3.7/configparser.py", line 780, in get
    d = self._unify_values(section, vars)
  File "/usr/local/lib/python3.7/configparser.py", line 1146, in _unify_values
    raise NoSectionError(section) from None
configparser.NoSectionError: No section: 'Database'
[2024-01-26T16:41:06.727+0000] {processor.py:755} WARNING - No viable dags retrieved from /opt/airflow/dags/etl_scripts/etl_atendimentos_dl.py
[2024-01-26T16:41:06.751+0000] {processor.py:175} INFO - Processing /opt/airflow/dags/etl_scripts/etl_atendimentos_dl.py took 0.343 seconds
[2024-01-26T16:41:36.680+0000] {processor.py:153} INFO - Started process (PID=18029) to work on /opt/airflow/dags/etl_scripts/etl_atendimentos_dl.py
[2024-01-26T16:41:36.681+0000] {processor.py:743} INFO - Processing file /opt/airflow/dags/etl_scripts/etl_atendimentos_dl.py for tasks to queue
[2024-01-26T16:41:36.682+0000] {logging_mixin.py:137} INFO - [2024-01-26T16:41:36.682+0000] {dagbag.py:538} INFO - Filling up the DagBag from /opt/airflow/dags/etl_scripts/etl_atendimentos_dl.py
[2024-01-26T16:41:36.706+0000] {logging_mixin.py:137} INFO - [2024-01-26T16:41:36.706+0000] {dagbag.py:320} INFO - File /opt/airflow/dags/etl_scripts/etl_atendimentos_dl.py assumed to contain no DAGs. Skipping.
[2024-01-26T16:41:36.706+0000] {processor.py:755} WARNING - No viable dags retrieved from /opt/airflow/dags/etl_scripts/etl_atendimentos_dl.py
[2024-01-26T16:41:36.724+0000] {processor.py:175} INFO - Processing /opt/airflow/dags/etl_scripts/etl_atendimentos_dl.py took 0.047 seconds
[2024-01-26T16:42:07.051+0000] {processor.py:153} INFO - Started process (PID=18063) to work on /opt/airflow/dags/etl_scripts/etl_atendimentos_dl.py
[2024-01-26T16:42:07.052+0000] {processor.py:743} INFO - Processing file /opt/airflow/dags/etl_scripts/etl_atendimentos_dl.py for tasks to queue
[2024-01-26T16:42:07.053+0000] {logging_mixin.py:137} INFO - [2024-01-26T16:42:07.053+0000] {dagbag.py:538} INFO - Filling up the DagBag from /opt/airflow/dags/etl_scripts/etl_atendimentos_dl.py
[2024-01-26T16:42:07.068+0000] {logging_mixin.py:137} INFO - [2024-01-26T16:42:07.068+0000] {dagbag.py:320} INFO - File /opt/airflow/dags/etl_scripts/etl_atendimentos_dl.py assumed to contain no DAGs. Skipping.
[2024-01-26T16:42:07.069+0000] {processor.py:755} WARNING - No viable dags retrieved from /opt/airflow/dags/etl_scripts/etl_atendimentos_dl.py
[2024-01-26T16:42:07.086+0000] {processor.py:175} INFO - Processing /opt/airflow/dags/etl_scripts/etl_atendimentos_dl.py took 0.038 seconds
[2024-01-26T16:42:37.382+0000] {processor.py:153} INFO - Started process (PID=18106) to work on /opt/airflow/dags/etl_scripts/etl_atendimentos_dl.py
[2024-01-26T16:42:37.383+0000] {processor.py:743} INFO - Processing file /opt/airflow/dags/etl_scripts/etl_atendimentos_dl.py for tasks to queue
[2024-01-26T16:42:37.385+0000] {logging_mixin.py:137} INFO - [2024-01-26T16:42:37.384+0000] {dagbag.py:538} INFO - Filling up the DagBag from /opt/airflow/dags/etl_scripts/etl_atendimentos_dl.py
[2024-01-26T16:42:37.395+0000] {logging_mixin.py:137} INFO - [2024-01-26T16:42:37.395+0000] {dagbag.py:320} INFO - File /opt/airflow/dags/etl_scripts/etl_atendimentos_dl.py assumed to contain no DAGs. Skipping.
[2024-01-26T16:42:37.396+0000] {processor.py:755} WARNING - No viable dags retrieved from /opt/airflow/dags/etl_scripts/etl_atendimentos_dl.py
[2024-01-26T16:42:37.411+0000] {processor.py:175} INFO - Processing /opt/airflow/dags/etl_scripts/etl_atendimentos_dl.py took 0.032 seconds
[2024-01-26T16:43:07.699+0000] {processor.py:153} INFO - Started process (PID=18147) to work on /opt/airflow/dags/etl_scripts/etl_atendimentos_dl.py
[2024-01-26T16:43:07.700+0000] {processor.py:743} INFO - Processing file /opt/airflow/dags/etl_scripts/etl_atendimentos_dl.py for tasks to queue
[2024-01-26T16:43:07.701+0000] {logging_mixin.py:137} INFO - [2024-01-26T16:43:07.701+0000] {dagbag.py:538} INFO - Filling up the DagBag from /opt/airflow/dags/etl_scripts/etl_atendimentos_dl.py
[2024-01-26T16:43:07.716+0000] {logging_mixin.py:137} INFO - [2024-01-26T16:43:07.716+0000] {dagbag.py:320} INFO - File /opt/airflow/dags/etl_scripts/etl_atendimentos_dl.py assumed to contain no DAGs. Skipping.
[2024-01-26T16:43:07.717+0000] {processor.py:755} WARNING - No viable dags retrieved from /opt/airflow/dags/etl_scripts/etl_atendimentos_dl.py
[2024-01-26T16:43:07.731+0000] {processor.py:175} INFO - Processing /opt/airflow/dags/etl_scripts/etl_atendimentos_dl.py took 0.036 seconds
[2024-01-26T16:43:37.999+0000] {processor.py:153} INFO - Started process (PID=18181) to work on /opt/airflow/dags/etl_scripts/etl_atendimentos_dl.py
[2024-01-26T16:43:38.000+0000] {processor.py:743} INFO - Processing file /opt/airflow/dags/etl_scripts/etl_atendimentos_dl.py for tasks to queue
[2024-01-26T16:43:38.001+0000] {logging_mixin.py:137} INFO - [2024-01-26T16:43:38.001+0000] {dagbag.py:538} INFO - Filling up the DagBag from /opt/airflow/dags/etl_scripts/etl_atendimentos_dl.py
[2024-01-26T16:43:38.011+0000] {logging_mixin.py:137} INFO - [2024-01-26T16:43:38.011+0000] {dagbag.py:320} INFO - File /opt/airflow/dags/etl_scripts/etl_atendimentos_dl.py assumed to contain no DAGs. Skipping.
[2024-01-26T16:43:38.012+0000] {processor.py:755} WARNING - No viable dags retrieved from /opt/airflow/dags/etl_scripts/etl_atendimentos_dl.py
[2024-01-26T16:43:38.027+0000] {processor.py:175} INFO - Processing /opt/airflow/dags/etl_scripts/etl_atendimentos_dl.py took 0.031 seconds
[2024-01-26T16:44:08.319+0000] {processor.py:153} INFO - Started process (PID=18231) to work on /opt/airflow/dags/etl_scripts/etl_atendimentos_dl.py
[2024-01-26T16:44:08.321+0000] {processor.py:743} INFO - Processing file /opt/airflow/dags/etl_scripts/etl_atendimentos_dl.py for tasks to queue
[2024-01-26T16:44:08.323+0000] {logging_mixin.py:137} INFO - [2024-01-26T16:44:08.323+0000] {dagbag.py:538} INFO - Filling up the DagBag from /opt/airflow/dags/etl_scripts/etl_atendimentos_dl.py
[2024-01-26T16:44:08.360+0000] {logging_mixin.py:137} INFO - [2024-01-26T16:44:08.360+0000] {dagbag.py:320} INFO - File /opt/airflow/dags/etl_scripts/etl_atendimentos_dl.py assumed to contain no DAGs. Skipping.
[2024-01-26T16:44:08.361+0000] {processor.py:755} WARNING - No viable dags retrieved from /opt/airflow/dags/etl_scripts/etl_atendimentos_dl.py
[2024-01-26T16:44:08.397+0000] {processor.py:175} INFO - Processing /opt/airflow/dags/etl_scripts/etl_atendimentos_dl.py took 0.085 seconds
